# PIRATE COVE PARK ATTRACTION - Minecraft Bedrock Edition
# Stand at ground level at the CENTER, face a cardinal direction, and look horizontally, then run this function.
# Coordinates use your view: ^left, ^up, ^forward. The main guest entrance is behind you.
# Approximate footprint: 124 x 124 blocks. Approximate maximum height: 42 blocks.
# This function builds the attraction only; it does not animate boats or effects.

# === SNAP PLAYER TO BLOCK CENTER AND NEAREST CARDINAL ===
execute if entity @s[rym=-45,ry=45] as @s at @s align xz run tp @s ~0.5 ~ ~0.5 0 0
execute if entity @s[rym=45,ry=135] as @s at @s align xz run tp @s ~0.5 ~ ~0.5 90 0
execute if entity @s[rym=135,ry=180] as @s at @s align xz run tp @s ~0.5 ~ ~0.5 180 0
execute if entity @s[rym=-180,ry=-135] as @s at @s align xz run tp @s ~0.5 ~ ~0.5 180 0
execute if entity @s[rym=-135,ry=-45] as @s at @s align xz run tp @s ~0.5 ~ ~0.5 -90 0

# === FOUNDATION & ISLAND BASE ===
execute as @s at @s rotated as @s run fill ^-62 ^-3 ^-62 ^62 ^-3 ^62 minecraft:stone
execute as @s at @s rotated as @s run fill ^-60 ^-2 ^-60 ^60 ^-2 ^60 minecraft:gravel
execute as @s at @s rotated as @s run fill ^ ^-1 ^-55 ^ ^-1 ^-55 minecraft:stone
execute as @s at @s rotated as @s run fill ^-10 ^-1 ^-54 ^10 ^-1 ^-54 minecraft:stone
execute as @s at @s rotated as @s run fill ^-14 ^-1 ^-53 ^14 ^-1 ^-53 minecraft:stone
execute as @s at @s rotated as @s run fill ^-17 ^-1 ^-52 ^17 ^-1 ^-52 minecraft:stone
execute as @s at @s rotated as @s run fill ^-20 ^-1 ^-51 ^20 ^-1 ^-51 minecraft:stone
execute as @s at @s rotated as @s run fill ^-22 ^-1 ^-50 ^22 ^-1 ^-50 minecraft:stone
execute as @s at @s rotated as @s run fill ^-24 ^-1 ^-49 ^24 ^-1 ^-49 minecraft:stone
execute as @s at @s rotated as @s run fill ^-26 ^-1 ^-48 ^26 ^-1 ^-48 minecraft:stone
execute as @s at @s rotated as @s run fill ^-28 ^-1 ^-47 ^28 ^-1 ^-47 minecraft:stone
execute as @s at @s rotated as @s run fill ^-30 ^-1 ^-46 ^30 ^-1 ^-46 minecraft:stone
execute as @s at @s rotated as @s run fill ^-31 ^-1 ^-45 ^31 ^-1 ^-45 minecraft:stone
execute as @s at @s rotated as @s run fill ^-33 ^-1 ^-44 ^33 ^-1 ^-44 minecraft:stone
execute as @s at @s rotated as @s run fill ^-34 ^-1 ^-43 ^34 ^-1 ^-43 minecraft:stone
execute as @s at @s rotated as @s run fill ^-35 ^-1 ^-42 ^35 ^-1 ^-42 minecraft:stone
execute as @s at @s rotated as @s run fill ^-36 ^-1 ^-41 ^36 ^-1 ^-41 minecraft:stone
execute as @s at @s rotated as @s run fill ^-37 ^-1 ^-40 ^37 ^-1 ^-40 minecraft:stone
execute as @s at @s rotated as @s run fill ^-38 ^-1 ^-39 ^38 ^-1 ^-39 minecraft:stone
execute as @s at @s rotated as @s run fill ^-39 ^-1 ^-38 ^39 ^-1 ^-38 minecraft:stone
execute as @s at @s rotated as @s run fill ^-40 ^-1 ^-37 ^40 ^-1 ^-37 minecraft:stone
execute as @s at @s rotated as @s run fill ^-41 ^-1 ^-36 ^41 ^-1 ^-36 minecraft:stone
execute as @s at @s rotated as @s run fill ^-42 ^-1 ^-35 ^42 ^-1 ^-35 minecraft:stone
execute as @s at @s rotated as @s run fill ^-43 ^-1 ^-34 ^43 ^-1 ^-34 minecraft:stone
execute as @s at @s rotated as @s run fill ^-44 ^-1 ^-33 ^44 ^-1 ^-33 minecraft:stone
execute as @s at @s rotated as @s run fill ^-44 ^-1 ^-32 ^44 ^-1 ^-32 minecraft:stone
execute as @s at @s rotated as @s run fill ^-45 ^-1 ^-31 ^45 ^-1 ^-31 minecraft:stone
execute as @s at @s rotated as @s run fill ^-46 ^-1 ^-30 ^46 ^-1 ^-30 minecraft:stone
execute as @s at @s rotated as @s run fill ^-46 ^-1 ^-29 ^46 ^-1 ^-29 minecraft:stone
execute as @s at @s rotated as @s run fill ^-47 ^-1 ^-28 ^47 ^-1 ^-28 minecraft:stone
execute as @s at @s rotated as @s run fill ^-47 ^-1 ^-27 ^47 ^-1 ^-27 minecraft:stone
execute as @s at @s rotated as @s run fill ^-48 ^-1 ^-26 ^48 ^-1 ^-26 minecraft:stone
execute as @s at @s rotated as @s run fill ^-48 ^-1 ^-25 ^48 ^-1 ^-25 minecraft:stone
execute as @s at @s rotated as @s run fill ^-49 ^-1 ^-24 ^49 ^-1 ^-24 minecraft:stone
execute as @s at @s rotated as @s run fill ^-49 ^-1 ^-23 ^49 ^-1 ^-23 minecraft:stone
execute as @s at @s rotated as @s run fill ^-50 ^-1 ^-22 ^50 ^-1 ^-22 minecraft:stone
execute as @s at @s rotated as @s run fill ^-50 ^-1 ^-21 ^50 ^-1 ^-21 minecraft:stone
execute as @s at @s rotated as @s run fill ^-51 ^-1 ^-20 ^51 ^-1 ^-20 minecraft:stone
execute as @s at @s rotated as @s run fill ^-51 ^-1 ^-19 ^51 ^-1 ^-19 minecraft:stone
execute as @s at @s rotated as @s run fill ^-51 ^-1 ^-18 ^51 ^-1 ^-18 minecraft:stone
execute as @s at @s rotated as @s run fill ^-52 ^-1 ^-17 ^52 ^-1 ^-17 minecraft:stone
execute as @s at @s rotated as @s run fill ^-52 ^-1 ^-16 ^52 ^-1 ^-16 minecraft:stone
execute as @s at @s rotated as @s run fill ^-52 ^-1 ^-15 ^52 ^-1 ^-15 minecraft:stone
execute as @s at @s rotated as @s run fill ^-53 ^-1 ^-14 ^53 ^-1 ^-14 minecraft:stone
execute as @s at @s rotated as @s run fill ^-53 ^-1 ^-13 ^53 ^-1 ^-13 minecraft:stone
execute as @s at @s rotated as @s run fill ^-53 ^-1 ^-12 ^53 ^-1 ^-12 minecraft:stone
execute as @s at @s rotated as @s run fill ^-53 ^-1 ^-11 ^53 ^-1 ^-11 minecraft:stone
execute as @s at @s rotated as @s run fill ^-54 ^-1 ^-10 ^54 ^-1 ^-10 minecraft:stone
execute as @s at @s rotated as @s run fill ^-54 ^-1 ^-9 ^54 ^-1 ^-9 minecraft:stone
execute as @s at @s rotated as @s run fill ^-54 ^-1 ^-8 ^54 ^-1 ^-8 minecraft:stone
execute as @s at @s rotated as @s run fill ^-54 ^-1 ^-7 ^54 ^-1 ^-7 minecraft:stone
execute as @s at @s rotated as @s run fill ^-54 ^-1 ^-6 ^54 ^-1 ^-6 minecraft:stone
execute as @s at @s rotated as @s run fill ^-54 ^-1 ^-5 ^54 ^-1 ^-5 minecraft:stone
execute as @s at @s rotated as @s run fill ^-54 ^-1 ^-4 ^54 ^-1 ^-4 minecraft:stone
execute as @s at @s rotated as @s run fill ^-54 ^-1 ^-3 ^54 ^-1 ^-3 minecraft:stone
execute as @s at @s rotated as @s run fill ^-54 ^-1 ^-2 ^54 ^-1 ^-2 minecraft:stone
execute as @s at @s rotated as @s run fill ^-54 ^-1 ^-1 ^54 ^-1 ^-1 minecraft:stone
execute as @s at @s rotated as @s run fill ^-55 ^-1 ^ ^55 ^-1 ^ minecraft:stone
execute as @s at @s rotated as @s run fill ^-54 ^-1 ^1 ^54 ^-1 ^1 minecraft:stone
execute as @s at @s rotated as @s run fill ^-54 ^-1 ^2 ^54 ^-1 ^2 minecraft:stone
execute as @s at @s rotated as @s run fill ^-54 ^-1 ^3 ^54 ^-1 ^3 minecraft:stone
execute as @s at @s rotated as @s run fill ^-54 ^-1 ^4 ^54 ^-1 ^4 minecraft:stone
execute as @s at @s rotated as @s run fill ^-54 ^-1 ^5 ^54 ^-1 ^5 minecraft:stone
execute as @s at @s rotated as @s run fill ^-54 ^-1 ^6 ^54 ^-1 ^6 minecraft:stone
execute as @s at @s rotated as @s run fill ^-54 ^-1 ^7 ^54 ^-1 ^7 minecraft:stone
execute as @s at @s rotated as @s run fill ^-54 ^-1 ^8 ^54 ^-1 ^8 minecraft:stone
execute as @s at @s rotated as @s run fill ^-54 ^-1 ^9 ^54 ^-1 ^9 minecraft:stone
execute as @s at @s rotated as @s run fill ^-54 ^-1 ^10 ^54 ^-1 ^10 minecraft:stone
execute as @s at @s rotated as @s run fill ^-53 ^-1 ^11 ^53 ^-1 ^11 minecraft:stone
execute as @s at @s rotated as @s run fill ^-53 ^-1 ^12 ^53 ^-1 ^12 minecraft:stone
execute as @s at @s rotated as @s run fill ^-53 ^-1 ^13 ^53 ^-1 ^13 minecraft:stone
execute as @s at @s rotated as @s run fill ^-53 ^-1 ^14 ^53 ^-1 ^14 minecraft:stone
execute as @s at @s rotated as @s run fill ^-52 ^-1 ^15 ^52 ^-1 ^15 minecraft:stone
execute as @s at @s rotated as @s run fill ^-52 ^-1 ^16 ^52 ^-1 ^16 minecraft:stone
execute as @s at @s rotated as @s run fill ^-52 ^-1 ^17 ^52 ^-1 ^17 minecraft:stone
execute as @s at @s rotated as @s run fill ^-51 ^-1 ^18 ^51 ^-1 ^18 minecraft:stone
execute as @s at @s rotated as @s run fill ^-51 ^-1 ^19 ^51 ^-1 ^19 minecraft:stone
execute as @s at @s rotated as @s run fill ^-51 ^-1 ^20 ^51 ^-1 ^20 minecraft:stone
execute as @s at @s rotated as @s run fill ^-50 ^-1 ^21 ^50 ^-1 ^21 minecraft:stone
execute as @s at @s rotated as @s run fill ^-50 ^-1 ^22 ^50 ^-1 ^22 minecraft:stone
execute as @s at @s rotated as @s run fill ^-49 ^-1 ^23 ^49 ^-1 ^23 minecraft:stone
execute as @s at @s rotated as @s run fill ^-49 ^-1 ^24 ^49 ^-1 ^24 minecraft:stone
execute as @s at @s rotated as @s run fill ^-48 ^-1 ^25 ^48 ^-1 ^25 minecraft:stone
execute as @s at @s rotated as @s run fill ^-48 ^-1 ^26 ^48 ^-1 ^26 minecraft:stone
execute as @s at @s rotated as @s run fill ^-47 ^-1 ^27 ^47 ^-1 ^27 minecraft:stone
execute as @s at @s rotated as @s run fill ^-47 ^-1 ^28 ^47 ^-1 ^28 minecraft:stone
execute as @s at @s rotated as @s run fill ^-46 ^-1 ^29 ^46 ^-1 ^29 minecraft:stone
execute as @s at @s rotated as @s run fill ^-46 ^-1 ^30 ^46 ^-1 ^30 minecraft:stone
execute as @s at @s rotated as @s run fill ^-45 ^-1 ^31 ^45 ^-1 ^31 minecraft:stone
execute as @s at @s rotated as @s run fill ^-44 ^-1 ^32 ^44 ^-1 ^32 minecraft:stone
execute as @s at @s rotated as @s run fill ^-44 ^-1 ^33 ^44 ^-1 ^33 minecraft:stone
execute as @s at @s rotated as @s run fill ^-43 ^-1 ^34 ^43 ^-1 ^34 minecraft:stone
execute as @s at @s rotated as @s run fill ^-42 ^-1 ^35 ^42 ^-1 ^35 minecraft:stone
execute as @s at @s rotated as @s run fill ^-41 ^-1 ^36 ^41 ^-1 ^36 minecraft:stone
execute as @s at @s rotated as @s run fill ^-40 ^-1 ^37 ^40 ^-1 ^37 minecraft:stone
execute as @s at @s rotated as @s run fill ^-39 ^-1 ^38 ^39 ^-1 ^38 minecraft:stone
execute as @s at @s rotated as @s run fill ^-38 ^-1 ^39 ^38 ^-1 ^39 minecraft:stone
execute as @s at @s rotated as @s run fill ^-37 ^-1 ^40 ^37 ^-1 ^40 minecraft:stone
execute as @s at @s rotated as @s run fill ^-36 ^-1 ^41 ^36 ^-1 ^41 minecraft:stone
execute as @s at @s rotated as @s run fill ^-35 ^-1 ^42 ^35 ^-1 ^42 minecraft:stone
execute as @s at @s rotated as @s run fill ^-34 ^-1 ^43 ^34 ^-1 ^43 minecraft:stone
execute as @s at @s rotated as @s run fill ^-33 ^-1 ^44 ^33 ^-1 ^44 minecraft:stone
execute as @s at @s rotated as @s run fill ^-31 ^-1 ^45 ^31 ^-1 ^45 minecraft:stone
execute as @s at @s rotated as @s run fill ^-30 ^-1 ^46 ^30 ^-1 ^46 minecraft:stone
execute as @s at @s rotated as @s run fill ^-28 ^-1 ^47 ^28 ^-1 ^47 minecraft:stone
execute as @s at @s rotated as @s run fill ^-26 ^-1 ^48 ^26 ^-1 ^48 minecraft:stone
execute as @s at @s rotated as @s run fill ^-24 ^-1 ^49 ^24 ^-1 ^49 minecraft:stone
execute as @s at @s rotated as @s run fill ^-22 ^-1 ^50 ^22 ^-1 ^50 minecraft:stone
execute as @s at @s rotated as @s run fill ^-20 ^-1 ^51 ^20 ^-1 ^51 minecraft:stone
execute as @s at @s rotated as @s run fill ^-17 ^-1 ^52 ^17 ^-1 ^52 minecraft:stone
execute as @s at @s rotated as @s run fill ^-14 ^-1 ^53 ^14 ^-1 ^53 minecraft:stone
execute as @s at @s rotated as @s run fill ^-10 ^-1 ^54 ^10 ^-1 ^54 minecraft:stone
execute as @s at @s rotated as @s run fill ^ ^-1 ^55 ^ ^-1 ^55 minecraft:stone
execute as @s at @s rotated as @s run fill ^ ^ ^-52 ^ ^ ^-52 minecraft:sand
execute as @s at @s rotated as @s run fill ^-10 ^ ^-51 ^10 ^ ^-51 minecraft:sand
execute as @s at @s rotated as @s run fill ^-14 ^ ^-50 ^14 ^ ^-50 minecraft:sand
execute as @s at @s rotated as @s run fill ^-17 ^ ^-49 ^17 ^ ^-49 minecraft:sand
execute as @s at @s rotated as @s run fill ^-20 ^ ^-48 ^20 ^ ^-48 minecraft:sand
execute as @s at @s rotated as @s run fill ^-22 ^ ^-47 ^22 ^ ^-47 minecraft:sand
execute as @s at @s rotated as @s run fill ^-24 ^ ^-46 ^24 ^ ^-46 minecraft:sand
execute as @s at @s rotated as @s run fill ^-26 ^ ^-45 ^26 ^ ^-45 minecraft:sand
execute as @s at @s rotated as @s run fill ^-27 ^ ^-44 ^27 ^ ^-44 minecraft:sand
execute as @s at @s rotated as @s run fill ^-29 ^ ^-43 ^29 ^ ^-43 minecraft:sand
execute as @s at @s rotated as @s run fill ^-30 ^ ^-42 ^30 ^ ^-42 minecraft:sand
execute as @s at @s rotated as @s run fill ^-31 ^ ^-41 ^31 ^ ^-41 minecraft:sand
execute as @s at @s rotated as @s run fill ^-33 ^ ^-40 ^33 ^ ^-40 minecraft:sand
execute as @s at @s rotated as @s run fill ^-34 ^ ^-39 ^34 ^ ^-39 minecraft:sand
execute as @s at @s rotated as @s run fill ^-35 ^ ^-38 ^35 ^ ^-38 minecraft:sand
execute as @s at @s rotated as @s run fill ^-36 ^ ^-37 ^36 ^ ^-37 minecraft:sand
execute as @s at @s rotated as @s run fill ^-37 ^ ^-36 ^37 ^ ^-36 minecraft:sand
execute as @s at @s rotated as @s run fill ^-38 ^ ^-35 ^38 ^ ^-35 minecraft:sand
execute as @s at @s rotated as @s run fill ^-39 ^ ^-34 ^39 ^ ^-34 minecraft:sand
execute as @s at @s rotated as @s run fill ^-40 ^ ^-33 ^40 ^ ^-33 minecraft:sand
execute as @s at @s rotated as @s run fill ^-40 ^ ^-32 ^40 ^ ^-32 minecraft:sand
execute as @s at @s rotated as @s run fill ^-41 ^ ^-31 ^41 ^ ^-31 minecraft:sand
execute as @s at @s rotated as @s run fill ^-42 ^ ^-30 ^42 ^ ^-30 minecraft:sand
execute as @s at @s rotated as @s run fill ^-43 ^ ^-29 ^43 ^ ^-29 minecraft:sand
execute as @s at @s rotated as @s run fill ^-43 ^ ^-28 ^43 ^ ^-28 minecraft:sand
execute as @s at @s rotated as @s run fill ^-44 ^ ^-27 ^44 ^ ^-27 minecraft:sand
execute as @s at @s rotated as @s run fill ^-45 ^ ^-26 ^45 ^ ^-26 minecraft:sand
execute as @s at @s rotated as @s run fill ^-45 ^ ^-25 ^45 ^ ^-25 minecraft:sand
execute as @s at @s rotated as @s run fill ^-46 ^ ^-24 ^46 ^ ^-24 minecraft:sand
execute as @s at @s rotated as @s run fill ^-46 ^ ^-23 ^46 ^ ^-23 minecraft:sand
execute as @s at @s rotated as @s run fill ^-47 ^ ^-22 ^47 ^ ^-22 minecraft:sand
execute as @s at @s rotated as @s run fill ^-47 ^ ^-21 ^47 ^ ^-21 minecraft:sand
execute as @s at @s rotated as @s run fill ^-48 ^ ^-20 ^48 ^ ^-20 minecraft:sand
execute as @s at @s rotated as @s run fill ^-48 ^ ^-19 ^48 ^ ^-19 minecraft:sand
execute as @s at @s rotated as @s run fill ^-48 ^ ^-18 ^48 ^ ^-18 minecraft:sand
execute as @s at @s rotated as @s run fill ^-49 ^ ^-17 ^49 ^ ^-17 minecraft:sand
execute as @s at @s rotated as @s run fill ^-49 ^ ^-16 ^49 ^ ^-16 minecraft:sand
execute as @s at @s rotated as @s run fill ^-49 ^ ^-15 ^49 ^ ^-15 minecraft:sand
execute as @s at @s rotated as @s run fill ^-50 ^ ^-14 ^50 ^ ^-14 minecraft:sand
execute as @s at @s rotated as @s run fill ^-50 ^ ^-13 ^50 ^ ^-13 minecraft:sand
execute as @s at @s rotated as @s run fill ^-50 ^ ^-12 ^50 ^ ^-12 minecraft:sand
execute as @s at @s rotated as @s run fill ^-50 ^ ^-11 ^50 ^ ^-11 minecraft:sand
execute as @s at @s rotated as @s run fill ^-51 ^ ^-10 ^51 ^ ^-10 minecraft:sand
execute as @s at @s rotated as @s run fill ^-51 ^ ^-9 ^51 ^ ^-9 minecraft:sand
execute as @s at @s rotated as @s run fill ^-51 ^ ^-8 ^51 ^ ^-8 minecraft:sand
execute as @s at @s rotated as @s run fill ^-51 ^ ^-7 ^51 ^ ^-7 minecraft:sand
execute as @s at @s rotated as @s run fill ^-51 ^ ^-6 ^51 ^ ^-6 minecraft:sand
execute as @s at @s rotated as @s run fill ^-51 ^ ^-5 ^51 ^ ^-5 minecraft:sand
execute as @s at @s rotated as @s run fill ^-51 ^ ^-4 ^51 ^ ^-4 minecraft:sand
execute as @s at @s rotated as @s run fill ^-51 ^ ^-3 ^51 ^ ^-3 minecraft:sand
execute as @s at @s rotated as @s run fill ^-51 ^ ^-2 ^51 ^ ^-2 minecraft:sand
execute as @s at @s rotated as @s run fill ^-51 ^ ^-1 ^51 ^ ^-1 minecraft:sand
execute as @s at @s rotated as @s run fill ^-52 ^ ^ ^52 ^ ^ minecraft:sand
execute as @s at @s rotated as @s run fill ^-51 ^ ^1 ^51 ^ ^1 minecraft:sand
execute as @s at @s rotated as @s run fill ^-51 ^ ^2 ^51 ^ ^2 minecraft:sand
execute as @s at @s rotated as @s run fill ^-51 ^ ^3 ^51 ^ ^3 minecraft:sand
execute as @s at @s rotated as @s run fill ^-51 ^ ^4 ^51 ^ ^4 minecraft:sand
execute as @s at @s rotated as @s run fill ^-51 ^ ^5 ^51 ^ ^5 minecraft:sand
execute as @s at @s rotated as @s run fill ^-51 ^ ^6 ^51 ^ ^6 minecraft:sand
execute as @s at @s rotated as @s run fill ^-51 ^ ^7 ^51 ^ ^7 minecraft:sand
execute as @s at @s rotated as @s run fill ^-51 ^ ^8 ^51 ^ ^8 minecraft:sand
execute as @s at @s rotated as @s run fill ^-51 ^ ^9 ^51 ^ ^9 minecraft:sand
execute as @s at @s rotated as @s run fill ^-51 ^ ^10 ^51 ^ ^10 minecraft:sand
execute as @s at @s rotated as @s run fill ^-50 ^ ^11 ^50 ^ ^11 minecraft:sand
execute as @s at @s rotated as @s run fill ^-50 ^ ^12 ^50 ^ ^12 minecraft:sand
execute as @s at @s rotated as @s run fill ^-50 ^ ^13 ^50 ^ ^13 minecraft:sand
execute as @s at @s rotated as @s run fill ^-50 ^ ^14 ^50 ^ ^14 minecraft:sand
execute as @s at @s rotated as @s run fill ^-49 ^ ^15 ^49 ^ ^15 minecraft:sand
execute as @s at @s rotated as @s run fill ^-49 ^ ^16 ^49 ^ ^16 minecraft:sand
execute as @s at @s rotated as @s run fill ^-49 ^ ^17 ^49 ^ ^17 minecraft:sand
execute as @s at @s rotated as @s run fill ^-48 ^ ^18 ^48 ^ ^18 minecraft:sand
execute as @s at @s rotated as @s run fill ^-48 ^ ^19 ^48 ^ ^19 minecraft:sand
execute as @s at @s rotated as @s run fill ^-48 ^ ^20 ^48 ^ ^20 minecraft:sand
execute as @s at @s rotated as @s run fill ^-47 ^ ^21 ^47 ^ ^21 minecraft:sand
execute as @s at @s rotated as @s run fill ^-47 ^ ^22 ^47 ^ ^22 minecraft:sand
execute as @s at @s rotated as @s run fill ^-46 ^ ^23 ^46 ^ ^23 minecraft:sand
execute as @s at @s rotated as @s run fill ^-46 ^ ^24 ^46 ^ ^24 minecraft:sand
execute as @s at @s rotated as @s run fill ^-45 ^ ^25 ^45 ^ ^25 minecraft:sand
execute as @s at @s rotated as @s run fill ^-45 ^ ^26 ^45 ^ ^26 minecraft:sand
execute as @s at @s rotated as @s run fill ^-44 ^ ^27 ^44 ^ ^27 minecraft:sand
execute as @s at @s rotated as @s run fill ^-43 ^ ^28 ^43 ^ ^28 minecraft:sand
execute as @s at @s rotated as @s run fill ^-43 ^ ^29 ^43 ^ ^29 minecraft:sand
execute as @s at @s rotated as @s run fill ^-42 ^ ^30 ^42 ^ ^30 minecraft:sand
execute as @s at @s rotated as @s run fill ^-41 ^ ^31 ^41 ^ ^31 minecraft:sand
execute as @s at @s rotated as @s run fill ^-40 ^ ^32 ^40 ^ ^32 minecraft:sand
execute as @s at @s rotated as @s run fill ^-40 ^ ^33 ^40 ^ ^33 minecraft:sand
execute as @s at @s rotated as @s run fill ^-39 ^ ^34 ^39 ^ ^34 minecraft:sand
execute as @s at @s rotated as @s run fill ^-38 ^ ^35 ^38 ^ ^35 minecraft:sand
execute as @s at @s rotated as @s run fill ^-37 ^ ^36 ^37 ^ ^36 minecraft:sand
execute as @s at @s rotated as @s run fill ^-36 ^ ^37 ^36 ^ ^37 minecraft:sand
execute as @s at @s rotated as @s run fill ^-35 ^ ^38 ^35 ^ ^38 minecraft:sand
execute as @s at @s rotated as @s run fill ^-34 ^ ^39 ^34 ^ ^39 minecraft:sand
execute as @s at @s rotated as @s run fill ^-33 ^ ^40 ^33 ^ ^40 minecraft:sand
execute as @s at @s rotated as @s run fill ^-31 ^ ^41 ^31 ^ ^41 minecraft:sand
execute as @s at @s rotated as @s run fill ^-30 ^ ^42 ^30 ^ ^42 minecraft:sand
execute as @s at @s rotated as @s run fill ^-29 ^ ^43 ^29 ^ ^43 minecraft:sand
execute as @s at @s rotated as @s run fill ^-27 ^ ^44 ^27 ^ ^44 minecraft:sand
execute as @s at @s rotated as @s run fill ^-26 ^ ^45 ^26 ^ ^45 minecraft:sand
execute as @s at @s rotated as @s run fill ^-24 ^ ^46 ^24 ^ ^46 minecraft:sand
execute as @s at @s rotated as @s run fill ^-22 ^ ^47 ^22 ^ ^47 minecraft:sand
execute as @s at @s rotated as @s run fill ^-20 ^ ^48 ^20 ^ ^48 minecraft:sand
execute as @s at @s rotated as @s run fill ^-17 ^ ^49 ^17 ^ ^49 minecraft:sand
execute as @s at @s rotated as @s run fill ^-14 ^ ^50 ^14 ^ ^50 minecraft:sand
execute as @s at @s rotated as @s run fill ^-10 ^ ^51 ^10 ^ ^51 minecraft:sand
execute as @s at @s rotated as @s run fill ^ ^ ^52 ^ ^ ^52 minecraft:sand
execute as @s at @s rotated as @s run setblock ^-53 ^ ^-7 minecraft:cobblestone
execute as @s at @s rotated as @s run setblock ^-53 ^ ^-6 minecraft:cobblestone
execute as @s at @s rotated as @s run setblock ^-53 ^ ^-5 minecraft:cobblestone
execute as @s at @s rotated as @s run setblock ^-53 ^ ^-4 minecraft:cobblestone
execute as @s at @s rotated as @s run setblock ^-53 ^ ^-3 minecraft:cobblestone
execute as @s at @s rotated as @s run setblock ^-53 ^ ^-2 minecraft:cobblestone
execute as @s at @s rotated as @s run setblock ^-53 ^ ^-1 minecraft:cobblestone
execute as @s at @s rotated as @s run setblock ^-53 ^ ^ minecraft:cobblestone
execute as @s at @s rotated as @s run setblock ^-53 ^ ^1 minecraft:cobblestone
execute as @s at @s rotated as @s run setblock ^-53 ^ ^2 minecraft:cobblestone
execute as @s at @s rotated as @s run setblock ^-53 ^ ^3 minecraft:cobblestone
execute as @s at @s rotated as @s run setblock ^-53 ^ ^4 minecraft:cobblestone
execute as @s at @s rotated as @s run setblock ^-53 ^ ^5 minecraft:cobblestone
execute as @s at @s rotated as @s run setblock ^-53 ^ ^6 minecraft:cobblestone
execute as @s at @s rotated as @s run setblock ^-53 ^ ^7 minecraft:cobblestone
execute as @s at @s rotated as @s run setblock ^-52 ^ ^-12 minecraft:cobblestone
execute as @s at @s rotated as @s run setblock ^-52 ^ ^-11 minecraft:cobblestone
execute as @s at @s rotated as @s run setblock ^-52 ^ ^-10 minecraft:cobblestone
execute as @s at @s rotated as @s run setblock ^-52 ^ ^-9 minecraft:cobblestone
execute as @s at @s rotated as @s run setblock ^-52 ^ ^-8 minecraft:cobblestone
execute as @s at @s rotated as @s run setblock ^-52 ^ ^-7 minecraft:cobblestone
execute as @s at @s rotated as @s run setblock ^-52 ^ ^7 minecraft:cobblestone
execute as @s at @s rotated as @s run setblock ^-52 ^ ^8 minecraft:cobblestone
execute as @s at @s rotated as @s run setblock ^-52 ^ ^9 minecraft:cobblestone
execute as @s at @s rotated as @s run setblock ^-52 ^ ^10 minecraft:cobblestone
execute as @s at @s rotated as @s run setblock ^-52 ^ ^11 minecraft:cobblestone
execute as @s at @s rotated as @s run setblock ^-52 ^ ^12 minecraft:cobblestone
execute as @s at @s rotated as @s run setblock ^-51 ^ ^-16 minecraft:cobblestone
execute as @s at @s rotated as @s run setblock ^-51 ^ ^-15 minecraft:cobblestone
execute as @s at @s rotated as @s run setblock ^-51 ^ ^-14 minecraft:cobblestone
execute as @s at @s rotated as @s run setblock ^-51 ^ ^-13 minecraft:cobblestone
execute as @s at @s rotated as @s run setblock ^-51 ^ ^13 minecraft:cobblestone
execute as @s at @s rotated as @s run setblock ^-51 ^ ^14 minecraft:cobblestone
execute as @s at @s rotated as @s run setblock ^-51 ^ ^15 minecraft:cobblestone
execute as @s at @s rotated as @s run setblock ^-51 ^ ^16 minecraft:cobblestone
execute as @s at @s rotated as @s run setblock ^-50 ^ ^-19 minecraft:cobblestone
execute as @s at @s rotated as @s run setblock ^-50 ^ ^-18 minecraft:cobblestone
execute as @s at @s rotated as @s run setblock ^-50 ^ ^-17 minecraft:cobblestone
execute as @s at @s rotated as @s run setblock ^-50 ^ ^-16 minecraft:cobblestone
execute as @s at @s rotated as @s run setblock ^-50 ^ ^16 minecraft:cobblestone
execute as @s at @s rotated as @s run setblock ^-50 ^ ^17 minecraft:cobblestone
execute as @s at @s rotated as @s run setblock ^-50 ^ ^18 minecraft:cobblestone
execute as @s at @s rotated as @s run setblock ^-50 ^ ^19 minecraft:cobblestone
execute as @s at @s rotated as @s run setblock ^-49 ^ ^-21 minecraft:cobblestone
execute as @s at @s rotated as @s run setblock ^-49 ^ ^-20 minecraft:cobblestone
execute as @s at @s rotated as @s run setblock ^-49 ^ ^-19 minecraft:cobblestone
execute as @s at @s rotated as @s run setblock ^-49 ^ ^19 minecraft:cobblestone
execute as @s at @s rotated as @s run setblock ^-49 ^ ^20 minecraft:cobblestone
execute as @s at @s rotated as @s run setblock ^-49 ^ ^21 minecraft:cobblestone
execute as @s at @s rotated as @s run setblock ^-48 ^ ^-23 minecraft:cobblestone
execute as @s at @s rotated as @s run setblock ^-48 ^ ^-22 minecraft:cobblestone
execute as @s at @s rotated as @s run setblock ^-48 ^ ^-21 minecraft:cobblestone
execute as @s at @s rotated as @s run setblock ^-48 ^ ^21 minecraft:cobblestone
execute as @s at @s rotated as @s run setblock ^-48 ^ ^22 minecraft:cobblestone
execute as @s at @s rotated as @s run setblock ^-48 ^ ^23 minecraft:cobblestone
execute as @s at @s rotated as @s run setblock ^-47 ^ ^-25 minecraft:cobblestone
execute as @s at @s rotated as @s run setblock ^-47 ^ ^-24 minecraft:cobblestone
execute as @s at @s rotated as @s run setblock ^-47 ^ ^24 minecraft:cobblestone
execute as @s at @s rotated as @s run setblock ^-47 ^ ^25 minecraft:cobblestone
execute as @s at @s rotated as @s run setblock ^-46 ^ ^-27 minecraft:cobblestone
execute as @s at @s rotated as @s run setblock ^-46 ^ ^-26 minecraft:cobblestone
execute as @s at @s rotated as @s run setblock ^-46 ^ ^26 minecraft:cobblestone
execute as @s at @s rotated as @s run setblock ^-46 ^ ^27 minecraft:cobblestone
execute as @s at @s rotated as @s run setblock ^-45 ^ ^-28 minecraft:cobblestone
execute as @s at @s rotated as @s run setblock ^-45 ^ ^28 minecraft:cobblestone
execute as @s at @s rotated as @s run setblock ^-44 ^ ^-30 minecraft:cobblestone
execute as @s at @s rotated as @s run setblock ^-44 ^ ^-29 minecraft:cobblestone
execute as @s at @s rotated as @s run setblock ^-44 ^ ^29 minecraft:cobblestone
execute as @s at @s rotated as @s run setblock ^-44 ^ ^30 minecraft:cobblestone
execute as @s at @s rotated as @s run setblock ^-43 ^ ^-31 minecraft:cobblestone
execute as @s at @s rotated as @s run setblock ^-43 ^ ^31 minecraft:cobblestone
execute as @s at @s rotated as @s run setblock ^-42 ^ ^-33 minecraft:cobblestone
execute as @s at @s rotated as @s run setblock ^-42 ^ ^-32 minecraft:cobblestone
execute as @s at @s rotated as @s run setblock ^-42 ^ ^32 minecraft:cobblestone
execute as @s at @s rotated as @s run setblock ^-42 ^ ^33 minecraft:cobblestone
execute as @s at @s rotated as @s run setblock ^-41 ^ ^-34 minecraft:cobblestone
execute as @s at @s rotated as @s run setblock ^-41 ^ ^-33 minecraft:cobblestone
execute as @s at @s rotated as @s run setblock ^-41 ^ ^33 minecraft:cobblestone
execute as @s at @s rotated as @s run setblock ^-41 ^ ^34 minecraft:cobblestone
execute as @s at @s rotated as @s run setblock ^-40 ^ ^-35 minecraft:cobblestone
execute as @s at @s rotated as @s run setblock ^-40 ^ ^-34 minecraft:cobblestone
execute as @s at @s rotated as @s run setblock ^-40 ^ ^34 minecraft:cobblestone
execute as @s at @s rotated as @s run setblock ^-40 ^ ^35 minecraft:cobblestone
execute as @s at @s rotated as @s run setblock ^-39 ^ ^-36 minecraft:cobblestone
execute as @s at @s rotated as @s run setblock ^-39 ^ ^36 minecraft:cobblestone
execute as @s at @s rotated as @s run setblock ^-38 ^ ^-37 minecraft:cobblestone
execute as @s at @s rotated as @s run setblock ^-38 ^ ^37 minecraft:cobblestone
execute as @s at @s rotated as @s run setblock ^-37 ^ ^-38 minecraft:cobblestone
execute as @s at @s rotated as @s run setblock ^-37 ^ ^38 minecraft:cobblestone
execute as @s at @s rotated as @s run setblock ^-36 ^ ^-39 minecraft:cobblestone
execute as @s at @s rotated as @s run setblock ^-36 ^ ^-38 minecraft:cobblestone
execute as @s at @s rotated as @s run setblock ^-36 ^ ^38 minecraft:cobblestone
execute as @s at @s rotated as @s run setblock ^-36 ^ ^39 minecraft:cobblestone
execute as @s at @s rotated as @s run setblock ^-35 ^ ^-40 minecraft:cobblestone
execute as @s at @s rotated as @s run setblock ^-35 ^ ^-39 minecraft:cobblestone
execute as @s at @s rotated as @s run setblock ^-35 ^ ^39 minecraft:cobblestone
execute as @s at @s rotated as @s run setblock ^-35 ^ ^40 minecraft:cobblestone
execute as @s at @s rotated as @s run setblock ^-34 ^ ^-41 minecraft:cobblestone
execute as @s at @s rotated as @s run setblock ^-34 ^ ^-40 minecraft:cobblestone
execute as @s at @s rotated as @s run setblock ^-34 ^ ^40 minecraft:cobblestone
execute as @s at @s rotated as @s run setblock ^-34 ^ ^41 minecraft:cobblestone
execute as @s at @s rotated as @s run setblock ^-33 ^ ^-42 minecraft:cobblestone
execute as @s at @s rotated as @s run setblock ^-33 ^ ^-41 minecraft:cobblestone
execute as @s at @s rotated as @s run setblock ^-33 ^ ^41 minecraft:cobblestone
execute as @s at @s rotated as @s run setblock ^-33 ^ ^42 minecraft:cobblestone
execute as @s at @s rotated as @s run setblock ^-32 ^ ^-43 minecraft:cobblestone
execute as @s at @s rotated as @s run setblock ^-32 ^ ^-42 minecraft:cobblestone
execute as @s at @s rotated as @s run setblock ^-32 ^ ^42 minecraft:cobblestone
execute as @s at @s rotated as @s run setblock ^-32 ^ ^43 minecraft:cobblestone
execute as @s at @s rotated as @s run setblock ^-31 ^ ^-43 minecraft:cobblestone
execute as @s at @s rotated as @s run setblock ^-31 ^ ^43 minecraft:cobblestone
execute as @s at @s rotated as @s run setblock ^-30 ^ ^-44 minecraft:cobblestone
execute as @s at @s rotated as @s run setblock ^-30 ^ ^-43 minecraft:cobblestone
execute as @s at @s rotated as @s run setblock ^-30 ^ ^43 minecraft:cobblestone
execute as @s at @s rotated as @s run setblock ^-30 ^ ^44 minecraft:cobblestone
execute as @s at @s rotated as @s run setblock ^-29 ^ ^-45 minecraft:cobblestone
execute as @s at @s rotated as @s run setblock ^-29 ^ ^-44 minecraft:cobblestone
execute as @s at @s rotated as @s run setblock ^-29 ^ ^44 minecraft:cobblestone
execute as @s at @s rotated as @s run setblock ^-29 ^ ^45 minecraft:cobblestone
execute as @s at @s rotated as @s run setblock ^-28 ^ ^-45 minecraft:cobblestone
execute as @s at @s rotated as @s run setblock ^-28 ^ ^45 minecraft:cobblestone
execute as @s at @s rotated as @s run setblock ^-27 ^ ^-46 minecraft:cobblestone
execute as @s at @s rotated as @s run setblock ^-27 ^ ^-45 minecraft:cobblestone
execute as @s at @s rotated as @s run setblock ^-27 ^ ^45 minecraft:cobblestone
execute as @s at @s rotated as @s run setblock ^-27 ^ ^46 minecraft:cobblestone
execute as @s at @s rotated as @s run setblock ^-26 ^ ^-46 minecraft:cobblestone
execute as @s at @s rotated as @s run setblock ^-26 ^ ^46 minecraft:cobblestone
execute as @s at @s rotated as @s run setblock ^-25 ^ ^-47 minecraft:cobblestone
execute as @s at @s rotated as @s run setblock ^-25 ^ ^47 minecraft:cobblestone
execute as @s at @s rotated as @s run setblock ^-24 ^ ^-47 minecraft:cobblestone
execute as @s at @s rotated as @s run setblock ^-24 ^ ^47 minecraft:cobblestone
execute as @s at @s rotated as @s run setblock ^-23 ^ ^-48 minecraft:cobblestone
execute as @s at @s rotated as @s run setblock ^-23 ^ ^48 minecraft:cobblestone
execute as @s at @s rotated as @s run setblock ^-22 ^ ^-48 minecraft:cobblestone
execute as @s at @s rotated as @s run setblock ^-22 ^ ^48 minecraft:cobblestone
execute as @s at @s rotated as @s run setblock ^-21 ^ ^-49 minecraft:cobblestone
execute as @s at @s rotated as @s run setblock ^-21 ^ ^49 minecraft:cobblestone
execute as @s at @s rotated as @s run setblock ^-20 ^ ^-49 minecraft:cobblestone
execute as @s at @s rotated as @s run setblock ^-20 ^ ^49 minecraft:cobblestone
execute as @s at @s rotated as @s run setblock ^-19 ^ ^-50 minecraft:cobblestone
execute as @s at @s rotated as @s run setblock ^-19 ^ ^-49 minecraft:cobblestone
execute as @s at @s rotated as @s run setblock ^-19 ^ ^49 minecraft:cobblestone
execute as @s at @s rotated as @s run setblock ^-19 ^ ^50 minecraft:cobblestone
execute as @s at @s rotated as @s run setblock ^-18 ^ ^-50 minecraft:cobblestone
execute as @s at @s rotated as @s run setblock ^-18 ^ ^50 minecraft:cobblestone
execute as @s at @s rotated as @s run setblock ^-17 ^ ^-50 minecraft:cobblestone
execute as @s at @s rotated as @s run setblock ^-17 ^ ^50 minecraft:cobblestone
execute as @s at @s rotated as @s run setblock ^-16 ^ ^-51 minecraft:cobblestone
execute as @s at @s rotated as @s run setblock ^-16 ^ ^-50 minecraft:cobblestone
execute as @s at @s rotated as @s run setblock ^-16 ^ ^50 minecraft:cobblestone
execute as @s at @s rotated as @s run setblock ^-16 ^ ^51 minecraft:cobblestone
execute as @s at @s rotated as @s run setblock ^-15 ^ ^-51 minecraft:cobblestone
execute as @s at @s rotated as @s run setblock ^-15 ^ ^51 minecraft:cobblestone
execute as @s at @s rotated as @s run setblock ^-14 ^ ^-51 minecraft:cobblestone
execute as @s at @s rotated as @s run setblock ^-14 ^ ^51 minecraft:cobblestone
execute as @s at @s rotated as @s run setblock ^-13 ^ ^-51 minecraft:cobblestone
execute as @s at @s rotated as @s run setblock ^-13 ^ ^51 minecraft:cobblestone
execute as @s at @s rotated as @s run setblock ^-12 ^ ^-52 minecraft:cobblestone
execute as @s at @s rotated as @s run setblock ^-12 ^ ^52 minecraft:cobblestone
execute as @s at @s rotated as @s run setblock ^-11 ^ ^-52 minecraft:cobblestone
execute as @s at @s rotated as @s run setblock ^-11 ^ ^52 minecraft:cobblestone
execute as @s at @s rotated as @s run setblock ^-10 ^ ^-52 minecraft:cobblestone
execute as @s at @s rotated as @s run setblock ^-10 ^ ^52 minecraft:cobblestone
execute as @s at @s rotated as @s run setblock ^-9 ^ ^-52 minecraft:cobblestone
execute as @s at @s rotated as @s run setblock ^-9 ^ ^52 minecraft:cobblestone
execute as @s at @s rotated as @s run setblock ^-8 ^ ^-52 minecraft:cobblestone
execute as @s at @s rotated as @s run setblock ^-8 ^ ^52 minecraft:cobblestone
execute as @s at @s rotated as @s run setblock ^-7 ^ ^-53 minecraft:cobblestone
execute as @s at @s rotated as @s run setblock ^-7 ^ ^53 minecraft:cobblestone
execute as @s at @s rotated as @s run setblock ^-6 ^ ^-53 minecraft:cobblestone
execute as @s at @s rotated as @s run setblock ^-6 ^ ^53 minecraft:cobblestone
execute as @s at @s rotated as @s run setblock ^-5 ^ ^-53 minecraft:cobblestone
execute as @s at @s rotated as @s run setblock ^-5 ^ ^53 minecraft:cobblestone
execute as @s at @s rotated as @s run setblock ^-4 ^ ^-53 minecraft:cobblestone
execute as @s at @s rotated as @s run setblock ^-4 ^ ^53 minecraft:cobblestone
execute as @s at @s rotated as @s run setblock ^-3 ^ ^-53 minecraft:cobblestone
execute as @s at @s rotated as @s run setblock ^-3 ^ ^53 minecraft:cobblestone
execute as @s at @s rotated as @s run setblock ^-2 ^ ^-53 minecraft:cobblestone
execute as @s at @s rotated as @s run setblock ^-2 ^ ^53 minecraft:cobblestone
execute as @s at @s rotated as @s run setblock ^-1 ^ ^-53 minecraft:cobblestone
execute as @s at @s rotated as @s run setblock ^-1 ^ ^53 minecraft:cobblestone
execute as @s at @s rotated as @s run setblock ^ ^ ^-53 minecraft:cobblestone
execute as @s at @s rotated as @s run setblock ^ ^ ^53 minecraft:cobblestone
execute as @s at @s rotated as @s run setblock ^1 ^ ^-53 minecraft:cobblestone
execute as @s at @s rotated as @s run setblock ^1 ^ ^53 minecraft:cobblestone
execute as @s at @s rotated as @s run setblock ^2 ^ ^-53 minecraft:cobblestone
execute as @s at @s rotated as @s run setblock ^2 ^ ^53 minecraft:cobblestone
execute as @s at @s rotated as @s run setblock ^3 ^ ^-53 minecraft:cobblestone
execute as @s at @s rotated as @s run setblock ^3 ^ ^53 minecraft:cobblestone
execute as @s at @s rotated as @s run setblock ^4 ^ ^-53 minecraft:cobblestone
execute as @s at @s rotated as @s run setblock ^4 ^ ^53 minecraft:cobblestone
execute as @s at @s rotated as @s run setblock ^5 ^ ^-53 minecraft:cobblestone
execute as @s at @s rotated as @s run setblock ^5 ^ ^53 minecraft:cobblestone
execute as @s at @s rotated as @s run setblock ^6 ^ ^-53 minecraft:cobblestone
execute as @s at @s rotated as @s run setblock ^6 ^ ^53 minecraft:cobblestone
execute as @s at @s rotated as @s run setblock ^7 ^ ^-53 minecraft:cobblestone
execute as @s at @s rotated as @s run setblock ^7 ^ ^53 minecraft:cobblestone
execute as @s at @s rotated as @s run setblock ^8 ^ ^-52 minecraft:cobblestone
execute as @s at @s rotated as @s run setblock ^8 ^ ^52 minecraft:cobblestone
execute as @s at @s rotated as @s run setblock ^9 ^ ^-52 minecraft:cobblestone
execute as @s at @s rotated as @s run setblock ^9 ^ ^52 minecraft:cobblestone
execute as @s at @s rotated as @s run setblock ^10 ^ ^-52 minecraft:cobblestone
execute as @s at @s rotated as @s run setblock ^10 ^ ^52 minecraft:cobblestone
execute as @s at @s rotated as @s run setblock ^11 ^ ^-52 minecraft:cobblestone
execute as @s at @s rotated as @s run setblock ^11 ^ ^52 minecraft:cobblestone
execute as @s at @s rotated as @s run setblock ^12 ^ ^-52 minecraft:cobblestone
execute as @s at @s rotated as @s run setblock ^12 ^ ^52 minecraft:cobblestone
execute as @s at @s rotated as @s run setblock ^13 ^ ^-51 minecraft:cobblestone
execute as @s at @s rotated as @s run setblock ^13 ^ ^51 minecraft:cobblestone
execute as @s at @s rotated as @s run setblock ^14 ^ ^-51 minecraft:cobblestone
execute as @s at @s rotated as @s run setblock ^14 ^ ^51 minecraft:cobblestone
execute as @s at @s rotated as @s run setblock ^15 ^ ^-51 minecraft:cobblestone
execute as @s at @s rotated as @s run setblock ^15 ^ ^51 minecraft:cobblestone
execute as @s at @s rotated as @s run setblock ^16 ^ ^-51 minecraft:cobblestone
execute as @s at @s rotated as @s run setblock ^16 ^ ^-50 minecraft:cobblestone
execute as @s at @s rotated as @s run setblock ^16 ^ ^50 minecraft:cobblestone
execute as @s at @s rotated as @s run setblock ^16 ^ ^51 minecraft:cobblestone
execute as @s at @s rotated as @s run setblock ^17 ^ ^-50 minecraft:cobblestone
execute as @s at @s rotated as @s run setblock ^17 ^ ^50 minecraft:cobblestone
execute as @s at @s rotated as @s run setblock ^18 ^ ^-50 minecraft:cobblestone
execute as @s at @s rotated as @s run setblock ^18 ^ ^50 minecraft:cobblestone
execute as @s at @s rotated as @s run setblock ^19 ^ ^-50 minecraft:cobblestone
execute as @s at @s rotated as @s run setblock ^19 ^ ^-49 minecraft:cobblestone
execute as @s at @s rotated as @s run setblock ^19 ^ ^49 minecraft:cobblestone
execute as @s at @s rotated as @s run setblock ^19 ^ ^50 minecraft:cobblestone
execute as @s at @s rotated as @s run setblock ^20 ^ ^-49 minecraft:cobblestone
execute as @s at @s rotated as @s run setblock ^20 ^ ^49 minecraft:cobblestone
execute as @s at @s rotated as @s run setblock ^21 ^ ^-49 minecraft:cobblestone
execute as @s at @s rotated as @s run setblock ^21 ^ ^49 minecraft:cobblestone
execute as @s at @s rotated as @s run setblock ^22 ^ ^-48 minecraft:cobblestone
execute as @s at @s rotated as @s run setblock ^22 ^ ^48 minecraft:cobblestone
execute as @s at @s rotated as @s run setblock ^23 ^ ^-48 minecraft:cobblestone
execute as @s at @s rotated as @s run setblock ^23 ^ ^48 minecraft:cobblestone
execute as @s at @s rotated as @s run setblock ^24 ^ ^-47 minecraft:cobblestone
execute as @s at @s rotated as @s run setblock ^24 ^ ^47 minecraft:cobblestone
execute as @s at @s rotated as @s run setblock ^25 ^ ^-47 minecraft:cobblestone
execute as @s at @s rotated as @s run setblock ^25 ^ ^47 minecraft:cobblestone
execute as @s at @s rotated as @s run setblock ^26 ^ ^-46 minecraft:cobblestone
execute as @s at @s rotated as @s run setblock ^26 ^ ^46 minecraft:cobblestone
execute as @s at @s rotated as @s run setblock ^27 ^ ^-46 minecraft:cobblestone
execute as @s at @s rotated as @s run setblock ^27 ^ ^-45 minecraft:cobblestone
execute as @s at @s rotated as @s run setblock ^27 ^ ^45 minecraft:cobblestone
execute as @s at @s rotated as @s run setblock ^27 ^ ^46 minecraft:cobblestone
execute as @s at @s rotated as @s run setblock ^28 ^ ^-45 minecraft:cobblestone
execute as @s at @s rotated as @s run setblock ^28 ^ ^45 minecraft:cobblestone
execute as @s at @s rotated as @s run setblock ^29 ^ ^-45 minecraft:cobblestone
execute as @s at @s rotated as @s run setblock ^29 ^ ^-44 minecraft:cobblestone
execute as @s at @s rotated as @s run setblock ^29 ^ ^44 minecraft:cobblestone
execute as @s at @s rotated as @s run setblock ^29 ^ ^45 minecraft:cobblestone
execute as @s at @s rotated as @s run setblock ^30 ^ ^-44 minecraft:cobblestone
execute as @s at @s rotated as @s run setblock ^30 ^ ^-43 minecraft:cobblestone
execute as @s at @s rotated as @s run setblock ^30 ^ ^43 minecraft:cobblestone
execute as @s at @s rotated as @s run setblock ^30 ^ ^44 minecraft:cobblestone
execute as @s at @s rotated as @s run setblock ^31 ^ ^-43 minecraft:cobblestone
execute as @s at @s rotated as @s run setblock ^31 ^ ^43 minecraft:cobblestone
execute as @s at @s rotated as @s run setblock ^32 ^ ^-43 minecraft:cobblestone
execute as @s at @s rotated as @s run setblock ^32 ^ ^-42 minecraft:cobblestone
execute as @s at @s rotated as @s run setblock ^32 ^ ^42 minecraft:cobblestone
execute as @s at @s rotated as @s run setblock ^32 ^ ^43 minecraft:cobblestone
execute as @s at @s rotated as @s run setblock ^33 ^ ^-42 minecraft:cobblestone
execute as @s at @s rotated as @s run setblock ^33 ^ ^-41 minecraft:cobblestone
execute as @s at @s rotated as @s run setblock ^33 ^ ^41 minecraft:cobblestone
execute as @s at @s rotated as @s run setblock ^33 ^ ^42 minecraft:cobblestone
execute as @s at @s rotated as @s run setblock ^34 ^ ^-41 minecraft:cobblestone
execute as @s at @s rotated as @s run setblock ^34 ^ ^-40 minecraft:cobblestone
execute as @s at @s rotated as @s run setblock ^34 ^ ^40 minecraft:cobblestone
execute as @s at @s rotated as @s run setblock ^34 ^ ^41 minecraft:cobblestone
execute as @s at @s rotated as @s run setblock ^35 ^ ^-40 minecraft:cobblestone
execute as @s at @s rotated as @s run setblock ^35 ^ ^-39 minecraft:cobblestone
execute as @s at @s rotated as @s run setblock ^35 ^ ^39 minecraft:cobblestone
execute as @s at @s rotated as @s run setblock ^35 ^ ^40 minecraft:cobblestone
execute as @s at @s rotated as @s run setblock ^36 ^ ^-39 minecraft:cobblestone
execute as @s at @s rotated as @s run setblock ^36 ^ ^-38 minecraft:cobblestone
execute as @s at @s rotated as @s run setblock ^36 ^ ^38 minecraft:cobblestone
execute as @s at @s rotated as @s run setblock ^36 ^ ^39 minecraft:cobblestone
execute as @s at @s rotated as @s run setblock ^37 ^ ^-38 minecraft:cobblestone
execute as @s at @s rotated as @s run setblock ^37 ^ ^38 minecraft:cobblestone
execute as @s at @s rotated as @s run setblock ^38 ^ ^-37 minecraft:cobblestone
execute as @s at @s rotated as @s run setblock ^38 ^ ^37 minecraft:cobblestone
execute as @s at @s rotated as @s run setblock ^39 ^ ^-36 minecraft:cobblestone
execute as @s at @s rotated as @s run setblock ^39 ^ ^36 minecraft:cobblestone
execute as @s at @s rotated as @s run setblock ^40 ^ ^-35 minecraft:cobblestone
execute as @s at @s rotated as @s run setblock ^40 ^ ^-34 minecraft:cobblestone
execute as @s at @s rotated as @s run setblock ^40 ^ ^34 minecraft:cobblestone
execute as @s at @s rotated as @s run setblock ^40 ^ ^35 minecraft:cobblestone
execute as @s at @s rotated as @s run setblock ^41 ^ ^-34 minecraft:cobblestone
execute as @s at @s rotated as @s run setblock ^41 ^ ^-33 minecraft:cobblestone
execute as @s at @s rotated as @s run setblock ^41 ^ ^33 minecraft:cobblestone
execute as @s at @s rotated as @s run setblock ^41 ^ ^34 minecraft:cobblestone
execute as @s at @s rotated as @s run setblock ^42 ^ ^-33 minecraft:cobblestone
execute as @s at @s rotated as @s run setblock ^42 ^ ^-32 minecraft:cobblestone
execute as @s at @s rotated as @s run setblock ^42 ^ ^32 minecraft:cobblestone
execute as @s at @s rotated as @s run setblock ^42 ^ ^33 minecraft:cobblestone
execute as @s at @s rotated as @s run setblock ^43 ^ ^-31 minecraft:cobblestone
execute as @s at @s rotated as @s run setblock ^43 ^ ^31 minecraft:cobblestone
execute as @s at @s rotated as @s run setblock ^44 ^ ^-30 minecraft:cobblestone
execute as @s at @s rotated as @s run setblock ^44 ^ ^-29 minecraft:cobblestone
execute as @s at @s rotated as @s run setblock ^44 ^ ^29 minecraft:cobblestone
execute as @s at @s rotated as @s run setblock ^44 ^ ^30 minecraft:cobblestone
execute as @s at @s rotated as @s run setblock ^45 ^ ^-28 minecraft:cobblestone
execute as @s at @s rotated as @s run setblock ^45 ^ ^28 minecraft:cobblestone
execute as @s at @s rotated as @s run setblock ^46 ^ ^-27 minecraft:cobblestone
execute as @s at @s rotated as @s run setblock ^46 ^ ^-26 minecraft:cobblestone
execute as @s at @s rotated as @s run setblock ^46 ^ ^26 minecraft:cobblestone
execute as @s at @s rotated as @s run setblock ^46 ^ ^27 minecraft:cobblestone
execute as @s at @s rotated as @s run setblock ^47 ^ ^-25 minecraft:cobblestone
execute as @s at @s rotated as @s run setblock ^47 ^ ^-24 minecraft:cobblestone
execute as @s at @s rotated as @s run setblock ^47 ^ ^24 minecraft:cobblestone
execute as @s at @s rotated as @s run setblock ^47 ^ ^25 minecraft:cobblestone
execute as @s at @s rotated as @s run setblock ^48 ^ ^-23 minecraft:cobblestone
execute as @s at @s rotated as @s run setblock ^48 ^ ^-22 minecraft:cobblestone
execute as @s at @s rotated as @s run setblock ^48 ^ ^-21 minecraft:cobblestone
execute as @s at @s rotated as @s run setblock ^48 ^ ^21 minecraft:cobblestone
execute as @s at @s rotated as @s run setblock ^48 ^ ^22 minecraft:cobblestone
execute as @s at @s rotated as @s run setblock ^48 ^ ^23 minecraft:cobblestone
execute as @s at @s rotated as @s run setblock ^49 ^ ^-21 minecraft:cobblestone
execute as @s at @s rotated as @s run setblock ^49 ^ ^-20 minecraft:cobblestone
execute as @s at @s rotated as @s run setblock ^49 ^ ^-19 minecraft:cobblestone
execute as @s at @s rotated as @s run setblock ^49 ^ ^19 minecraft:cobblestone
execute as @s at @s rotated as @s run setblock ^49 ^ ^20 minecraft:cobblestone
execute as @s at @s rotated as @s run setblock ^49 ^ ^21 minecraft:cobblestone
execute as @s at @s rotated as @s run setblock ^50 ^ ^-19 minecraft:cobblestone
execute as @s at @s rotated as @s run setblock ^50 ^ ^-18 minecraft:cobblestone
execute as @s at @s rotated as @s run setblock ^50 ^ ^-17 minecraft:cobblestone
execute as @s at @s rotated as @s run setblock ^50 ^ ^-16 minecraft:cobblestone
execute as @s at @s rotated as @s run setblock ^50 ^ ^16 minecraft:cobblestone
execute as @s at @s rotated as @s run setblock ^50 ^ ^17 minecraft:cobblestone
execute as @s at @s rotated as @s run setblock ^50 ^ ^18 minecraft:cobblestone
execute as @s at @s rotated as @s run setblock ^50 ^ ^19 minecraft:cobblestone
execute as @s at @s rotated as @s run setblock ^51 ^ ^-16 minecraft:cobblestone
execute as @s at @s rotated as @s run setblock ^51 ^ ^-15 minecraft:cobblestone
execute as @s at @s rotated as @s run setblock ^51 ^ ^-14 minecraft:cobblestone
execute as @s at @s rotated as @s run setblock ^51 ^ ^-13 minecraft:cobblestone
execute as @s at @s rotated as @s run setblock ^51 ^ ^13 minecraft:cobblestone
execute as @s at @s rotated as @s run setblock ^51 ^ ^14 minecraft:cobblestone
execute as @s at @s rotated as @s run setblock ^51 ^ ^15 minecraft:cobblestone
execute as @s at @s rotated as @s run setblock ^51 ^ ^16 minecraft:cobblestone
execute as @s at @s rotated as @s run setblock ^52 ^ ^-12 minecraft:cobblestone
execute as @s at @s rotated as @s run setblock ^52 ^ ^-11 minecraft:cobblestone
execute as @s at @s rotated as @s run setblock ^52 ^ ^-10 minecraft:cobblestone
execute as @s at @s rotated as @s run setblock ^52 ^ ^-9 minecraft:cobblestone
execute as @s at @s rotated as @s run setblock ^52 ^ ^-8 minecraft:cobblestone
execute as @s at @s rotated as @s run setblock ^52 ^ ^-7 minecraft:cobblestone
execute as @s at @s rotated as @s run setblock ^52 ^ ^7 minecraft:cobblestone
execute as @s at @s rotated as @s run setblock ^52 ^ ^8 minecraft:cobblestone
execute as @s at @s rotated as @s run setblock ^52 ^ ^9 minecraft:cobblestone
execute as @s at @s rotated as @s run setblock ^52 ^ ^10 minecraft:cobblestone
execute as @s at @s rotated as @s run setblock ^52 ^ ^11 minecraft:cobblestone
execute as @s at @s rotated as @s run setblock ^52 ^ ^12 minecraft:cobblestone
execute as @s at @s rotated as @s run setblock ^53 ^ ^-7 minecraft:cobblestone
execute as @s at @s rotated as @s run setblock ^53 ^ ^-6 minecraft:cobblestone
execute as @s at @s rotated as @s run setblock ^53 ^ ^-5 minecraft:cobblestone
execute as @s at @s rotated as @s run setblock ^53 ^ ^-4 minecraft:cobblestone
execute as @s at @s rotated as @s run setblock ^53 ^ ^-3 minecraft:cobblestone
execute as @s at @s rotated as @s run setblock ^53 ^ ^-2 minecraft:cobblestone
execute as @s at @s rotated as @s run setblock ^53 ^ ^-1 minecraft:cobblestone
execute as @s at @s rotated as @s run setblock ^53 ^ ^ minecraft:cobblestone
execute as @s at @s rotated as @s run setblock ^53 ^ ^1 minecraft:cobblestone
execute as @s at @s rotated as @s run setblock ^53 ^ ^2 minecraft:cobblestone
execute as @s at @s rotated as @s run setblock ^53 ^ ^3 minecraft:cobblestone
execute as @s at @s rotated as @s run setblock ^53 ^ ^4 minecraft:cobblestone
execute as @s at @s rotated as @s run setblock ^53 ^ ^5 minecraft:cobblestone
execute as @s at @s rotated as @s run setblock ^53 ^ ^6 minecraft:cobblestone
execute as @s at @s rotated as @s run setblock ^53 ^ ^7 minecraft:cobblestone
execute as @s at @s rotated as @s run setblock ^-52 ^1 ^-7 minecraft:mossy_cobblestone
execute as @s at @s rotated as @s run setblock ^-52 ^1 ^-6 minecraft:mossy_cobblestone
execute as @s at @s rotated as @s run setblock ^-52 ^1 ^-5 minecraft:mossy_cobblestone
execute as @s at @s rotated as @s run setblock ^-52 ^1 ^-4 minecraft:mossy_cobblestone
execute as @s at @s rotated as @s run setblock ^-52 ^1 ^-3 minecraft:mossy_cobblestone
execute as @s at @s rotated as @s run setblock ^-52 ^1 ^-2 minecraft:mossy_cobblestone
execute as @s at @s rotated as @s run setblock ^-52 ^1 ^-1 minecraft:mossy_cobblestone
execute as @s at @s rotated as @s run setblock ^-52 ^1 ^ minecraft:mossy_cobblestone
execute as @s at @s rotated as @s run setblock ^-52 ^1 ^1 minecraft:mossy_cobblestone
execute as @s at @s rotated as @s run setblock ^-52 ^1 ^2 minecraft:mossy_cobblestone
execute as @s at @s rotated as @s run setblock ^-52 ^1 ^3 minecraft:mossy_cobblestone
execute as @s at @s rotated as @s run setblock ^-52 ^1 ^4 minecraft:mossy_cobblestone
execute as @s at @s rotated as @s run setblock ^-52 ^1 ^5 minecraft:mossy_cobblestone
execute as @s at @s rotated as @s run setblock ^-52 ^1 ^6 minecraft:mossy_cobblestone
execute as @s at @s rotated as @s run setblock ^-52 ^1 ^7 minecraft:mossy_cobblestone
execute as @s at @s rotated as @s run setblock ^-51 ^1 ^-12 minecraft:mossy_cobblestone
execute as @s at @s rotated as @s run setblock ^-51 ^1 ^-11 minecraft:mossy_cobblestone
execute as @s at @s rotated as @s run setblock ^-51 ^1 ^-10 minecraft:mossy_cobblestone
execute as @s at @s rotated as @s run setblock ^-51 ^1 ^-9 minecraft:mossy_cobblestone
execute as @s at @s rotated as @s run setblock ^-51 ^1 ^-8 minecraft:mossy_cobblestone
execute as @s at @s rotated as @s run setblock ^-51 ^1 ^-7 minecraft:mossy_cobblestone
execute as @s at @s rotated as @s run setblock ^-51 ^1 ^7 minecraft:mossy_cobblestone
execute as @s at @s rotated as @s run setblock ^-51 ^1 ^8 minecraft:mossy_cobblestone
execute as @s at @s rotated as @s run setblock ^-51 ^1 ^9 minecraft:mossy_cobblestone
execute as @s at @s rotated as @s run setblock ^-51 ^1 ^10 minecraft:mossy_cobblestone
execute as @s at @s rotated as @s run setblock ^-51 ^1 ^11 minecraft:mossy_cobblestone
execute as @s at @s rotated as @s run setblock ^-51 ^1 ^12 minecraft:mossy_cobblestone
execute as @s at @s rotated as @s run setblock ^-50 ^1 ^-16 minecraft:mossy_cobblestone
execute as @s at @s rotated as @s run setblock ^-50 ^1 ^-15 minecraft:mossy_cobblestone
execute as @s at @s rotated as @s run setblock ^-50 ^1 ^-14 minecraft:mossy_cobblestone
execute as @s at @s rotated as @s run setblock ^-50 ^1 ^-13 minecraft:mossy_cobblestone
execute as @s at @s rotated as @s run setblock ^-50 ^1 ^13 minecraft:mossy_cobblestone
execute as @s at @s rotated as @s run setblock ^-50 ^1 ^14 minecraft:mossy_cobblestone
execute as @s at @s rotated as @s run setblock ^-50 ^1 ^15 minecraft:mossy_cobblestone
execute as @s at @s rotated as @s run setblock ^-50 ^1 ^16 minecraft:mossy_cobblestone
execute as @s at @s rotated as @s run setblock ^-49 ^1 ^-18 minecraft:mossy_cobblestone
execute as @s at @s rotated as @s run setblock ^-49 ^1 ^-17 minecraft:mossy_cobblestone
execute as @s at @s rotated as @s run setblock ^-49 ^1 ^-16 minecraft:mossy_cobblestone
execute as @s at @s rotated as @s run setblock ^-49 ^1 ^16 minecraft:mossy_cobblestone
execute as @s at @s rotated as @s run setblock ^-49 ^1 ^17 minecraft:mossy_cobblestone
execute as @s at @s rotated as @s run setblock ^-49 ^1 ^18 minecraft:mossy_cobblestone
execute as @s at @s rotated as @s run setblock ^-48 ^1 ^-21 minecraft:mossy_cobblestone
execute as @s at @s rotated as @s run setblock ^-48 ^1 ^-20 minecraft:mossy_cobblestone
execute as @s at @s rotated as @s run setblock ^-48 ^1 ^-19 minecraft:mossy_cobblestone
execute as @s at @s rotated as @s run setblock ^-48 ^1 ^19 minecraft:mossy_cobblestone
execute as @s at @s rotated as @s run setblock ^-48 ^1 ^20 minecraft:mossy_cobblestone
execute as @s at @s rotated as @s run setblock ^-48 ^1 ^21 minecraft:mossy_cobblestone
execute as @s at @s rotated as @s run setblock ^-47 ^1 ^-23 minecraft:mossy_cobblestone
execute as @s at @s rotated as @s run setblock ^-47 ^1 ^-22 minecraft:mossy_cobblestone
execute as @s at @s rotated as @s run setblock ^-47 ^1 ^22 minecraft:mossy_cobblestone
execute as @s at @s rotated as @s run setblock ^-47 ^1 ^23 minecraft:mossy_cobblestone
execute as @s at @s rotated as @s run setblock ^-46 ^1 ^-25 minecraft:mossy_cobblestone
execute as @s at @s rotated as @s run setblock ^-46 ^1 ^-24 minecraft:mossy_cobblestone
execute as @s at @s rotated as @s run setblock ^-46 ^1 ^-23 minecraft:mossy_cobblestone
execute as @s at @s rotated as @s run setblock ^-46 ^1 ^23 minecraft:mossy_cobblestone
execute as @s at @s rotated as @s run setblock ^-46 ^1 ^24 minecraft:mossy_cobblestone
execute as @s at @s rotated as @s run setblock ^-46 ^1 ^25 minecraft:mossy_cobblestone
execute as @s at @s rotated as @s run setblock ^-45 ^1 ^-27 minecraft:mossy_cobblestone
execute as @s at @s rotated as @s run setblock ^-45 ^1 ^-26 minecraft:mossy_cobblestone
execute as @s at @s rotated as @s run setblock ^-45 ^1 ^26 minecraft:mossy_cobblestone
execute as @s at @s rotated as @s run setblock ^-45 ^1 ^27 minecraft:mossy_cobblestone
execute as @s at @s rotated as @s run setblock ^-44 ^1 ^-28 minecraft:mossy_cobblestone
execute as @s at @s rotated as @s run setblock ^-44 ^1 ^-27 minecraft:mossy_cobblestone
execute as @s at @s rotated as @s run setblock ^-44 ^1 ^27 minecraft:mossy_cobblestone
execute as @s at @s rotated as @s run setblock ^-44 ^1 ^28 minecraft:mossy_cobblestone
execute as @s at @s rotated as @s run setblock ^-43 ^1 ^-30 minecraft:mossy_cobblestone
execute as @s at @s rotated as @s run setblock ^-43 ^1 ^-29 minecraft:mossy_cobblestone
execute as @s at @s rotated as @s run setblock ^-43 ^1 ^29 minecraft:mossy_cobblestone
execute as @s at @s rotated as @s run setblock ^-43 ^1 ^30 minecraft:mossy_cobblestone
execute as @s at @s rotated as @s run setblock ^-42 ^1 ^-31 minecraft:mossy_cobblestone
execute as @s at @s rotated as @s run setblock ^-42 ^1 ^-30 minecraft:mossy_cobblestone
execute as @s at @s rotated as @s run setblock ^-42 ^1 ^30 minecraft:mossy_cobblestone
execute as @s at @s rotated as @s run setblock ^-42 ^1 ^31 minecraft:mossy_cobblestone
execute as @s at @s rotated as @s run setblock ^-41 ^1 ^-32 minecraft:mossy_cobblestone
execute as @s at @s rotated as @s run setblock ^-41 ^1 ^-31 minecraft:mossy_cobblestone
execute as @s at @s rotated as @s run setblock ^-41 ^1 ^31 minecraft:mossy_cobblestone
execute as @s at @s rotated as @s run setblock ^-41 ^1 ^32 minecraft:mossy_cobblestone
execute as @s at @s rotated as @s run setblock ^-40 ^1 ^-34 minecraft:mossy_cobblestone
execute as @s at @s rotated as @s run setblock ^-40 ^1 ^-33 minecraft:mossy_cobblestone
execute as @s at @s rotated as @s run setblock ^-40 ^1 ^33 minecraft:mossy_cobblestone
execute as @s at @s rotated as @s run setblock ^-40 ^1 ^34 minecraft:mossy_cobblestone
execute as @s at @s rotated as @s run setblock ^-39 ^1 ^-35 minecraft:mossy_cobblestone
execute as @s at @s rotated as @s run setblock ^-39 ^1 ^-34 minecraft:mossy_cobblestone
execute as @s at @s rotated as @s run setblock ^-39 ^1 ^34 minecraft:mossy_cobblestone
execute as @s at @s rotated as @s run setblock ^-39 ^1 ^35 minecraft:mossy_cobblestone
execute as @s at @s rotated as @s run setblock ^-38 ^1 ^-36 minecraft:mossy_cobblestone
execute as @s at @s rotated as @s run setblock ^-38 ^1 ^-35 minecraft:mossy_cobblestone
execute as @s at @s rotated as @s run setblock ^-38 ^1 ^35 minecraft:mossy_cobblestone
execute as @s at @s rotated as @s run setblock ^-38 ^1 ^36 minecraft:mossy_cobblestone
execute as @s at @s rotated as @s run setblock ^-37 ^1 ^-37 minecraft:mossy_cobblestone
execute as @s at @s rotated as @s run setblock ^-37 ^1 ^-36 minecraft:mossy_cobblestone
execute as @s at @s rotated as @s run setblock ^-37 ^1 ^36 minecraft:mossy_cobblestone
execute as @s at @s rotated as @s run setblock ^-37 ^1 ^37 minecraft:mossy_cobblestone
execute as @s at @s rotated as @s run setblock ^-36 ^1 ^-38 minecraft:mossy_cobblestone
execute as @s at @s rotated as @s run setblock ^-36 ^1 ^-37 minecraft:mossy_cobblestone
execute as @s at @s rotated as @s run setblock ^-36 ^1 ^37 minecraft:mossy_cobblestone
execute as @s at @s rotated as @s run setblock ^-36 ^1 ^38 minecraft:mossy_cobblestone
execute as @s at @s rotated as @s run setblock ^-35 ^1 ^-39 minecraft:mossy_cobblestone
execute as @s at @s rotated as @s run setblock ^-35 ^1 ^-38 minecraft:mossy_cobblestone
execute as @s at @s rotated as @s run setblock ^-35 ^1 ^38 minecraft:mossy_cobblestone
execute as @s at @s rotated as @s run setblock ^-35 ^1 ^39 minecraft:mossy_cobblestone
execute as @s at @s rotated as @s run setblock ^-34 ^1 ^-39 minecraft:mossy_cobblestone
execute as @s at @s rotated as @s run setblock ^-34 ^1 ^39 minecraft:mossy_cobblestone
execute as @s at @s rotated as @s run setblock ^-33 ^1 ^-40 minecraft:mossy_cobblestone
execute as @s at @s rotated as @s run setblock ^-33 ^1 ^40 minecraft:mossy_cobblestone
execute as @s at @s rotated as @s run setblock ^-32 ^1 ^-41 minecraft:mossy_cobblestone
execute as @s at @s rotated as @s run setblock ^-32 ^1 ^41 minecraft:mossy_cobblestone
execute as @s at @s rotated as @s run setblock ^-31 ^1 ^-42 minecraft:mossy_cobblestone
execute as @s at @s rotated as @s run setblock ^-31 ^1 ^42 minecraft:mossy_cobblestone
execute as @s at @s rotated as @s run setblock ^-30 ^1 ^-43 minecraft:mossy_cobblestone
execute as @s at @s rotated as @s run setblock ^-30 ^1 ^-42 minecraft:mossy_cobblestone
execute as @s at @s rotated as @s run setblock ^-30 ^1 ^42 minecraft:mossy_cobblestone
execute as @s at @s rotated as @s run setblock ^-30 ^1 ^43 minecraft:mossy_cobblestone
execute as @s at @s rotated as @s run setblock ^-29 ^1 ^-43 minecraft:mossy_cobblestone
execute as @s at @s rotated as @s run setblock ^-29 ^1 ^43 minecraft:mossy_cobblestone
execute as @s at @s rotated as @s run setblock ^-28 ^1 ^-44 minecraft:mossy_cobblestone
execute as @s at @s rotated as @s run setblock ^-28 ^1 ^44 minecraft:mossy_cobblestone
execute as @s at @s rotated as @s run setblock ^-27 ^1 ^-45 minecraft:mossy_cobblestone
execute as @s at @s rotated as @s run setblock ^-27 ^1 ^-44 minecraft:mossy_cobblestone
execute as @s at @s rotated as @s run setblock ^-27 ^1 ^44 minecraft:mossy_cobblestone
execute as @s at @s rotated as @s run setblock ^-27 ^1 ^45 minecraft:mossy_cobblestone
execute as @s at @s rotated as @s run setblock ^-26 ^1 ^-45 minecraft:mossy_cobblestone
execute as @s at @s rotated as @s run setblock ^-26 ^1 ^45 minecraft:mossy_cobblestone
execute as @s at @s rotated as @s run setblock ^-25 ^1 ^-46 minecraft:mossy_cobblestone
execute as @s at @s rotated as @s run setblock ^-25 ^1 ^-45 minecraft:mossy_cobblestone
execute as @s at @s rotated as @s run setblock ^-25 ^1 ^45 minecraft:mossy_cobblestone
execute as @s at @s rotated as @s run setblock ^-25 ^1 ^46 minecraft:mossy_cobblestone
execute as @s at @s rotated as @s run setblock ^-24 ^1 ^-46 minecraft:mossy_cobblestone
execute as @s at @s rotated as @s run setblock ^-24 ^1 ^46 minecraft:mossy_cobblestone
execute as @s at @s rotated as @s run setblock ^-23 ^1 ^-47 minecraft:mossy_cobblestone
execute as @s at @s rotated as @s run setblock ^-23 ^1 ^47 minecraft:mossy_cobblestone
execute as @s at @s rotated as @s run setblock ^-22 ^1 ^-47 minecraft:mossy_cobblestone
execute as @s at @s rotated as @s run setblock ^-22 ^1 ^47 minecraft:mossy_cobblestone
execute as @s at @s rotated as @s run setblock ^-21 ^1 ^-48 minecraft:mossy_cobblestone
execute as @s at @s rotated as @s run setblock ^-21 ^1 ^-47 minecraft:mossy_cobblestone
execute as @s at @s rotated as @s run setblock ^-21 ^1 ^47 minecraft:mossy_cobblestone
execute as @s at @s rotated as @s run setblock ^-21 ^1 ^48 minecraft:mossy_cobblestone
execute as @s at @s rotated as @s run setblock ^-20 ^1 ^-48 minecraft:mossy_cobblestone
execute as @s at @s rotated as @s run setblock ^-20 ^1 ^48 minecraft:mossy_cobblestone
execute as @s at @s rotated as @s run setblock ^-19 ^1 ^-48 minecraft:mossy_cobblestone
execute as @s at @s rotated as @s run setblock ^-19 ^1 ^48 minecraft:mossy_cobblestone
execute as @s at @s rotated as @s run setblock ^-18 ^1 ^-49 minecraft:mossy_cobblestone
execute as @s at @s rotated as @s run setblock ^-18 ^1 ^49 minecraft:mossy_cobblestone
execute as @s at @s rotated as @s run setblock ^-17 ^1 ^-49 minecraft:mossy_cobblestone
execute as @s at @s rotated as @s run setblock ^-17 ^1 ^49 minecraft:mossy_cobblestone
execute as @s at @s rotated as @s run setblock ^-16 ^1 ^-50 minecraft:mossy_cobblestone
execute as @s at @s rotated as @s run setblock ^-16 ^1 ^-49 minecraft:mossy_cobblestone
execute as @s at @s rotated as @s run setblock ^-16 ^1 ^49 minecraft:mossy_cobblestone
execute as @s at @s rotated as @s run setblock ^-16 ^1 ^50 minecraft:mossy_cobblestone
execute as @s at @s rotated as @s run setblock ^-15 ^1 ^-50 minecraft:mossy_cobblestone
execute as @s at @s rotated as @s run setblock ^-15 ^1 ^50 minecraft:mossy_cobblestone
execute as @s at @s rotated as @s run setblock ^-14 ^1 ^-50 minecraft:mossy_cobblestone
execute as @s at @s rotated as @s run setblock ^-14 ^1 ^50 minecraft:mossy_cobblestone
execute as @s at @s rotated as @s run setblock ^-13 ^1 ^-50 minecraft:mossy_cobblestone
execute as @s at @s rotated as @s run setblock ^-13 ^1 ^50 minecraft:mossy_cobblestone
execute as @s at @s rotated as @s run setblock ^-12 ^1 ^-51 minecraft:mossy_cobblestone
execute as @s at @s rotated as @s run setblock ^-12 ^1 ^51 minecraft:mossy_cobblestone
execute as @s at @s rotated as @s run setblock ^-11 ^1 ^-51 minecraft:mossy_cobblestone
execute as @s at @s rotated as @s run setblock ^-11 ^1 ^51 minecraft:mossy_cobblestone
execute as @s at @s rotated as @s run setblock ^-10 ^1 ^-51 minecraft:mossy_cobblestone
execute as @s at @s rotated as @s run setblock ^-10 ^1 ^51 minecraft:mossy_cobblestone
execute as @s at @s rotated as @s run setblock ^-9 ^1 ^-51 minecraft:mossy_cobblestone
execute as @s at @s rotated as @s run setblock ^-9 ^1 ^51 minecraft:mossy_cobblestone
execute as @s at @s rotated as @s run setblock ^-8 ^1 ^-51 minecraft:mossy_cobblestone
execute as @s at @s rotated as @s run setblock ^-8 ^1 ^51 minecraft:mossy_cobblestone
execute as @s at @s rotated as @s run setblock ^-7 ^1 ^-52 minecraft:mossy_cobblestone
execute as @s at @s rotated as @s run setblock ^-7 ^1 ^-51 minecraft:mossy_cobblestone
execute as @s at @s rotated as @s run setblock ^-7 ^1 ^51 minecraft:mossy_cobblestone
execute as @s at @s rotated as @s run setblock ^-7 ^1 ^52 minecraft:mossy_cobblestone
execute as @s at @s rotated as @s run setblock ^-6 ^1 ^-52 minecraft:mossy_cobblestone
execute as @s at @s rotated as @s run setblock ^-6 ^1 ^52 minecraft:mossy_cobblestone
execute as @s at @s rotated as @s run setblock ^-5 ^1 ^-52 minecraft:mossy_cobblestone
execute as @s at @s rotated as @s run setblock ^-5 ^1 ^52 minecraft:mossy_cobblestone
execute as @s at @s rotated as @s run setblock ^-4 ^1 ^-52 minecraft:mossy_cobblestone
execute as @s at @s rotated as @s run setblock ^-4 ^1 ^52 minecraft:mossy_cobblestone
execute as @s at @s rotated as @s run setblock ^-3 ^1 ^-52 minecraft:mossy_cobblestone
execute as @s at @s rotated as @s run setblock ^-3 ^1 ^52 minecraft:mossy_cobblestone
execute as @s at @s rotated as @s run setblock ^-2 ^1 ^-52 minecraft:mossy_cobblestone
execute as @s at @s rotated as @s run setblock ^-2 ^1 ^52 minecraft:mossy_cobblestone
execute as @s at @s rotated as @s run setblock ^-1 ^1 ^-52 minecraft:mossy_cobblestone
execute as @s at @s rotated as @s run setblock ^-1 ^1 ^52 minecraft:mossy_cobblestone
execute as @s at @s rotated as @s run setblock ^ ^1 ^-52 minecraft:mossy_cobblestone
execute as @s at @s rotated as @s run setblock ^ ^1 ^52 minecraft:mossy_cobblestone
execute as @s at @s rotated as @s run setblock ^1 ^1 ^-52 minecraft:mossy_cobblestone
execute as @s at @s rotated as @s run setblock ^1 ^1 ^52 minecraft:mossy_cobblestone
execute as @s at @s rotated as @s run setblock ^2 ^1 ^-52 minecraft:mossy_cobblestone
execute as @s at @s rotated as @s run setblock ^2 ^1 ^52 minecraft:mossy_cobblestone
execute as @s at @s rotated as @s run setblock ^3 ^1 ^-52 minecraft:mossy_cobblestone
execute as @s at @s rotated as @s run setblock ^3 ^1 ^52 minecraft:mossy_cobblestone
execute as @s at @s rotated as @s run setblock ^4 ^1 ^-52 minecraft:mossy_cobblestone
execute as @s at @s rotated as @s run setblock ^4 ^1 ^52 minecraft:mossy_cobblestone
execute as @s at @s rotated as @s run setblock ^5 ^1 ^-52 minecraft:mossy_cobblestone
execute as @s at @s rotated as @s run setblock ^5 ^1 ^52 minecraft:mossy_cobblestone
execute as @s at @s rotated as @s run setblock ^6 ^1 ^-52 minecraft:mossy_cobblestone
execute as @s at @s rotated as @s run setblock ^6 ^1 ^52 minecraft:mossy_cobblestone
execute as @s at @s rotated as @s run setblock ^7 ^1 ^-52 minecraft:mossy_cobblestone
execute as @s at @s rotated as @s run setblock ^7 ^1 ^52 minecraft:mossy_cobblestone
execute as @s at @s rotated as @s run setblock ^8 ^1 ^-51 minecraft:mossy_cobblestone
execute as @s at @s rotated as @s run setblock ^8 ^1 ^51 minecraft:mossy_cobblestone
execute as @s at @s rotated as @s run setblock ^9 ^1 ^-51 minecraft:mossy_cobblestone
execute as @s at @s rotated as @s run setblock ^9 ^1 ^51 minecraft:mossy_cobblestone
execute as @s at @s rotated as @s run setblock ^10 ^1 ^-51 minecraft:mossy_cobblestone
execute as @s at @s rotated as @s run setblock ^10 ^1 ^51 minecraft:mossy_cobblestone
execute as @s at @s rotated as @s run setblock ^11 ^1 ^-51 minecraft:mossy_cobblestone
execute as @s at @s rotated as @s run setblock ^11 ^1 ^51 minecraft:mossy_cobblestone
execute as @s at @s rotated as @s run setblock ^12 ^1 ^-51 minecraft:mossy_cobblestone
execute as @s at @s rotated as @s run setblock ^12 ^1 ^51 minecraft:mossy_cobblestone
execute as @s at @s rotated as @s run setblock ^13 ^1 ^-50 minecraft:mossy_cobblestone
execute as @s at @s rotated as @s run setblock ^13 ^1 ^50 minecraft:mossy_cobblestone
execute as @s at @s rotated as @s run setblock ^14 ^1 ^-50 minecraft:mossy_cobblestone
execute as @s at @s rotated as @s run setblock ^14 ^1 ^50 minecraft:mossy_cobblestone
execute as @s at @s rotated as @s run setblock ^15 ^1 ^-50 minecraft:mossy_cobblestone
execute as @s at @s rotated as @s run setblock ^15 ^1 ^50 minecraft:mossy_cobblestone
execute as @s at @s rotated as @s run setblock ^16 ^1 ^-50 minecraft:mossy_cobblestone
execute as @s at @s rotated as @s run setblock ^16 ^1 ^-49 minecraft:mossy_cobblestone
execute as @s at @s rotated as @s run setblock ^16 ^1 ^49 minecraft:mossy_cobblestone
execute as @s at @s rotated as @s run setblock ^16 ^1 ^50 minecraft:mossy_cobblestone
execute as @s at @s rotated as @s run setblock ^17 ^1 ^-49 minecraft:mossy_cobblestone
execute as @s at @s rotated as @s run setblock ^17 ^1 ^49 minecraft:mossy_cobblestone
execute as @s at @s rotated as @s run setblock ^18 ^1 ^-49 minecraft:mossy_cobblestone
execute as @s at @s rotated as @s run setblock ^18 ^1 ^49 minecraft:mossy_cobblestone
execute as @s at @s rotated as @s run setblock ^19 ^1 ^-49 minecraft:mossy_cobblestone
execute as @s at @s rotated as @s run setblock ^19 ^1 ^-48 minecraft:mossy_cobblestone
execute as @s at @s rotated as @s run setblock ^19 ^1 ^48 minecraft:mossy_cobblestone
execute as @s at @s rotated as @s run setblock ^19 ^1 ^49 minecraft:mossy_cobblestone
execute as @s at @s rotated as @s run setblock ^20 ^1 ^-48 minecraft:mossy_cobblestone
execute as @s at @s rotated as @s run setblock ^20 ^1 ^48 minecraft:mossy_cobblestone
execute as @s at @s rotated as @s run setblock ^21 ^1 ^-48 minecraft:mossy_cobblestone
execute as @s at @s rotated as @s run setblock ^21 ^1 ^-47 minecraft:mossy_cobblestone
execute as @s at @s rotated as @s run setblock ^21 ^1 ^47 minecraft:mossy_cobblestone
execute as @s at @s rotated as @s run setblock ^21 ^1 ^48 minecraft:mossy_cobblestone
execute as @s at @s rotated as @s run setblock ^22 ^1 ^-47 minecraft:mossy_cobblestone
execute as @s at @s rotated as @s run setblock ^22 ^1 ^47 minecraft:mossy_cobblestone
execute as @s at @s rotated as @s run setblock ^23 ^1 ^-47 minecraft:mossy_cobblestone
execute as @s at @s rotated as @s run setblock ^23 ^1 ^-46 minecraft:mossy_cobblestone
execute as @s at @s rotated as @s run setblock ^23 ^1 ^46 minecraft:mossy_cobblestone
execute as @s at @s rotated as @s run setblock ^23 ^1 ^47 minecraft:mossy_cobblestone
execute as @s at @s rotated as @s run setblock ^24 ^1 ^-46 minecraft:mossy_cobblestone
execute as @s at @s rotated as @s run setblock ^24 ^1 ^46 minecraft:mossy_cobblestone
execute as @s at @s rotated as @s run setblock ^25 ^1 ^-46 minecraft:mossy_cobblestone
execute as @s at @s rotated as @s run setblock ^25 ^1 ^-45 minecraft:mossy_cobblestone
execute as @s at @s rotated as @s run setblock ^25 ^1 ^45 minecraft:mossy_cobblestone
execute as @s at @s rotated as @s run setblock ^25 ^1 ^46 minecraft:mossy_cobblestone
execute as @s at @s rotated as @s run setblock ^26 ^1 ^-45 minecraft:mossy_cobblestone
execute as @s at @s rotated as @s run setblock ^26 ^1 ^45 minecraft:mossy_cobblestone
execute as @s at @s rotated as @s run setblock ^27 ^1 ^-45 minecraft:mossy_cobblestone
execute as @s at @s rotated as @s run setblock ^27 ^1 ^-44 minecraft:mossy_cobblestone
execute as @s at @s rotated as @s run setblock ^27 ^1 ^44 minecraft:mossy_cobblestone
execute as @s at @s rotated as @s run setblock ^27 ^1 ^45 minecraft:mossy_cobblestone
execute as @s at @s rotated as @s run setblock ^28 ^1 ^-44 minecraft:mossy_cobblestone
execute as @s at @s rotated as @s run setblock ^28 ^1 ^44 minecraft:mossy_cobblestone
execute as @s at @s rotated as @s run setblock ^29 ^1 ^-43 minecraft:mossy_cobblestone
execute as @s at @s rotated as @s run setblock ^29 ^1 ^43 minecraft:mossy_cobblestone
execute as @s at @s rotated as @s run setblock ^30 ^1 ^-43 minecraft:mossy_cobblestone
execute as @s at @s rotated as @s run setblock ^30 ^1 ^-42 minecraft:mossy_cobblestone
execute as @s at @s rotated as @s run setblock ^30 ^1 ^42 minecraft:mossy_cobblestone
execute as @s at @s rotated as @s run setblock ^30 ^1 ^43 minecraft:mossy_cobblestone
execute as @s at @s rotated as @s run setblock ^31 ^1 ^-42 minecraft:mossy_cobblestone
execute as @s at @s rotated as @s run setblock ^31 ^1 ^-41 minecraft:mossy_cobblestone
execute as @s at @s rotated as @s run setblock ^31 ^1 ^41 minecraft:mossy_cobblestone
execute as @s at @s rotated as @s run setblock ^31 ^1 ^42 minecraft:mossy_cobblestone
execute as @s at @s rotated as @s run setblock ^32 ^1 ^-41 minecraft:mossy_cobblestone
execute as @s at @s rotated as @s run setblock ^32 ^1 ^41 minecraft:mossy_cobblestone
execute as @s at @s rotated as @s run setblock ^33 ^1 ^-41 minecraft:mossy_cobblestone
execute as @s at @s rotated as @s run setblock ^33 ^1 ^-40 minecraft:mossy_cobblestone
execute as @s at @s rotated as @s run setblock ^33 ^1 ^40 minecraft:mossy_cobblestone
execute as @s at @s rotated as @s run setblock ^33 ^1 ^41 minecraft:mossy_cobblestone
execute as @s at @s rotated as @s run setblock ^34 ^1 ^-40 minecraft:mossy_cobblestone
execute as @s at @s rotated as @s run setblock ^34 ^1 ^-39 minecraft:mossy_cobblestone
execute as @s at @s rotated as @s run setblock ^34 ^1 ^39 minecraft:mossy_cobblestone
execute as @s at @s rotated as @s run setblock ^34 ^1 ^40 minecraft:mossy_cobblestone
execute as @s at @s rotated as @s run setblock ^35 ^1 ^-39 minecraft:mossy_cobblestone
execute as @s at @s rotated as @s run setblock ^35 ^1 ^-38 minecraft:mossy_cobblestone
execute as @s at @s rotated as @s run setblock ^35 ^1 ^38 minecraft:mossy_cobblestone
execute as @s at @s rotated as @s run setblock ^35 ^1 ^39 minecraft:mossy_cobblestone
execute as @s at @s rotated as @s run setblock ^36 ^1 ^-38 minecraft:mossy_cobblestone
execute as @s at @s rotated as @s run setblock ^36 ^1 ^-37 minecraft:mossy_cobblestone
execute as @s at @s rotated as @s run setblock ^36 ^1 ^37 minecraft:mossy_cobblestone
execute as @s at @s rotated as @s run setblock ^36 ^1 ^38 minecraft:mossy_cobblestone
execute as @s at @s rotated as @s run setblock ^37 ^1 ^-37 minecraft:mossy_cobblestone
execute as @s at @s rotated as @s run setblock ^37 ^1 ^-36 minecraft:mossy_cobblestone
execute as @s at @s rotated as @s run setblock ^37 ^1 ^36 minecraft:mossy_cobblestone
execute as @s at @s rotated as @s run setblock ^37 ^1 ^37 minecraft:mossy_cobblestone
execute as @s at @s rotated as @s run setblock ^38 ^1 ^-36 minecraft:mossy_cobblestone
execute as @s at @s rotated as @s run setblock ^38 ^1 ^-35 minecraft:mossy_cobblestone
execute as @s at @s rotated as @s run setblock ^38 ^1 ^35 minecraft:mossy_cobblestone
execute as @s at @s rotated as @s run setblock ^38 ^1 ^36 minecraft:mossy_cobblestone
execute as @s at @s rotated as @s run setblock ^39 ^1 ^-35 minecraft:mossy_cobblestone
execute as @s at @s rotated as @s run setblock ^39 ^1 ^-34 minecraft:mossy_cobblestone
execute as @s at @s rotated as @s run setblock ^39 ^1 ^34 minecraft:mossy_cobblestone
execute as @s at @s rotated as @s run setblock ^39 ^1 ^35 minecraft:mossy_cobblestone
execute as @s at @s rotated as @s run setblock ^40 ^1 ^-34 minecraft:mossy_cobblestone
execute as @s at @s rotated as @s run setblock ^40 ^1 ^-33 minecraft:mossy_cobblestone
execute as @s at @s rotated as @s run setblock ^40 ^1 ^33 minecraft:mossy_cobblestone
execute as @s at @s rotated as @s run setblock ^40 ^1 ^34 minecraft:mossy_cobblestone
execute as @s at @s rotated as @s run setblock ^41 ^1 ^-32 minecraft:mossy_cobblestone
execute as @s at @s rotated as @s run setblock ^41 ^1 ^32 minecraft:mossy_cobblestone
execute as @s at @s rotated as @s run setblock ^42 ^1 ^-31 minecraft:mossy_cobblestone
execute as @s at @s rotated as @s run setblock ^42 ^1 ^-30 minecraft:mossy_cobblestone
execute as @s at @s rotated as @s run setblock ^42 ^1 ^30 minecraft:mossy_cobblestone
execute as @s at @s rotated as @s run setblock ^42 ^1 ^31 minecraft:mossy_cobblestone
execute as @s at @s rotated as @s run setblock ^43 ^1 ^-30 minecraft:mossy_cobblestone
execute as @s at @s rotated as @s run setblock ^43 ^1 ^-29 minecraft:mossy_cobblestone
execute as @s at @s rotated as @s run setblock ^43 ^1 ^29 minecraft:mossy_cobblestone
execute as @s at @s rotated as @s run setblock ^43 ^1 ^30 minecraft:mossy_cobblestone
execute as @s at @s rotated as @s run setblock ^44 ^1 ^-28 minecraft:mossy_cobblestone
execute as @s at @s rotated as @s run setblock ^44 ^1 ^-27 minecraft:mossy_cobblestone
execute as @s at @s rotated as @s run setblock ^44 ^1 ^27 minecraft:mossy_cobblestone
execute as @s at @s rotated as @s run setblock ^44 ^1 ^28 minecraft:mossy_cobblestone
execute as @s at @s rotated as @s run setblock ^45 ^1 ^-27 minecraft:mossy_cobblestone
execute as @s at @s rotated as @s run setblock ^45 ^1 ^-26 minecraft:mossy_cobblestone
execute as @s at @s rotated as @s run setblock ^45 ^1 ^-25 minecraft:mossy_cobblestone
execute as @s at @s rotated as @s run setblock ^45 ^1 ^25 minecraft:mossy_cobblestone
execute as @s at @s rotated as @s run setblock ^45 ^1 ^26 minecraft:mossy_cobblestone
execute as @s at @s rotated as @s run setblock ^45 ^1 ^27 minecraft:mossy_cobblestone
execute as @s at @s rotated as @s run setblock ^46 ^1 ^-25 minecraft:mossy_cobblestone
execute as @s at @s rotated as @s run setblock ^46 ^1 ^-24 minecraft:mossy_cobblestone
execute as @s at @s rotated as @s run setblock ^46 ^1 ^24 minecraft:mossy_cobblestone
execute as @s at @s rotated as @s run setblock ^46 ^1 ^25 minecraft:mossy_cobblestone
execute as @s at @s rotated as @s run setblock ^47 ^1 ^-23 minecraft:mossy_cobblestone
execute as @s at @s rotated as @s run setblock ^47 ^1 ^-22 minecraft:mossy_cobblestone
execute as @s at @s rotated as @s run setblock ^47 ^1 ^-21 minecraft:mossy_cobblestone
execute as @s at @s rotated as @s run setblock ^47 ^1 ^21 minecraft:mossy_cobblestone
execute as @s at @s rotated as @s run setblock ^47 ^1 ^22 minecraft:mossy_cobblestone
execute as @s at @s rotated as @s run setblock ^47 ^1 ^23 minecraft:mossy_cobblestone
execute as @s at @s rotated as @s run setblock ^48 ^1 ^-21 minecraft:mossy_cobblestone
execute as @s at @s rotated as @s run setblock ^48 ^1 ^-20 minecraft:mossy_cobblestone
execute as @s at @s rotated as @s run setblock ^48 ^1 ^-19 minecraft:mossy_cobblestone
execute as @s at @s rotated as @s run setblock ^48 ^1 ^19 minecraft:mossy_cobblestone
execute as @s at @s rotated as @s run setblock ^48 ^1 ^20 minecraft:mossy_cobblestone
execute as @s at @s rotated as @s run setblock ^48 ^1 ^21 minecraft:mossy_cobblestone
execute as @s at @s rotated as @s run setblock ^49 ^1 ^-19 minecraft:mossy_cobblestone
execute as @s at @s rotated as @s run setblock ^49 ^1 ^-18 minecraft:mossy_cobblestone
execute as @s at @s rotated as @s run setblock ^49 ^1 ^-17 minecraft:mossy_cobblestone
execute as @s at @s rotated as @s run setblock ^49 ^1 ^-16 minecraft:mossy_cobblestone
execute as @s at @s rotated as @s run setblock ^49 ^1 ^16 minecraft:mossy_cobblestone
execute as @s at @s rotated as @s run setblock ^49 ^1 ^17 minecraft:mossy_cobblestone
execute as @s at @s rotated as @s run setblock ^49 ^1 ^18 minecraft:mossy_cobblestone
execute as @s at @s rotated as @s run setblock ^49 ^1 ^19 minecraft:mossy_cobblestone
execute as @s at @s rotated as @s run setblock ^50 ^1 ^-16 minecraft:mossy_cobblestone
execute as @s at @s rotated as @s run setblock ^50 ^1 ^-15 minecraft:mossy_cobblestone
execute as @s at @s rotated as @s run setblock ^50 ^1 ^-14 minecraft:mossy_cobblestone
execute as @s at @s rotated as @s run setblock ^50 ^1 ^-13 minecraft:mossy_cobblestone
execute as @s at @s rotated as @s run setblock ^50 ^1 ^13 minecraft:mossy_cobblestone
execute as @s at @s rotated as @s run setblock ^50 ^1 ^14 minecraft:mossy_cobblestone
execute as @s at @s rotated as @s run setblock ^50 ^1 ^15 minecraft:mossy_cobblestone
execute as @s at @s rotated as @s run setblock ^50 ^1 ^16 minecraft:mossy_cobblestone
execute as @s at @s rotated as @s run setblock ^51 ^1 ^-12 minecraft:mossy_cobblestone
execute as @s at @s rotated as @s run setblock ^51 ^1 ^-11 minecraft:mossy_cobblestone
execute as @s at @s rotated as @s run setblock ^51 ^1 ^-10 minecraft:mossy_cobblestone
execute as @s at @s rotated as @s run setblock ^51 ^1 ^-9 minecraft:mossy_cobblestone
execute as @s at @s rotated as @s run setblock ^51 ^1 ^-8 minecraft:mossy_cobblestone
execute as @s at @s rotated as @s run setblock ^51 ^1 ^-7 minecraft:mossy_cobblestone
execute as @s at @s rotated as @s run setblock ^51 ^1 ^7 minecraft:mossy_cobblestone
execute as @s at @s rotated as @s run setblock ^51 ^1 ^8 minecraft:mossy_cobblestone
execute as @s at @s rotated as @s run setblock ^51 ^1 ^9 minecraft:mossy_cobblestone
execute as @s at @s rotated as @s run setblock ^51 ^1 ^10 minecraft:mossy_cobblestone
execute as @s at @s rotated as @s run setblock ^51 ^1 ^11 minecraft:mossy_cobblestone
execute as @s at @s rotated as @s run setblock ^51 ^1 ^12 minecraft:mossy_cobblestone
execute as @s at @s rotated as @s run setblock ^52 ^1 ^-7 minecraft:mossy_cobblestone
execute as @s at @s rotated as @s run setblock ^52 ^1 ^-6 minecraft:mossy_cobblestone
execute as @s at @s rotated as @s run setblock ^52 ^1 ^-5 minecraft:mossy_cobblestone
execute as @s at @s rotated as @s run setblock ^52 ^1 ^-4 minecraft:mossy_cobblestone
execute as @s at @s rotated as @s run setblock ^52 ^1 ^-3 minecraft:mossy_cobblestone
execute as @s at @s rotated as @s run setblock ^52 ^1 ^-2 minecraft:mossy_cobblestone
execute as @s at @s rotated as @s run setblock ^52 ^1 ^-1 minecraft:mossy_cobblestone
execute as @s at @s rotated as @s run setblock ^52 ^1 ^ minecraft:mossy_cobblestone
execute as @s at @s rotated as @s run setblock ^52 ^1 ^1 minecraft:mossy_cobblestone
execute as @s at @s rotated as @s run setblock ^52 ^1 ^2 minecraft:mossy_cobblestone
execute as @s at @s rotated as @s run setblock ^52 ^1 ^3 minecraft:mossy_cobblestone
execute as @s at @s rotated as @s run setblock ^52 ^1 ^4 minecraft:mossy_cobblestone
execute as @s at @s rotated as @s run setblock ^52 ^1 ^5 minecraft:mossy_cobblestone
execute as @s at @s rotated as @s run setblock ^52 ^1 ^6 minecraft:mossy_cobblestone
execute as @s at @s rotated as @s run setblock ^52 ^1 ^7 minecraft:mossy_cobblestone

# === CENTRAL LAGOON ===
execute as @s at @s rotated as @s run fill ^ ^ ^-31 ^ ^ ^-31 minecraft:water
execute as @s at @s rotated as @s run fill ^-7 ^ ^-30 ^7 ^ ^-30 minecraft:water
execute as @s at @s rotated as @s run fill ^-10 ^ ^-29 ^10 ^ ^-29 minecraft:water
execute as @s at @s rotated as @s run fill ^-13 ^ ^-28 ^13 ^ ^-28 minecraft:water
execute as @s at @s rotated as @s run fill ^-15 ^ ^-27 ^15 ^ ^-27 minecraft:water
execute as @s at @s rotated as @s run fill ^-16 ^ ^-26 ^16 ^ ^-26 minecraft:water
execute as @s at @s rotated as @s run fill ^-18 ^ ^-25 ^18 ^ ^-25 minecraft:water
execute as @s at @s rotated as @s run fill ^-19 ^ ^-24 ^19 ^ ^-24 minecraft:water
execute as @s at @s rotated as @s run fill ^-20 ^ ^-23 ^20 ^ ^-23 minecraft:water
execute as @s at @s rotated as @s run fill ^-21 ^ ^-22 ^21 ^ ^-22 minecraft:water
execute as @s at @s rotated as @s run fill ^-22 ^ ^-21 ^22 ^ ^-21 minecraft:water
execute as @s at @s rotated as @s run fill ^-23 ^ ^-20 ^23 ^ ^-20 minecraft:water
execute as @s at @s rotated as @s run fill ^-24 ^ ^-19 ^24 ^ ^-19 minecraft:water
execute as @s at @s rotated as @s run fill ^-25 ^ ^-18 ^25 ^ ^-18 minecraft:water
execute as @s at @s rotated as @s run fill ^-25 ^ ^-17 ^25 ^ ^-17 minecraft:water
execute as @s at @s rotated as @s run fill ^-26 ^ ^-16 ^26 ^ ^-16 minecraft:water
execute as @s at @s rotated as @s run fill ^-27 ^ ^-15 ^27 ^ ^-15 minecraft:water
execute as @s at @s rotated as @s run fill ^-27 ^ ^-14 ^27 ^ ^-14 minecraft:water
execute as @s at @s rotated as @s run fill ^-28 ^ ^-13 ^28 ^ ^-13 minecraft:water
execute as @s at @s rotated as @s run fill ^-28 ^ ^-12 ^28 ^ ^-12 minecraft:water
execute as @s at @s rotated as @s run fill ^-28 ^ ^-11 ^28 ^ ^-11 minecraft:water
execute as @s at @s rotated as @s run fill ^-29 ^ ^-10 ^29 ^ ^-10 minecraft:water
execute as @s at @s rotated as @s run fill ^-29 ^ ^-9 ^29 ^ ^-9 minecraft:water
execute as @s at @s rotated as @s run fill ^-29 ^ ^-8 ^29 ^ ^-8 minecraft:water
execute as @s at @s rotated as @s run fill ^-30 ^ ^-7 ^30 ^ ^-7 minecraft:water
execute as @s at @s rotated as @s run fill ^-30 ^ ^-6 ^30 ^ ^-6 minecraft:water
execute as @s at @s rotated as @s run fill ^-30 ^ ^-5 ^30 ^ ^-5 minecraft:water
execute as @s at @s rotated as @s run fill ^-30 ^ ^-4 ^30 ^ ^-4 minecraft:water
execute as @s at @s rotated as @s run fill ^-30 ^ ^-3 ^30 ^ ^-3 minecraft:water
execute as @s at @s rotated as @s run fill ^-30 ^ ^-2 ^30 ^ ^-2 minecraft:water
execute as @s at @s rotated as @s run fill ^-30 ^ ^-1 ^30 ^ ^-1 minecraft:water
execute as @s at @s rotated as @s run fill ^-31 ^ ^ ^31 ^ ^ minecraft:water
execute as @s at @s rotated as @s run fill ^-30 ^ ^1 ^30 ^ ^1 minecraft:water
execute as @s at @s rotated as @s run fill ^-30 ^ ^2 ^30 ^ ^2 minecraft:water
execute as @s at @s rotated as @s run fill ^-30 ^ ^3 ^30 ^ ^3 minecraft:water
execute as @s at @s rotated as @s run fill ^-30 ^ ^4 ^30 ^ ^4 minecraft:water
execute as @s at @s rotated as @s run fill ^-30 ^ ^5 ^30 ^ ^5 minecraft:water
execute as @s at @s rotated as @s run fill ^-30 ^ ^6 ^30 ^ ^6 minecraft:water
execute as @s at @s rotated as @s run fill ^-30 ^ ^7 ^30 ^ ^7 minecraft:water
execute as @s at @s rotated as @s run fill ^-29 ^ ^8 ^29 ^ ^8 minecraft:water
execute as @s at @s rotated as @s run fill ^-29 ^ ^9 ^29 ^ ^9 minecraft:water
execute as @s at @s rotated as @s run fill ^-29 ^ ^10 ^29 ^ ^10 minecraft:water
execute as @s at @s rotated as @s run fill ^-28 ^ ^11 ^28 ^ ^11 minecraft:water
execute as @s at @s rotated as @s run fill ^-28 ^ ^12 ^28 ^ ^12 minecraft:water
execute as @s at @s rotated as @s run fill ^-28 ^ ^13 ^28 ^ ^13 minecraft:water
execute as @s at @s rotated as @s run fill ^-27 ^ ^14 ^27 ^ ^14 minecraft:water
execute as @s at @s rotated as @s run fill ^-27 ^ ^15 ^27 ^ ^15 minecraft:water
execute as @s at @s rotated as @s run fill ^-26 ^ ^16 ^26 ^ ^16 minecraft:water
execute as @s at @s rotated as @s run fill ^-25 ^ ^17 ^25 ^ ^17 minecraft:water
execute as @s at @s rotated as @s run fill ^-25 ^ ^18 ^25 ^ ^18 minecraft:water
execute as @s at @s rotated as @s run fill ^-24 ^ ^19 ^24 ^ ^19 minecraft:water
execute as @s at @s rotated as @s run fill ^-23 ^ ^20 ^23 ^ ^20 minecraft:water
execute as @s at @s rotated as @s run fill ^-22 ^ ^21 ^22 ^ ^21 minecraft:water
execute as @s at @s rotated as @s run fill ^-21 ^ ^22 ^21 ^ ^22 minecraft:water
execute as @s at @s rotated as @s run fill ^-20 ^ ^23 ^20 ^ ^23 minecraft:water
execute as @s at @s rotated as @s run fill ^-19 ^ ^24 ^19 ^ ^24 minecraft:water
execute as @s at @s rotated as @s run fill ^-18 ^ ^25 ^18 ^ ^25 minecraft:water
execute as @s at @s rotated as @s run fill ^-16 ^ ^26 ^16 ^ ^26 minecraft:water
execute as @s at @s rotated as @s run fill ^-15 ^ ^27 ^15 ^ ^27 minecraft:water
execute as @s at @s rotated as @s run fill ^-13 ^ ^28 ^13 ^ ^28 minecraft:water
execute as @s at @s rotated as @s run fill ^-10 ^ ^29 ^10 ^ ^29 minecraft:water
execute as @s at @s rotated as @s run fill ^-7 ^ ^30 ^7 ^ ^30 minecraft:water
execute as @s at @s rotated as @s run fill ^ ^ ^31 ^ ^ ^31 minecraft:water
execute as @s at @s rotated as @s run fill ^ ^-1 ^-31 ^ ^-1 ^-31 minecraft:prismarine
execute as @s at @s rotated as @s run fill ^-7 ^-1 ^-30 ^7 ^-1 ^-30 minecraft:prismarine
execute as @s at @s rotated as @s run fill ^-10 ^-1 ^-29 ^10 ^-1 ^-29 minecraft:prismarine
execute as @s at @s rotated as @s run fill ^-13 ^-1 ^-28 ^13 ^-1 ^-28 minecraft:prismarine
execute as @s at @s rotated as @s run fill ^-15 ^-1 ^-27 ^15 ^-1 ^-27 minecraft:prismarine
execute as @s at @s rotated as @s run fill ^-16 ^-1 ^-26 ^16 ^-1 ^-26 minecraft:prismarine
execute as @s at @s rotated as @s run fill ^-18 ^-1 ^-25 ^18 ^-1 ^-25 minecraft:prismarine
execute as @s at @s rotated as @s run fill ^-19 ^-1 ^-24 ^19 ^-1 ^-24 minecraft:prismarine
execute as @s at @s rotated as @s run fill ^-20 ^-1 ^-23 ^20 ^-1 ^-23 minecraft:prismarine
execute as @s at @s rotated as @s run fill ^-21 ^-1 ^-22 ^21 ^-1 ^-22 minecraft:prismarine
execute as @s at @s rotated as @s run fill ^-22 ^-1 ^-21 ^22 ^-1 ^-21 minecraft:prismarine
execute as @s at @s rotated as @s run fill ^-23 ^-1 ^-20 ^23 ^-1 ^-20 minecraft:prismarine
execute as @s at @s rotated as @s run fill ^-24 ^-1 ^-19 ^24 ^-1 ^-19 minecraft:prismarine
execute as @s at @s rotated as @s run fill ^-25 ^-1 ^-18 ^25 ^-1 ^-18 minecraft:prismarine
execute as @s at @s rotated as @s run fill ^-25 ^-1 ^-17 ^25 ^-1 ^-17 minecraft:prismarine
execute as @s at @s rotated as @s run fill ^-26 ^-1 ^-16 ^26 ^-1 ^-16 minecraft:prismarine
execute as @s at @s rotated as @s run fill ^-27 ^-1 ^-15 ^27 ^-1 ^-15 minecraft:prismarine
execute as @s at @s rotated as @s run fill ^-27 ^-1 ^-14 ^27 ^-1 ^-14 minecraft:prismarine
execute as @s at @s rotated as @s run fill ^-28 ^-1 ^-13 ^28 ^-1 ^-13 minecraft:prismarine
execute as @s at @s rotated as @s run fill ^-28 ^-1 ^-12 ^28 ^-1 ^-12 minecraft:prismarine
execute as @s at @s rotated as @s run fill ^-28 ^-1 ^-11 ^28 ^-1 ^-11 minecraft:prismarine
execute as @s at @s rotated as @s run fill ^-29 ^-1 ^-10 ^29 ^-1 ^-10 minecraft:prismarine
execute as @s at @s rotated as @s run fill ^-29 ^-1 ^-9 ^29 ^-1 ^-9 minecraft:prismarine
execute as @s at @s rotated as @s run fill ^-29 ^-1 ^-8 ^29 ^-1 ^-8 minecraft:prismarine
execute as @s at @s rotated as @s run fill ^-30 ^-1 ^-7 ^30 ^-1 ^-7 minecraft:prismarine
execute as @s at @s rotated as @s run fill ^-30 ^-1 ^-6 ^30 ^-1 ^-6 minecraft:prismarine
execute as @s at @s rotated as @s run fill ^-30 ^-1 ^-5 ^30 ^-1 ^-5 minecraft:prismarine
execute as @s at @s rotated as @s run fill ^-30 ^-1 ^-4 ^30 ^-1 ^-4 minecraft:prismarine
execute as @s at @s rotated as @s run fill ^-30 ^-1 ^-3 ^30 ^-1 ^-3 minecraft:prismarine
execute as @s at @s rotated as @s run fill ^-30 ^-1 ^-2 ^30 ^-1 ^-2 minecraft:prismarine
execute as @s at @s rotated as @s run fill ^-30 ^-1 ^-1 ^30 ^-1 ^-1 minecraft:prismarine
execute as @s at @s rotated as @s run fill ^-31 ^-1 ^ ^31 ^-1 ^ minecraft:prismarine
execute as @s at @s rotated as @s run fill ^-30 ^-1 ^1 ^30 ^-1 ^1 minecraft:prismarine
execute as @s at @s rotated as @s run fill ^-30 ^-1 ^2 ^30 ^-1 ^2 minecraft:prismarine
execute as @s at @s rotated as @s run fill ^-30 ^-1 ^3 ^30 ^-1 ^3 minecraft:prismarine
execute as @s at @s rotated as @s run fill ^-30 ^-1 ^4 ^30 ^-1 ^4 minecraft:prismarine
execute as @s at @s rotated as @s run fill ^-30 ^-1 ^5 ^30 ^-1 ^5 minecraft:prismarine
execute as @s at @s rotated as @s run fill ^-30 ^-1 ^6 ^30 ^-1 ^6 minecraft:prismarine
execute as @s at @s rotated as @s run fill ^-30 ^-1 ^7 ^30 ^-1 ^7 minecraft:prismarine
execute as @s at @s rotated as @s run fill ^-29 ^-1 ^8 ^29 ^-1 ^8 minecraft:prismarine
execute as @s at @s rotated as @s run fill ^-29 ^-1 ^9 ^29 ^-1 ^9 minecraft:prismarine
execute as @s at @s rotated as @s run fill ^-29 ^-1 ^10 ^29 ^-1 ^10 minecraft:prismarine
execute as @s at @s rotated as @s run fill ^-28 ^-1 ^11 ^28 ^-1 ^11 minecraft:prismarine
execute as @s at @s rotated as @s run fill ^-28 ^-1 ^12 ^28 ^-1 ^12 minecraft:prismarine
execute as @s at @s rotated as @s run fill ^-28 ^-1 ^13 ^28 ^-1 ^13 minecraft:prismarine
execute as @s at @s rotated as @s run fill ^-27 ^-1 ^14 ^27 ^-1 ^14 minecraft:prismarine
execute as @s at @s rotated as @s run fill ^-27 ^-1 ^15 ^27 ^-1 ^15 minecraft:prismarine
execute as @s at @s rotated as @s run fill ^-26 ^-1 ^16 ^26 ^-1 ^16 minecraft:prismarine
execute as @s at @s rotated as @s run fill ^-25 ^-1 ^17 ^25 ^-1 ^17 minecraft:prismarine
execute as @s at @s rotated as @s run fill ^-25 ^-1 ^18 ^25 ^-1 ^18 minecraft:prismarine
execute as @s at @s rotated as @s run fill ^-24 ^-1 ^19 ^24 ^-1 ^19 minecraft:prismarine
execute as @s at @s rotated as @s run fill ^-23 ^-1 ^20 ^23 ^-1 ^20 minecraft:prismarine
execute as @s at @s rotated as @s run fill ^-22 ^-1 ^21 ^22 ^-1 ^21 minecraft:prismarine
execute as @s at @s rotated as @s run fill ^-21 ^-1 ^22 ^21 ^-1 ^22 minecraft:prismarine
execute as @s at @s rotated as @s run fill ^-20 ^-1 ^23 ^20 ^-1 ^23 minecraft:prismarine
execute as @s at @s rotated as @s run fill ^-19 ^-1 ^24 ^19 ^-1 ^24 minecraft:prismarine
execute as @s at @s rotated as @s run fill ^-18 ^-1 ^25 ^18 ^-1 ^25 minecraft:prismarine
execute as @s at @s rotated as @s run fill ^-16 ^-1 ^26 ^16 ^-1 ^26 minecraft:prismarine
execute as @s at @s rotated as @s run fill ^-15 ^-1 ^27 ^15 ^-1 ^27 minecraft:prismarine
execute as @s at @s rotated as @s run fill ^-13 ^-1 ^28 ^13 ^-1 ^28 minecraft:prismarine
execute as @s at @s rotated as @s run fill ^-10 ^-1 ^29 ^10 ^-1 ^29 minecraft:prismarine
execute as @s at @s rotated as @s run fill ^-7 ^-1 ^30 ^7 ^-1 ^30 minecraft:prismarine
execute as @s at @s rotated as @s run fill ^ ^-1 ^31 ^ ^-1 ^31 minecraft:prismarine
execute as @s at @s rotated as @s run fill ^ ^-2 ^-27 ^ ^-2 ^-27 minecraft:dark_prismarine
execute as @s at @s rotated as @s run fill ^-7 ^-2 ^-26 ^7 ^-2 ^-26 minecraft:dark_prismarine
execute as @s at @s rotated as @s run fill ^-10 ^-2 ^-25 ^10 ^-2 ^-25 minecraft:dark_prismarine
execute as @s at @s rotated as @s run fill ^-12 ^-2 ^-24 ^12 ^-2 ^-24 minecraft:dark_prismarine
execute as @s at @s rotated as @s run fill ^-14 ^-2 ^-23 ^14 ^-2 ^-23 minecraft:dark_prismarine
execute as @s at @s rotated as @s run fill ^-15 ^-2 ^-22 ^15 ^-2 ^-22 minecraft:dark_prismarine
execute as @s at @s rotated as @s run fill ^-16 ^-2 ^-21 ^16 ^-2 ^-21 minecraft:dark_prismarine
execute as @s at @s rotated as @s run fill ^-18 ^-2 ^-20 ^18 ^-2 ^-20 minecraft:dark_prismarine
execute as @s at @s rotated as @s run fill ^-19 ^-2 ^-19 ^19 ^-2 ^-19 minecraft:dark_prismarine
execute as @s at @s rotated as @s run fill ^-20 ^-2 ^-18 ^20 ^-2 ^-18 minecraft:dark_prismarine
execute as @s at @s rotated as @s run fill ^-20 ^-2 ^-17 ^20 ^-2 ^-17 minecraft:dark_prismarine
execute as @s at @s rotated as @s run fill ^-21 ^-2 ^-16 ^21 ^-2 ^-16 minecraft:dark_prismarine
execute as @s at @s rotated as @s run fill ^-22 ^-2 ^-15 ^22 ^-2 ^-15 minecraft:dark_prismarine
execute as @s at @s rotated as @s run fill ^-23 ^-2 ^-14 ^23 ^-2 ^-14 minecraft:dark_prismarine
execute as @s at @s rotated as @s run fill ^-23 ^-2 ^-13 ^23 ^-2 ^-13 minecraft:dark_prismarine
execute as @s at @s rotated as @s run fill ^-24 ^-2 ^-12 ^24 ^-2 ^-12 minecraft:dark_prismarine
execute as @s at @s rotated as @s run fill ^-24 ^-2 ^-11 ^24 ^-2 ^-11 minecraft:dark_prismarine
execute as @s at @s rotated as @s run fill ^-25 ^-2 ^-10 ^25 ^-2 ^-10 minecraft:dark_prismarine
execute as @s at @s rotated as @s run fill ^-25 ^-2 ^-9 ^25 ^-2 ^-9 minecraft:dark_prismarine
execute as @s at @s rotated as @s run fill ^-25 ^-2 ^-8 ^25 ^-2 ^-8 minecraft:dark_prismarine
execute as @s at @s rotated as @s run fill ^-26 ^-2 ^-7 ^26 ^-2 ^-7 minecraft:dark_prismarine
execute as @s at @s rotated as @s run fill ^-26 ^-2 ^-6 ^26 ^-2 ^-6 minecraft:dark_prismarine
execute as @s at @s rotated as @s run fill ^-26 ^-2 ^-5 ^26 ^-2 ^-5 minecraft:dark_prismarine
execute as @s at @s rotated as @s run fill ^-26 ^-2 ^-4 ^26 ^-2 ^-4 minecraft:dark_prismarine
execute as @s at @s rotated as @s run fill ^-26 ^-2 ^-3 ^26 ^-2 ^-3 minecraft:dark_prismarine
execute as @s at @s rotated as @s run fill ^-26 ^-2 ^-2 ^26 ^-2 ^-2 minecraft:dark_prismarine
execute as @s at @s rotated as @s run fill ^-26 ^-2 ^-1 ^26 ^-2 ^-1 minecraft:dark_prismarine
execute as @s at @s rotated as @s run fill ^-27 ^-2 ^ ^27 ^-2 ^ minecraft:dark_prismarine
execute as @s at @s rotated as @s run fill ^-26 ^-2 ^1 ^26 ^-2 ^1 minecraft:dark_prismarine
execute as @s at @s rotated as @s run fill ^-26 ^-2 ^2 ^26 ^-2 ^2 minecraft:dark_prismarine
execute as @s at @s rotated as @s run fill ^-26 ^-2 ^3 ^26 ^-2 ^3 minecraft:dark_prismarine
execute as @s at @s rotated as @s run fill ^-26 ^-2 ^4 ^26 ^-2 ^4 minecraft:dark_prismarine
execute as @s at @s rotated as @s run fill ^-26 ^-2 ^5 ^26 ^-2 ^5 minecraft:dark_prismarine
execute as @s at @s rotated as @s run fill ^-26 ^-2 ^6 ^26 ^-2 ^6 minecraft:dark_prismarine
execute as @s at @s rotated as @s run fill ^-26 ^-2 ^7 ^26 ^-2 ^7 minecraft:dark_prismarine
execute as @s at @s rotated as @s run fill ^-25 ^-2 ^8 ^25 ^-2 ^8 minecraft:dark_prismarine
execute as @s at @s rotated as @s run fill ^-25 ^-2 ^9 ^25 ^-2 ^9 minecraft:dark_prismarine
execute as @s at @s rotated as @s run fill ^-25 ^-2 ^10 ^25 ^-2 ^10 minecraft:dark_prismarine
execute as @s at @s rotated as @s run fill ^-24 ^-2 ^11 ^24 ^-2 ^11 minecraft:dark_prismarine
execute as @s at @s rotated as @s run fill ^-24 ^-2 ^12 ^24 ^-2 ^12 minecraft:dark_prismarine
execute as @s at @s rotated as @s run fill ^-23 ^-2 ^13 ^23 ^-2 ^13 minecraft:dark_prismarine
execute as @s at @s rotated as @s run fill ^-23 ^-2 ^14 ^23 ^-2 ^14 minecraft:dark_prismarine
execute as @s at @s rotated as @s run fill ^-22 ^-2 ^15 ^22 ^-2 ^15 minecraft:dark_prismarine
execute as @s at @s rotated as @s run fill ^-21 ^-2 ^16 ^21 ^-2 ^16 minecraft:dark_prismarine
execute as @s at @s rotated as @s run fill ^-20 ^-2 ^17 ^20 ^-2 ^17 minecraft:dark_prismarine
execute as @s at @s rotated as @s run fill ^-20 ^-2 ^18 ^20 ^-2 ^18 minecraft:dark_prismarine
execute as @s at @s rotated as @s run fill ^-19 ^-2 ^19 ^19 ^-2 ^19 minecraft:dark_prismarine
execute as @s at @s rotated as @s run fill ^-18 ^-2 ^20 ^18 ^-2 ^20 minecraft:dark_prismarine
execute as @s at @s rotated as @s run fill ^-16 ^-2 ^21 ^16 ^-2 ^21 minecraft:dark_prismarine
execute as @s at @s rotated as @s run fill ^-15 ^-2 ^22 ^15 ^-2 ^22 minecraft:dark_prismarine
execute as @s at @s rotated as @s run fill ^-14 ^-2 ^23 ^14 ^-2 ^23 minecraft:dark_prismarine
execute as @s at @s rotated as @s run fill ^-12 ^-2 ^24 ^12 ^-2 ^24 minecraft:dark_prismarine
execute as @s at @s rotated as @s run fill ^-10 ^-2 ^25 ^10 ^-2 ^25 minecraft:dark_prismarine
execute as @s at @s rotated as @s run fill ^-7 ^-2 ^26 ^7 ^-2 ^26 minecraft:dark_prismarine
execute as @s at @s rotated as @s run fill ^ ^-2 ^27 ^ ^-2 ^27 minecraft:dark_prismarine
execute as @s at @s rotated as @s run setblock ^-33 ^ ^-5 minecraft:sand
execute as @s at @s rotated as @s run setblock ^-33 ^ ^-4 minecraft:sand
execute as @s at @s rotated as @s run setblock ^-33 ^ ^-3 minecraft:sand
execute as @s at @s rotated as @s run setblock ^-33 ^ ^-2 minecraft:sand
execute as @s at @s rotated as @s run setblock ^-33 ^ ^-1 minecraft:sand
execute as @s at @s rotated as @s run setblock ^-33 ^ ^ minecraft:sand
execute as @s at @s rotated as @s run setblock ^-33 ^ ^1 minecraft:sand
execute as @s at @s rotated as @s run setblock ^-33 ^ ^2 minecraft:sand
execute as @s at @s rotated as @s run setblock ^-33 ^ ^3 minecraft:sand
execute as @s at @s rotated as @s run setblock ^-33 ^ ^4 minecraft:sand
execute as @s at @s rotated as @s run setblock ^-33 ^ ^5 minecraft:sand
execute as @s at @s rotated as @s run setblock ^-32 ^ ^-9 minecraft:sand
execute as @s at @s rotated as @s run setblock ^-32 ^ ^-8 minecraft:sand
execute as @s at @s rotated as @s run setblock ^-32 ^ ^-7 minecraft:sand
execute as @s at @s rotated as @s run setblock ^-32 ^ ^-6 minecraft:sand
execute as @s at @s rotated as @s run setblock ^-32 ^ ^6 minecraft:sand
execute as @s at @s rotated as @s run setblock ^-32 ^ ^7 minecraft:sand
execute as @s at @s rotated as @s run setblock ^-32 ^ ^8 minecraft:sand
execute as @s at @s rotated as @s run setblock ^-32 ^ ^9 minecraft:sand
execute as @s at @s rotated as @s run setblock ^-31 ^ ^-12 minecraft:sand
execute as @s at @s rotated as @s run setblock ^-31 ^ ^-11 minecraft:sand
execute as @s at @s rotated as @s run setblock ^-31 ^ ^-10 minecraft:sand
execute as @s at @s rotated as @s run setblock ^-31 ^ ^10 minecraft:sand
execute as @s at @s rotated as @s run setblock ^-31 ^ ^11 minecraft:sand
execute as @s at @s rotated as @s run setblock ^-31 ^ ^12 minecraft:sand
execute as @s at @s rotated as @s run setblock ^-30 ^ ^-15 minecraft:sand
execute as @s at @s rotated as @s run setblock ^-30 ^ ^-14 minecraft:sand
execute as @s at @s rotated as @s run setblock ^-30 ^ ^-13 minecraft:sand
execute as @s at @s rotated as @s run setblock ^-30 ^ ^13 minecraft:sand
execute as @s at @s rotated as @s run setblock ^-30 ^ ^14 minecraft:sand
execute as @s at @s rotated as @s run setblock ^-30 ^ ^15 minecraft:sand
execute as @s at @s rotated as @s run setblock ^-29 ^ ^-16 minecraft:sand
execute as @s at @s rotated as @s run setblock ^-29 ^ ^-15 minecraft:sand
execute as @s at @s rotated as @s run setblock ^-29 ^ ^15 minecraft:sand
execute as @s at @s rotated as @s run setblock ^-29 ^ ^16 minecraft:sand
execute as @s at @s rotated as @s run setblock ^-28 ^ ^-18 minecraft:sand
execute as @s at @s rotated as @s run setblock ^-28 ^ ^-17 minecraft:sand
execute as @s at @s rotated as @s run setblock ^-28 ^ ^17 minecraft:sand
execute as @s at @s rotated as @s run setblock ^-28 ^ ^18 minecraft:sand
execute as @s at @s rotated as @s run setblock ^-27 ^ ^-20 minecraft:sand
execute as @s at @s rotated as @s run setblock ^-27 ^ ^-19 minecraft:sand
execute as @s at @s rotated as @s run setblock ^-27 ^ ^-18 minecraft:sand
execute as @s at @s rotated as @s run setblock ^-27 ^ ^18 minecraft:sand
execute as @s at @s rotated as @s run setblock ^-27 ^ ^19 minecraft:sand
execute as @s at @s rotated as @s run setblock ^-27 ^ ^20 minecraft:sand
execute as @s at @s rotated as @s run setblock ^-26 ^ ^-21 minecraft:sand
execute as @s at @s rotated as @s run setblock ^-26 ^ ^-20 minecraft:sand
execute as @s at @s rotated as @s run setblock ^-26 ^ ^20 minecraft:sand
execute as @s at @s rotated as @s run setblock ^-26 ^ ^21 minecraft:sand
execute as @s at @s rotated as @s run setblock ^-25 ^ ^-22 minecraft:sand
execute as @s at @s rotated as @s run setblock ^-25 ^ ^-21 minecraft:sand
execute as @s at @s rotated as @s run setblock ^-25 ^ ^21 minecraft:sand
