# GRAND FERRIS WHEEL - Minecraft Bedrock Edition
# Run at ground level from the CENTER while facing a cardinal direction and looking horizontally.
# Coordinates use your view: ^left, ^up, ^forward. The entrance is behind you; the wheel lies in the left/up plane.
# Approximate footprint: 89 x 57 blocks. Approximate top height: 69 blocks.

# === SNAP PLAYER TO BLOCK CENTER AND NEAREST CARDINAL ===
execute if entity @s[rym=-45,ry=45] as @s at @s align xz run tp @s ~0.5 ~ ~0.5 0 0
execute if entity @s[rym=45,ry=135] as @s at @s align xz run tp @s ~0.5 ~ ~0.5 90 0
execute if entity @s[rym=135,ry=180] as @s at @s align xz run tp @s ~0.5 ~ ~0.5 180 0
execute if entity @s[rym=-180,ry=-135] as @s at @s align xz run tp @s ~0.5 ~ ~0.5 180 0
execute if entity @s[rym=-135,ry=-45] as @s at @s align xz run tp @s ~0.5 ~ ~0.5 -90 0

# === PLAZA & FOUNDATION ===
execute as @s at @s rotated as @s run fill ^-44 ^-2 ^-28 ^44 ^-2 ^28 minecraft:stone_bricks
execute as @s at @s rotated as @s run fill ^-42 ^-1 ^-26 ^42 ^-1 ^26 minecraft:smooth_stone
execute as @s at @s rotated as @s run fill ^-34 ^-1 ^-18 ^34 ^-1 ^18 minecraft:polished_andesite
execute as @s at @s rotated as @s run fill ^-10 ^-1 ^-26 ^10 ^-1 ^26 minecraft:stone_bricks
execute as @s at @s rotated as @s run fill ^-3 ^-1 ^-26 ^3 ^-1 ^26 minecraft:gold_block

# === PERIMETER FENCE & MAIN ENTRY ===
execute as @s at @s rotated as @s run fill ^-44 ^ ^-28 ^-8 ^ ^-28 minecraft:spruce_fence
execute as @s at @s rotated as @s run fill ^8 ^ ^-28 ^44 ^ ^-28 minecraft:spruce_fence
execute as @s at @s rotated as @s run fill ^-44 ^ ^28 ^44 ^ ^28 minecraft:spruce_fence
execute as @s at @s rotated as @s run fill ^-44 ^ ^-28 ^-44 ^ ^28 minecraft:spruce_fence
execute as @s at @s rotated as @s run fill ^44 ^ ^-28 ^44 ^ ^28 minecraft:spruce_fence
execute as @s at @s rotated as @s run fill ^-8 ^ ^-28 ^-6 ^8 ^-28 minecraft:dark_oak_log
execute as @s at @s rotated as @s run fill ^6 ^ ^-28 ^8 ^8 ^-28 minecraft:dark_oak_log
execute as @s at @s rotated as @s run fill ^-8 ^8 ^-28 ^8 ^10 ^-28 minecraft:dark_oak_planks
execute as @s at @s rotated as @s run fill ^-6 ^10 ^-28 ^6 ^11 ^-28 minecraft:red_wool
execute as @s at @s rotated as @s run fill ^-2 ^11 ^-28 ^2 ^12 ^-28 minecraft:gold_block
execute as @s at @s rotated as @s run setblock ^-5 ^9 ^-29 minecraft:lantern
execute as @s at @s rotated as @s run setblock ^5 ^9 ^-29 minecraft:lantern
execute as @s at @s rotated as @s run setblock ^-5 ^10 ^-29 minecraft:sea_lantern
execute as @s at @s rotated as @s run setblock ^-3 ^10 ^-29 minecraft:sea_lantern
execute as @s at @s rotated as @s run setblock ^-1 ^10 ^-29 minecraft:sea_lantern
execute as @s at @s rotated as @s run setblock ^1 ^10 ^-29 minecraft:sea_lantern
execute as @s at @s rotated as @s run setblock ^3 ^10 ^-29 minecraft:sea_lantern
execute as @s at @s rotated as @s run setblock ^5 ^10 ^-29 minecraft:sea_lantern

# === QUEUE AREA ===
execute as @s at @s rotated as @s run fill ^-40 ^-1 ^-24 ^-14 ^-1 ^-8 minecraft:smooth_stone
execute as @s at @s rotated as @s run fill ^-39 ^ ^-23 ^-16 ^ ^-23 minecraft:spruce_fence
execute as @s at @s rotated as @s run fill ^-39 ^ ^-19 ^-16 ^ ^-19 minecraft:spruce_fence
execute as @s at @s rotated as @s run fill ^-39 ^ ^-15 ^-16 ^ ^-15 minecraft:spruce_fence
execute as @s at @s rotated as @s run fill ^-39 ^ ^-11 ^-16 ^ ^-11 minecraft:spruce_fence
execute as @s at @s rotated as @s run fill ^-39 ^ ^-23 ^-39 ^ ^-11 minecraft:spruce_fence
execute as @s at @s rotated as @s run fill ^-16 ^ ^-19 ^-16 ^ ^-15 minecraft:spruce_fence
execute as @s at @s rotated as @s run fill ^-16 ^ ^-11 ^-16 ^ ^-8 minecraft:spruce_fence
execute as @s at @s rotated as @s run fill ^-37 ^ ^-22 ^-37 ^3 ^-22 minecraft:dark_oak_fence
execute as @s at @s rotated as @s run setblock ^-37 ^4 ^-22 minecraft:lantern
execute as @s at @s rotated as @s run fill ^-29 ^ ^-18 ^-29 ^3 ^-18 minecraft:dark_oak_fence
execute as @s at @s rotated as @s run setblock ^-29 ^4 ^-18 minecraft:lantern
execute as @s at @s rotated as @s run fill ^-21 ^ ^-14 ^-21 ^3 ^-14 minecraft:dark_oak_fence
execute as @s at @s rotated as @s run setblock ^-21 ^4 ^-14 minecraft:lantern
execute as @s at @s rotated as @s run fill ^-36 ^ ^-10 ^-36 ^3 ^-10 minecraft:dark_oak_fence
execute as @s at @s rotated as @s run setblock ^-36 ^4 ^-10 minecraft:lantern

# === TICKET BOOTH ===
execute as @s at @s rotated as @s run fill ^16 ^ ^-24 ^28 ^ ^-15 minecraft:stone_bricks
execute as @s at @s rotated as @s run fill ^17 ^1 ^-23 ^27 ^5 ^-16 minecraft:dark_oak_planks
execute as @s at @s rotated as @s run fill ^18 ^2 ^-24 ^26 ^4 ^-24 minecraft:glass
execute as @s at @s rotated as @s run fill ^16 ^6 ^-24 ^28 ^7 ^-15 minecraft:red_wool
execute as @s at @s rotated as @s run fill ^18 ^7 ^-25 ^26 ^8 ^-25 minecraft:gold_block
execute as @s at @s rotated as @s run fill ^18 ^1 ^-25 ^26 ^2 ^-24 minecraft:oak_planks
execute as @s at @s rotated as @s run setblock ^16 ^8 ^-20 minecraft:lantern
execute as @s at @s rotated as @s run setblock ^28 ^8 ^-20 minecraft:lantern

# === LOADING PLATFORM ===
execute as @s at @s rotated as @s run fill ^-15 ^ ^-8 ^15 ^ ^8 minecraft:stone_bricks
execute as @s at @s rotated as @s run fill ^-13 ^1 ^-6 ^13 ^1 ^6 minecraft:oak_planks
execute as @s at @s rotated as @s run fill ^-13 ^2 ^-6 ^-4 ^2 ^-6 minecraft:iron_bars
execute as @s at @s rotated as @s run fill ^4 ^2 ^-6 ^13 ^2 ^-6 minecraft:iron_bars
execute as @s at @s rotated as @s run fill ^-13 ^2 ^6 ^13 ^2 ^6 minecraft:iron_bars
execute as @s at @s rotated as @s run fill ^-13 ^2 ^-6 ^-13 ^2 ^6 minecraft:iron_bars
execute as @s at @s rotated as @s run fill ^13 ^2 ^-6 ^13 ^2 ^6 minecraft:iron_bars
execute as @s at @s rotated as @s run fill ^-3 ^-1 ^-12 ^3 ^-1 ^-12 minecraft:stone_bricks
execute as @s at @s rotated as @s run fill ^-3 ^ ^-11 ^3 ^ ^-11 minecraft:stone_bricks
execute as @s at @s rotated as @s run fill ^-3 ^1 ^-10 ^3 ^1 ^-10 minecraft:stone_bricks
execute as @s at @s rotated as @s run fill ^-3 ^2 ^-9 ^3 ^2 ^-9 minecraft:stone_bricks

# === SUPPORT FOOTINGS ===
execute as @s at @s rotated as @s run fill ^-25 ^-1 ^-13 ^-19 ^1 ^-7 minecraft:stone_bricks
execute as @s at @s rotated as @s run fill ^-25 ^-1 ^7 ^-19 ^1 ^13 minecraft:stone_bricks
execute as @s at @s rotated as @s run fill ^19 ^-1 ^-13 ^25 ^1 ^-7 minecraft:stone_bricks
execute as @s at @s rotated as @s run fill ^19 ^-1 ^7 ^25 ^1 ^13 minecraft:stone_bricks

# === GIANT A-FRAME SUPPORTS ===
execute as @s at @s rotated as @s run fill ^-23 ^2 ^-9 ^-21 ^2 ^-7 minecraft:dark_oak_log
execute as @s at @s rotated as @s run fill ^-22 ^3 ^-9 ^-20 ^3 ^-7 minecraft:dark_oak_log
execute as @s at @s rotated as @s run fill ^-22 ^4 ^-9 ^-20 ^4 ^-7 minecraft:dark_oak_log
execute as @s at @s rotated as @s run fill ^-21 ^5 ^-9 ^-19 ^5 ^-7 minecraft:dark_oak_log
execute as @s at @s rotated as @s run fill ^-21 ^6 ^-9 ^-19 ^6 ^-7 minecraft:dark_oak_log
execute as @s at @s rotated as @s run fill ^-20 ^7 ^-9 ^-18 ^7 ^-7 minecraft:dark_oak_log
execute as @s at @s rotated as @s run fill ^-19 ^8 ^-9 ^-17 ^8 ^-7 minecraft:dark_oak_log
execute as @s at @s rotated as @s run fill ^-19 ^9 ^-9 ^-17 ^9 ^-7 minecraft:dark_oak_log
execute as @s at @s rotated as @s run fill ^-18 ^10 ^-9 ^-16 ^10 ^-7 minecraft:dark_oak_log
execute as @s at @s rotated as @s run fill ^-18 ^11 ^-9 ^-16 ^11 ^-7 minecraft:dark_oak_log
execute as @s at @s rotated as @s run fill ^-17 ^12 ^-9 ^-15 ^12 ^-7 minecraft:dark_oak_log
execute as @s at @s rotated as @s run fill ^-16 ^13 ^-9 ^-14 ^13 ^-7 minecraft:dark_oak_log
execute as @s at @s rotated as @s run fill ^-16 ^14 ^-9 ^-14 ^14 ^-7 minecraft:dark_oak_log
execute as @s at @s rotated as @s run fill ^-15 ^15 ^-9 ^-13 ^15 ^-7 minecraft:dark_oak_log
execute as @s at @s rotated as @s run fill ^-15 ^16 ^-9 ^-13 ^16 ^-7 minecraft:dark_oak_log
execute as @s at @s rotated as @s run fill ^-14 ^17 ^-9 ^-12 ^17 ^-7 minecraft:dark_oak_log
execute as @s at @s rotated as @s run fill ^-13 ^18 ^-9 ^-11 ^18 ^-7 minecraft:dark_oak_log
execute as @s at @s rotated as @s run fill ^-13 ^19 ^-9 ^-11 ^19 ^-7 minecraft:dark_oak_log
execute as @s at @s rotated as @s run fill ^-12 ^20 ^-9 ^-10 ^20 ^-7 minecraft:dark_oak_log
execute as @s at @s rotated as @s run fill ^-12 ^21 ^-9 ^-10 ^21 ^-7 minecraft:dark_oak_log
execute as @s at @s rotated as @s run fill ^-11 ^22 ^-9 ^-9 ^22 ^-7 minecraft:dark_oak_log
execute as @s at @s rotated as @s run fill ^-11 ^23 ^-9 ^-9 ^23 ^-7 minecraft:dark_oak_log
execute as @s at @s rotated as @s run fill ^-10 ^24 ^-9 ^-8 ^24 ^-7 minecraft:dark_oak_log
execute as @s at @s rotated as @s run fill ^-9 ^25 ^-9 ^-7 ^25 ^-7 minecraft:dark_oak_log
execute as @s at @s rotated as @s run fill ^-9 ^26 ^-9 ^-7 ^26 ^-7 minecraft:dark_oak_log
execute as @s at @s rotated as @s run fill ^-8 ^27 ^-9 ^-6 ^27 ^-7 minecraft:dark_oak_log
execute as @s at @s rotated as @s run fill ^-8 ^28 ^-9 ^-6 ^28 ^-7 minecraft:dark_oak_log
execute as @s at @s rotated as @s run fill ^-7 ^29 ^-9 ^-5 ^29 ^-7 minecraft:dark_oak_log
execute as @s at @s rotated as @s run fill ^-6 ^30 ^-9 ^-4 ^30 ^-7 minecraft:dark_oak_log
execute as @s at @s rotated as @s run fill ^-6 ^31 ^-9 ^-4 ^31 ^-7 minecraft:dark_oak_log
execute as @s at @s rotated as @s run fill ^-5 ^32 ^-9 ^-3 ^32 ^-7 minecraft:dark_oak_log
execute as @s at @s rotated as @s run fill ^-5 ^33 ^-9 ^-3 ^33 ^-7 minecraft:dark_oak_log
execute as @s at @s rotated as @s run fill ^-4 ^34 ^-9 ^-2 ^34 ^-7 minecraft:dark_oak_log
execute as @s at @s rotated as @s run fill ^21 ^2 ^-9 ^23 ^2 ^-7 minecraft:dark_oak_log
execute as @s at @s rotated as @s run fill ^20 ^3 ^-9 ^22 ^3 ^-7 minecraft:dark_oak_log
execute as @s at @s rotated as @s run fill ^20 ^4 ^-9 ^22 ^4 ^-7 minecraft:dark_oak_log
execute as @s at @s rotated as @s run fill ^19 ^5 ^-9 ^21 ^5 ^-7 minecraft:dark_oak_log
execute as @s at @s rotated as @s run fill ^19 ^6 ^-9 ^21 ^6 ^-7 minecraft:dark_oak_log
execute as @s at @s rotated as @s run fill ^18 ^7 ^-9 ^20 ^7 ^-7 minecraft:dark_oak_log
execute as @s at @s rotated as @s run fill ^17 ^8 ^-9 ^19 ^8 ^-7 minecraft:dark_oak_log
execute as @s at @s rotated as @s run fill ^17 ^9 ^-9 ^19 ^9 ^-7 minecraft:dark_oak_log
execute as @s at @s rotated as @s run fill ^16 ^10 ^-9 ^18 ^10 ^-7 minecraft:dark_oak_log
execute as @s at @s rotated as @s run fill ^16 ^11 ^-9 ^18 ^11 ^-7 minecraft:dark_oak_log
execute as @s at @s rotated as @s run fill ^15 ^12 ^-9 ^17 ^12 ^-7 minecraft:dark_oak_log
execute as @s at @s rotated as @s run fill ^14 ^13 ^-9 ^16 ^13 ^-7 minecraft:dark_oak_log
execute as @s at @s rotated as @s run fill ^14 ^14 ^-9 ^16 ^14 ^-7 minecraft:dark_oak_log
execute as @s at @s rotated as @s run fill ^13 ^15 ^-9 ^15 ^15 ^-7 minecraft:dark_oak_log
execute as @s at @s rotated as @s run fill ^13 ^16 ^-9 ^15 ^16 ^-7 minecraft:dark_oak_log
execute as @s at @s rotated as @s run fill ^12 ^17 ^-9 ^14 ^17 ^-7 minecraft:dark_oak_log
execute as @s at @s rotated as @s run fill ^11 ^18 ^-9 ^13 ^18 ^-7 minecraft:dark_oak_log
execute as @s at @s rotated as @s run fill ^11 ^19 ^-9 ^13 ^19 ^-7 minecraft:dark_oak_log
execute as @s at @s rotated as @s run fill ^10 ^20 ^-9 ^12 ^20 ^-7 minecraft:dark_oak_log
execute as @s at @s rotated as @s run fill ^10 ^21 ^-9 ^12 ^21 ^-7 minecraft:dark_oak_log
execute as @s at @s rotated as @s run fill ^9 ^22 ^-9 ^11 ^22 ^-7 minecraft:dark_oak_log
execute as @s at @s rotated as @s run fill ^9 ^23 ^-9 ^11 ^23 ^-7 minecraft:dark_oak_log
execute as @s at @s rotated as @s run fill ^8 ^24 ^-9 ^10 ^24 ^-7 minecraft:dark_oak_log
execute as @s at @s rotated as @s run fill ^7 ^25 ^-9 ^9 ^25 ^-7 minecraft:dark_oak_log
execute as @s at @s rotated as @s run fill ^7 ^26 ^-9 ^9 ^26 ^-7 minecraft:dark_oak_log
execute as @s at @s rotated as @s run fill ^6 ^27 ^-9 ^8 ^27 ^-7 minecraft:dark_oak_log
execute as @s at @s rotated as @s run fill ^6 ^28 ^-9 ^8 ^28 ^-7 minecraft:dark_oak_log
execute as @s at @s rotated as @s run fill ^5 ^29 ^-9 ^7 ^29 ^-7 minecraft:dark_oak_log
execute as @s at @s rotated as @s run fill ^4 ^30 ^-9 ^6 ^30 ^-7 minecraft:dark_oak_log
execute as @s at @s rotated as @s run fill ^4 ^31 ^-9 ^6 ^31 ^-7 minecraft:dark_oak_log
execute as @s at @s rotated as @s run fill ^3 ^32 ^-9 ^5 ^32 ^-7 minecraft:dark_oak_log
execute as @s at @s rotated as @s run fill ^3 ^33 ^-9 ^5 ^33 ^-7 minecraft:dark_oak_log
execute as @s at @s rotated as @s run fill ^2 ^34 ^-9 ^4 ^34 ^-7 minecraft:dark_oak_log
execute as @s at @s rotated as @s run fill ^-17 ^10 ^-9 ^17 ^11 ^-7 minecraft:spruce_planks
execute as @s at @s rotated as @s run fill ^-12 ^18 ^-9 ^12 ^19 ^-7 minecraft:spruce_planks
execute as @s at @s rotated as @s run fill ^-8 ^26 ^-9 ^8 ^27 ^-7 minecraft:spruce_planks
execute as @s at @s rotated as @s run fill ^-23 ^2 ^7 ^-21 ^2 ^9 minecraft:dark_oak_log
execute as @s at @s rotated as @s run fill ^-22 ^3 ^7 ^-20 ^3 ^9 minecraft:dark_oak_log
execute as @s at @s rotated as @s run fill ^-22 ^4 ^7 ^-20 ^4 ^9 minecraft:dark_oak_log
execute as @s at @s rotated as @s run fill ^-21 ^5 ^7 ^-19 ^5 ^9 minecraft:dark_oak_log
execute as @s at @s rotated as @s run fill ^-21 ^6 ^7 ^-19 ^6 ^9 minecraft:dark_oak_log
execute as @s at @s rotated as @s run fill ^-20 ^7 ^7 ^-18 ^7 ^9 minecraft:dark_oak_log
execute as @s at @s rotated as @s run fill ^-19 ^8 ^7 ^-17 ^8 ^9 minecraft:dark_oak_log
execute as @s at @s rotated as @s run fill ^-19 ^9 ^7 ^-17 ^9 ^9 minecraft:dark_oak_log
execute as @s at @s rotated as @s run fill ^-18 ^10 ^7 ^-16 ^10 ^9 minecraft:dark_oak_log
execute as @s at @s rotated as @s run fill ^-18 ^11 ^7 ^-16 ^11 ^9 minecraft:dark_oak_log
execute as @s at @s rotated as @s run fill ^-17 ^12 ^7 ^-15 ^12 ^9 minecraft:dark_oak_log
execute as @s at @s rotated as @s run fill ^-16 ^13 ^7 ^-14 ^13 ^9 minecraft:dark_oak_log
execute as @s at @s rotated as @s run fill ^-16 ^14 ^7 ^-14 ^14 ^9 minecraft:dark_oak_log
execute as @s at @s rotated as @s run fill ^-15 ^15 ^7 ^-13 ^15 ^9 minecraft:dark_oak_log
execute as @s at @s rotated as @s run fill ^-15 ^16 ^7 ^-13 ^16 ^9 minecraft:dark_oak_log
execute as @s at @s rotated as @s run fill ^-14 ^17 ^7 ^-12 ^17 ^9 minecraft:dark_oak_log
execute as @s at @s rotated as @s run fill ^-13 ^18 ^7 ^-11 ^18 ^9 minecraft:dark_oak_log
execute as @s at @s rotated as @s run fill ^-13 ^19 ^7 ^-11 ^19 ^9 minecraft:dark_oak_log
execute as @s at @s rotated as @s run fill ^-12 ^20 ^7 ^-10 ^20 ^9 minecraft:dark_oak_log
execute as @s at @s rotated as @s run fill ^-12 ^21 ^7 ^-10 ^21 ^9 minecraft:dark_oak_log
execute as @s at @s rotated as @s run fill ^-11 ^22 ^7 ^-9 ^22 ^9 minecraft:dark_oak_log
execute as @s at @s rotated as @s run fill ^-11 ^23 ^7 ^-9 ^23 ^9 minecraft:dark_oak_log
execute as @s at @s rotated as @s run fill ^-10 ^24 ^7 ^-8 ^24 ^9 minecraft:dark_oak_log
execute as @s at @s rotated as @s run fill ^-9 ^25 ^7 ^-7 ^25 ^9 minecraft:dark_oak_log
execute as @s at @s rotated as @s run fill ^-9 ^26 ^7 ^-7 ^26 ^9 minecraft:dark_oak_log
execute as @s at @s rotated as @s run fill ^-8 ^27 ^7 ^-6 ^27 ^9 minecraft:dark_oak_log
execute as @s at @s rotated as @s run fill ^-8 ^28 ^7 ^-6 ^28 ^9 minecraft:dark_oak_log
execute as @s at @s rotated as @s run fill ^-7 ^29 ^7 ^-5 ^29 ^9 minecraft:dark_oak_log
execute as @s at @s rotated as @s run fill ^-6 ^30 ^7 ^-4 ^30 ^9 minecraft:dark_oak_log
execute as @s at @s rotated as @s run fill ^-6 ^31 ^7 ^-4 ^31 ^9 minecraft:dark_oak_log
execute as @s at @s rotated as @s run fill ^-5 ^32 ^7 ^-3 ^32 ^9 minecraft:dark_oak_log
execute as @s at @s rotated as @s run fill ^-5 ^33 ^7 ^-3 ^33 ^9 minecraft:dark_oak_log
execute as @s at @s rotated as @s run fill ^-4 ^34 ^7 ^-2 ^34 ^9 minecraft:dark_oak_log
execute as @s at @s rotated as @s run fill ^21 ^2 ^7 ^23 ^2 ^9 minecraft:dark_oak_log
execute as @s at @s rotated as @s run fill ^20 ^3 ^7 ^22 ^3 ^9 minecraft:dark_oak_log
execute as @s at @s rotated as @s run fill ^20 ^4 ^7 ^22 ^4 ^9 minecraft:dark_oak_log
execute as @s at @s rotated as @s run fill ^19 ^5 ^7 ^21 ^5 ^9 minecraft:dark_oak_log
execute as @s at @s rotated as @s run fill ^19 ^6 ^7 ^21 ^6 ^9 minecraft:dark_oak_log
execute as @s at @s rotated as @s run fill ^18 ^7 ^7 ^20 ^7 ^9 minecraft:dark_oak_log
execute as @s at @s rotated as @s run fill ^17 ^8 ^7 ^19 ^8 ^9 minecraft:dark_oak_log
execute as @s at @s rotated as @s run fill ^17 ^9 ^7 ^19 ^9 ^9 minecraft:dark_oak_log
execute as @s at @s rotated as @s run fill ^16 ^10 ^7 ^18 ^10 ^9 minecraft:dark_oak_log
execute as @s at @s rotated as @s run fill ^16 ^11 ^7 ^18 ^11 ^9 minecraft:dark_oak_log
execute as @s at @s rotated as @s run fill ^15 ^12 ^7 ^17 ^12 ^9 minecraft:dark_oak_log
execute as @s at @s rotated as @s run fill ^14 ^13 ^7 ^16 ^13 ^9 minecraft:dark_oak_log
execute as @s at @s rotated as @s run fill ^14 ^14 ^7 ^16 ^14 ^9 minecraft:dark_oak_log
execute as @s at @s rotated as @s run fill ^13 ^15 ^7 ^15 ^15 ^9 minecraft:dark_oak_log
execute as @s at @s rotated as @s run fill ^13 ^16 ^7 ^15 ^16 ^9 minecraft:dark_oak_log
execute as @s at @s rotated as @s run fill ^12 ^17 ^7 ^14 ^17 ^9 minecraft:dark_oak_log
execute as @s at @s rotated as @s run fill ^11 ^18 ^7 ^13 ^18 ^9 minecraft:dark_oak_log
execute as @s at @s rotated as @s run fill ^11 ^19 ^7 ^13 ^19 ^9 minecraft:dark_oak_log
execute as @s at @s rotated as @s run fill ^10 ^20 ^7 ^12 ^20 ^9 minecraft:dark_oak_log
execute as @s at @s rotated as @s run fill ^10 ^21 ^7 ^12 ^21 ^9 minecraft:dark_oak_log
execute as @s at @s rotated as @s run fill ^9 ^22 ^7 ^11 ^22 ^9 minecraft:dark_oak_log
execute as @s at @s rotated as @s run fill ^9 ^23 ^7 ^11 ^23 ^9 minecraft:dark_oak_log
execute as @s at @s rotated as @s run fill ^8 ^24 ^7 ^10 ^24 ^9 minecraft:dark_oak_log
execute as @s at @s rotated as @s run fill ^7 ^25 ^7 ^9 ^25 ^9 minecraft:dark_oak_log
execute as @s at @s rotated as @s run fill ^7 ^26 ^7 ^9 ^26 ^9 minecraft:dark_oak_log
execute as @s at @s rotated as @s run fill ^6 ^27 ^7 ^8 ^27 ^9 minecraft:dark_oak_log
execute as @s at @s rotated as @s run fill ^6 ^28 ^7 ^8 ^28 ^9 minecraft:dark_oak_log
execute as @s at @s rotated as @s run fill ^5 ^29 ^7 ^7 ^29 ^9 minecraft:dark_oak_log
execute as @s at @s rotated as @s run fill ^4 ^30 ^7 ^6 ^30 ^9 minecraft:dark_oak_log
execute as @s at @s rotated as @s run fill ^4 ^31 ^7 ^6 ^31 ^9 minecraft:dark_oak_log
execute as @s at @s rotated as @s run fill ^3 ^32 ^7 ^5 ^32 ^9 minecraft:dark_oak_log
execute as @s at @s rotated as @s run fill ^3 ^33 ^7 ^5 ^33 ^9 minecraft:dark_oak_log
execute as @s at @s rotated as @s run fill ^2 ^34 ^7 ^4 ^34 ^9 minecraft:dark_oak_log
execute as @s at @s rotated as @s run fill ^-17 ^10 ^7 ^17 ^11 ^9 minecraft:spruce_planks
execute as @s at @s rotated as @s run fill ^-12 ^18 ^7 ^12 ^19 ^9 minecraft:spruce_planks
execute as @s at @s rotated as @s run fill ^-8 ^26 ^7 ^8 ^27 ^9 minecraft:spruce_planks
execute as @s at @s rotated as @s run fill ^-5 ^33 ^-11 ^5 ^37 ^11 minecraft:dark_oak_log
execute as @s at @s rotated as @s run fill ^-3 ^34 ^-13 ^3 ^36 ^13 minecraft:iron_block

# === HUB & AXLE ===
execute as @s at @s rotated as @s run fill ^-4 ^31 ^-4 ^4 ^39 ^4 minecraft:iron_block
execute as @s at @s rotated as @s run fill ^-6 ^33 ^-2 ^6 ^37 ^2 minecraft:gold_block
execute as @s at @s rotated as @s run fill ^-2 ^33 ^-12 ^2 ^37 ^12 minecraft:iron_block
execute as @s at @s rotated as @s run fill ^-1 ^34 ^-14 ^1 ^36 ^14 minecraft:gold_block
execute as @s at @s rotated as @s run setblock ^ ^35 ^-15 minecraft:sea_lantern
execute as @s at @s rotated as @s run setblock ^ ^35 ^15 minecraft:sea_lantern

# === DOUBLE FERRIS WHEEL RIMS ===
execute as @s at @s rotated as @s run setblock ^-31 ^30 ^-4 minecraft:iron_block
execute as @s at @s rotated as @s run setblock ^-31 ^30 ^4 minecraft:iron_block
execute as @s at @s rotated as @s run setblock ^-31 ^31 ^-4 minecraft:iron_block
execute as @s at @s rotated as @s run setblock ^-31 ^31 ^4 minecraft:iron_block
execute as @s at @s rotated as @s run setblock ^-31 ^32 ^-4 minecraft:iron_block
execute as @s at @s rotated as @s run setblock ^-31 ^32 ^4 minecraft:iron_block
execute as @s at @s rotated as @s run setblock ^-31 ^33 ^-4 minecraft:iron_block
execute as @s at @s rotated as @s run setblock ^-31 ^33 ^4 minecraft:iron_block
execute as @s at @s rotated as @s run setblock ^-31 ^34 ^-4 minecraft:iron_block
execute as @s at @s rotated as @s run setblock ^-31 ^34 ^4 minecraft:iron_block
execute as @s at @s rotated as @s run setblock ^-31 ^35 ^-4 minecraft:iron_block
execute as @s at @s rotated as @s run setblock ^-31 ^35 ^4 minecraft:iron_block
execute as @s at @s rotated as @s run setblock ^-31 ^36 ^-4 minecraft:iron_block
execute as @s at @s rotated as @s run setblock ^-31 ^36 ^4 minecraft:iron_block
execute as @s at @s rotated as @s run setblock ^-31 ^37 ^-4 minecraft:iron_block
execute as @s at @s rotated as @s run setblock ^-31 ^37 ^4 minecraft:iron_block
execute as @s at @s rotated as @s run setblock ^-31 ^38 ^-4 minecraft:iron_block
execute as @s at @s rotated as @s run setblock ^-31 ^38 ^4 minecraft:iron_block
execute as @s at @s rotated as @s run setblock ^-31 ^39 ^-4 minecraft:iron_block
execute as @s at @s rotated as @s run setblock ^-31 ^39 ^4 minecraft:iron_block
execute as @s at @s rotated as @s run setblock ^-31 ^40 ^-4 minecraft:iron_block
execute as @s at @s rotated as @s run setblock ^-31 ^40 ^4 minecraft:iron_block
execute as @s at @s rotated as @s run setblock ^-30 ^26 ^-4 minecraft:iron_block
execute as @s at @s rotated as @s run setblock ^-30 ^26 ^4 minecraft:iron_block
execute as @s at @s rotated as @s run setblock ^-30 ^27 ^-4 minecraft:iron_block
execute as @s at @s rotated as @s run setblock ^-30 ^27 ^4 minecraft:iron_block
execute as @s at @s rotated as @s run setblock ^-30 ^28 ^-4 minecraft:iron_block
execute as @s at @s rotated as @s run setblock ^-30 ^28 ^4 minecraft:iron_block
execute as @s at @s rotated as @s run setblock ^-30 ^29 ^-4 minecraft:iron_block
execute as @s at @s rotated as @s run setblock ^-30 ^29 ^4 minecraft:iron_block
execute as @s at @s rotated as @s run setblock ^-30 ^30 ^-4 minecraft:iron_block
execute as @s at @s rotated as @s run setblock ^-30 ^30 ^4 minecraft:iron_block
execute as @s at @s rotated as @s run setblock ^-30 ^31 ^-4 minecraft:iron_block
execute as @s at @s rotated as @s run setblock ^-30 ^31 ^4 minecraft:iron_block
execute as @s at @s rotated as @s run setblock ^-30 ^32 ^-4 minecraft:iron_block
execute as @s at @s rotated as @s run setblock ^-30 ^32 ^4 minecraft:iron_block
execute as @s at @s rotated as @s run setblock ^-30 ^33 ^-4 minecraft:iron_block
execute as @s at @s rotated as @s run setblock ^-30 ^33 ^4 minecraft:iron_block
execute as @s at @s rotated as @s run setblock ^-30 ^34 ^-4 minecraft:iron_block
execute as @s at @s rotated as @s run setblock ^-30 ^34 ^4 minecraft:iron_block
execute as @s at @s rotated as @s run setblock ^-30 ^35 ^-4 minecraft:iron_block
execute as @s at @s rotated as @s run setblock ^-30 ^35 ^4 minecraft:iron_block
execute as @s at @s rotated as @s run setblock ^-30 ^36 ^-4 minecraft:iron_block
execute as @s at @s rotated as @s run setblock ^-30 ^36 ^4 minecraft:iron_block
execute as @s at @s rotated as @s run setblock ^-30 ^37 ^-4 minecraft:iron_block
execute as @s at @s rotated as @s run setblock ^-30 ^37 ^4 minecraft:iron_block
execute as @s at @s rotated as @s run setblock ^-30 ^38 ^-4 minecraft:iron_block
execute as @s at @s rotated as @s run setblock ^-30 ^38 ^4 minecraft:iron_block
execute as @s at @s rotated as @s run setblock ^-30 ^39 ^-4 minecraft:iron_block
execute as @s at @s rotated as @s run setblock ^-30 ^39 ^4 minecraft:iron_block
execute as @s at @s rotated as @s run setblock ^-30 ^40 ^-4 minecraft:iron_block
execute as @s at @s rotated as @s run setblock ^-30 ^40 ^4 minecraft:iron_block
execute as @s at @s rotated as @s run setblock ^-30 ^41 ^-4 minecraft:iron_block
execute as @s at @s rotated as @s run setblock ^-30 ^41 ^4 minecraft:iron_block
execute as @s at @s rotated as @s run setblock ^-30 ^42 ^-4 minecraft:iron_block
execute as @s at @s rotated as @s run setblock ^-30 ^42 ^4 minecraft:iron_block
execute as @s at @s rotated as @s run setblock ^-30 ^43 ^-4 minecraft:iron_block
execute as @s at @s rotated as @s run setblock ^-30 ^43 ^4 minecraft:iron_block
execute as @s at @s rotated as @s run setblock ^-30 ^44 ^-4 minecraft:iron_block
execute as @s at @s rotated as @s run setblock ^-30 ^44 ^4 minecraft:iron_block
execute as @s at @s rotated as @s run setblock ^-29 ^23 ^-4 minecraft:iron_block
execute as @s at @s rotated as @s run setblock ^-29 ^23 ^4 minecraft:iron_block
execute as @s at @s rotated as @s run setblock ^-29 ^24 ^-4 minecraft:iron_block
execute as @s at @s rotated as @s run setblock ^-29 ^24 ^4 minecraft:iron_block
execute as @s at @s rotated as @s run setblock ^-29 ^25 ^-4 minecraft:iron_block
execute as @s at @s rotated as @s run setblock ^-29 ^25 ^4 minecraft:iron_block
execute as @s at @s rotated as @s run setblock ^-29 ^26 ^-4 minecraft:iron_block
execute as @s at @s rotated as @s run setblock ^-29 ^26 ^4 minecraft:iron_block
execute as @s at @s rotated as @s run setblock ^-29 ^27 ^-4 minecraft:iron_block
execute as @s at @s rotated as @s run setblock ^-29 ^27 ^4 minecraft:iron_block
execute as @s at @s rotated as @s run setblock ^-29 ^28 ^-4 minecraft:iron_block
execute as @s at @s rotated as @s run setblock ^-29 ^28 ^4 minecraft:iron_block
execute as @s at @s rotated as @s run setblock ^-29 ^29 ^-4 minecraft:iron_block
execute as @s at @s rotated as @s run setblock ^-29 ^29 ^4 minecraft:iron_block
execute as @s at @s rotated as @s run setblock ^-29 ^30 ^-4 minecraft:iron_block
execute as @s at @s rotated as @s run setblock ^-29 ^30 ^4 minecraft:iron_block
execute as @s at @s rotated as @s run setblock ^-29 ^31 ^-4 minecraft:iron_block
execute as @s at @s rotated as @s run setblock ^-29 ^31 ^4 minecraft:iron_block
execute as @s at @s rotated as @s run setblock ^-29 ^32 ^-4 minecraft:iron_block
execute as @s at @s rotated as @s run setblock ^-29 ^32 ^4 minecraft:iron_block
execute as @s at @s rotated as @s run setblock ^-29 ^33 ^-4 minecraft:iron_block
execute as @s at @s rotated as @s run setblock ^-29 ^33 ^4 minecraft:iron_block
execute as @s at @s rotated as @s run setblock ^-29 ^34 ^-4 minecraft:iron_block
execute as @s at @s rotated as @s run setblock ^-29 ^34 ^4 minecraft:iron_block
execute as @s at @s rotated as @s run setblock ^-29 ^35 ^-4 minecraft:iron_block
execute as @s at @s rotated as @s run setblock ^-29 ^35 ^4 minecraft:iron_block
execute as @s at @s rotated as @s run setblock ^-29 ^36 ^-4 minecraft:iron_block
execute as @s at @s rotated as @s run setblock ^-29 ^36 ^4 minecraft:iron_block
execute as @s at @s rotated as @s run setblock ^-29 ^37 ^-4 minecraft:iron_block
execute as @s at @s rotated as @s run setblock ^-29 ^37 ^4 minecraft:iron_block
execute as @s at @s rotated as @s run setblock ^-29 ^38 ^-4 minecraft:iron_block
execute as @s at @s rotated as @s run setblock ^-29 ^38 ^4 minecraft:iron_block
execute as @s at @s rotated as @s run setblock ^-29 ^39 ^-4 minecraft:iron_block
execute as @s at @s rotated as @s run setblock ^-29 ^39 ^4 minecraft:iron_block
execute as @s at @s rotated as @s run setblock ^-29 ^40 ^-4 minecraft:iron_block
execute as @s at @s rotated as @s run setblock ^-29 ^40 ^4 minecraft:iron_block
execute as @s at @s rotated as @s run setblock ^-29 ^41 ^-4 minecraft:iron_block
execute as @s at @s rotated as @s run setblock ^-29 ^41 ^4 minecraft:iron_block
execute as @s at @s rotated as @s run setblock ^-29 ^42 ^-4 minecraft:iron_block
execute as @s at @s rotated as @s run setblock ^-29 ^42 ^4 minecraft:iron_block
execute as @s at @s rotated as @s run setblock ^-29 ^43 ^-4 minecraft:iron_block
execute as @s at @s rotated as @s run setblock ^-29 ^43 ^4 minecraft:iron_block
execute as @s at @s rotated as @s run setblock ^-29 ^44 ^-4 minecraft:iron_block
execute as @s at @s rotated as @s run setblock ^-29 ^44 ^4 minecraft:iron_block
execute as @s at @s rotated as @s run setblock ^-29 ^45 ^-4 minecraft:iron_block
execute as @s at @s rotated as @s run setblock ^-29 ^45 ^4 minecraft:iron_block
execute as @s at @s rotated as @s run setblock ^-29 ^46 ^-4 minecraft:iron_block
execute as @s at @s rotated as @s run setblock ^-29 ^46 ^4 minecraft:iron_block
execute as @s at @s rotated as @s run setblock ^-29 ^47 ^-4 minecraft:iron_block
execute as @s at @s rotated as @s run setblock ^-29 ^47 ^4 minecraft:iron_block
execute as @s at @s rotated as @s run setblock ^-28 ^21 ^-4 minecraft:iron_block
execute as @s at @s rotated as @s run setblock ^-28 ^21 ^4 minecraft:iron_block
execute as @s at @s rotated as @s run setblock ^-28 ^22 ^-4 minecraft:iron_block
execute as @s at @s rotated as @s run setblock ^-28 ^22 ^4 minecraft:iron_block
execute as @s at @s rotated as @s run setblock ^-28 ^23 ^-4 minecraft:iron_block
execute as @s at @s rotated as @s run setblock ^-28 ^23 ^4 minecraft:iron_block
execute as @s at @s rotated as @s run setblock ^-28 ^24 ^-4 minecraft:iron_block
execute as @s at @s rotated as @s run setblock ^-28 ^24 ^4 minecraft:iron_block
execute as @s at @s rotated as @s run setblock ^-28 ^25 ^-4 minecraft:iron_block
execute as @s at @s rotated as @s run setblock ^-28 ^25 ^4 minecraft:iron_block
execute as @s at @s rotated as @s run setblock ^-28 ^26 ^-4 minecraft:iron_block
execute as @s at @s rotated as @s run setblock ^-28 ^26 ^4 minecraft:iron_block
execute as @s at @s rotated as @s run setblock ^-28 ^27 ^-4 minecraft:iron_block
execute as @s at @s rotated as @s run setblock ^-28 ^27 ^4 minecraft:iron_block
execute as @s at @s rotated as @s run setblock ^-28 ^28 ^-4 minecraft:iron_block
execute as @s at @s rotated as @s run setblock ^-28 ^28 ^4 minecraft:iron_block
execute as @s at @s rotated as @s run setblock ^-28 ^29 ^-4 minecraft:iron_block
execute as @s at @s rotated as @s run setblock ^-28 ^29 ^4 minecraft:iron_block
execute as @s at @s rotated as @s run setblock ^-28 ^30 ^-4 minecraft:iron_block
execute as @s at @s rotated as @s run setblock ^-28 ^30 ^4 minecraft:iron_block
execute as @s at @s rotated as @s run setblock ^-28 ^31 ^-4 minecraft:iron_block
execute as @s at @s rotated as @s run setblock ^-28 ^31 ^4 minecraft:iron_block
execute as @s at @s rotated as @s run setblock ^-28 ^32 ^-4 minecraft:iron_block
execute as @s at @s rotated as @s run setblock ^-28 ^32 ^4 minecraft:iron_block
execute as @s at @s rotated as @s run setblock ^-28 ^33 ^-4 minecraft:iron_block
execute as @s at @s rotated as @s run setblock ^-28 ^33 ^4 minecraft:iron_block
execute as @s at @s rotated as @s run setblock ^-28 ^34 ^-4 minecraft:iron_block
execute as @s at @s rotated as @s run setblock ^-28 ^34 ^4 minecraft:iron_block
execute as @s at @s rotated as @s run setblock ^-28 ^35 ^-4 minecraft:iron_block
execute as @s at @s rotated as @s run setblock ^-28 ^35 ^4 minecraft:iron_block
execute as @s at @s rotated as @s run setblock ^-28 ^36 ^-4 minecraft:iron_block
execute as @s at @s rotated as @s run setblock ^-28 ^36 ^4 minecraft:iron_block
execute as @s at @s rotated as @s run setblock ^-28 ^37 ^-4 minecraft:iron_block
execute as @s at @s rotated as @s run setblock ^-28 ^37 ^4 minecraft:iron_block
execute as @s at @s rotated as @s run setblock ^-28 ^38 ^-4 minecraft:iron_block
execute as @s at @s rotated as @s run setblock ^-28 ^38 ^4 minecraft:iron_block
execute as @s at @s rotated as @s run setblock ^-28 ^39 ^-4 minecraft:iron_block
execute as @s at @s rotated as @s run setblock ^-28 ^39 ^4 minecraft:iron_block
execute as @s at @s rotated as @s run setblock ^-28 ^40 ^-4 minecraft:iron_block
execute as @s at @s rotated as @s run setblock ^-28 ^40 ^4 minecraft:iron_block
execute as @s at @s rotated as @s run setblock ^-28 ^41 ^-4 minecraft:iron_block
execute as @s at @s rotated as @s run setblock ^-28 ^41 ^4 minecraft:iron_block
execute as @s at @s rotated as @s run setblock ^-28 ^42 ^-4 minecraft:iron_block
execute as @s at @s rotated as @s run setblock ^-28 ^42 ^4 minecraft:iron_block
execute as @s at @s rotated as @s run setblock ^-28 ^43 ^-4 minecraft:iron_block
execute as @s at @s rotated as @s run setblock ^-28 ^43 ^4 minecraft:iron_block
execute as @s at @s rotated as @s run setblock ^-28 ^44 ^-4 minecraft:iron_block
execute as @s at @s rotated as @s run setblock ^-28 ^44 ^4 minecraft:iron_block
execute as @s at @s rotated as @s run setblock ^-28 ^45 ^-4 minecraft:iron_block
execute as @s at @s rotated as @s run setblock ^-28 ^45 ^4 minecraft:iron_block
execute as @s at @s rotated as @s run setblock ^-28 ^46 ^-4 minecraft:iron_block
execute as @s at @s rotated as @s run setblock ^-28 ^46 ^4 minecraft:iron_block
execute as @s at @s rotated as @s run setblock ^-28 ^47 ^-4 minecraft:iron_block
execute as @s at @s rotated as @s run setblock ^-28 ^47 ^4 minecraft:iron_block
execute as @s at @s rotated as @s run setblock ^-28 ^48 ^-4 minecraft:iron_block
execute as @s at @s rotated as @s run setblock ^-28 ^48 ^4 minecraft:iron_block
execute as @s at @s rotated as @s run setblock ^-28 ^49 ^-4 minecraft:iron_block
execute as @s at @s rotated as @s run setblock ^-28 ^49 ^4 minecraft:iron_block
execute as @s at @s rotated as @s run setblock ^-27 ^19 ^-4 minecraft:iron_block
execute as @s at @s rotated as @s run setblock ^-27 ^19 ^4 minecraft:iron_block
execute as @s at @s rotated as @s run setblock ^-27 ^20 ^-4 minecraft:iron_block
execute as @s at @s rotated as @s run setblock ^-27 ^20 ^4 minecraft:iron_block
execute as @s at @s rotated as @s run setblock ^-27 ^21 ^-4 minecraft:iron_block
execute as @s at @s rotated as @s run setblock ^-27 ^21 ^4 minecraft:iron_block
execute as @s at @s rotated as @s run setblock ^-27 ^22 ^-4 minecraft:iron_block
execute as @s at @s rotated as @s run setblock ^-27 ^22 ^4 minecraft:iron_block
execute as @s at @s rotated as @s run setblock ^-27 ^23 ^-4 minecraft:iron_block
execute as @s at @s rotated as @s run setblock ^-27 ^23 ^4 minecraft:iron_block
execute as @s at @s rotated as @s run setblock ^-27 ^24 ^-4 minecraft:iron_block
execute as @s at @s rotated as @s run setblock ^-27 ^24 ^4 minecraft:iron_block
execute as @s at @s rotated as @s run setblock ^-27 ^25 ^-4 minecraft:iron_block
execute as @s at @s rotated as @s run setblock ^-27 ^25 ^4 minecraft:iron_block
execute as @s at @s rotated as @s run setblock ^-27 ^26 ^-4 minecraft:iron_block
execute as @s at @s rotated as @s run setblock ^-27 ^26 ^4 minecraft:iron_block
execute as @s at @s rotated as @s run setblock ^-27 ^27 ^-4 minecraft:iron_block
execute as @s at @s rotated as @s run setblock ^-27 ^27 ^4 minecraft:iron_block
execute as @s at @s rotated as @s run setblock ^-27 ^28 ^-4 minecraft:iron_block
execute as @s at @s rotated as @s run setblock ^-27 ^28 ^4 minecraft:iron_block
execute as @s at @s rotated as @s run setblock ^-27 ^29 ^-4 minecraft:iron_block
execute as @s at @s rotated as @s run setblock ^-27 ^29 ^4 minecraft:iron_block
execute as @s at @s rotated as @s run setblock ^-27 ^30 ^-4 minecraft:iron_block
execute as @s at @s rotated as @s run setblock ^-27 ^30 ^4 minecraft:iron_block
execute as @s at @s rotated as @s run setblock ^-27 ^40 ^-4 minecraft:iron_block
execute as @s at @s rotated as @s run setblock ^-27 ^40 ^4 minecraft:iron_block
execute as @s at @s rotated as @s run setblock ^-27 ^41 ^-4 minecraft:iron_block
execute as @s at @s rotated as @s run setblock ^-27 ^41 ^4 minecraft:iron_block
execute as @s at @s rotated as @s run setblock ^-27 ^42 ^-4 minecraft:iron_block
execute as @s at @s rotated as @s run setblock ^-27 ^42 ^4 minecraft:iron_block
execute as @s at @s rotated as @s run setblock ^-27 ^43 ^-4 minecraft:iron_block
execute as @s at @s rotated as @s run setblock ^-27 ^43 ^4 minecraft:iron_block
execute as @s at @s rotated as @s run setblock ^-27 ^44 ^-4 minecraft:iron_block
execute as @s at @s rotated as @s run setblock ^-27 ^44 ^4 minecraft:iron_block
execute as @s at @s rotated as @s run setblock ^-27 ^45 ^-4 minecraft:iron_block
execute as @s at @s rotated as @s run setblock ^-27 ^45 ^4 minecraft:iron_block
execute as @s at @s rotated as @s run setblock ^-27 ^46 ^-4 minecraft:iron_block
execute as @s at @s rotated as @s run setblock ^-27 ^46 ^4 minecraft:iron_block
execute as @s at @s rotated as @s run setblock ^-27 ^47 ^-4 minecraft:iron_block
execute as @s at @s rotated as @s run setblock ^-27 ^47 ^4 minecraft:iron_block
execute as @s at @s rotated as @s run setblock ^-27 ^48 ^-4 minecraft:iron_block
execute as @s at @s rotated as @s run setblock ^-27 ^48 ^4 minecraft:iron_block
execute as @s at @s rotated as @s run setblock ^-27 ^49 ^-4 minecraft:iron_block
execute as @s at @s rotated as @s run setblock ^-27 ^49 ^4 minecraft:iron_block
execute as @s at @s rotated as @s run setblock ^-27 ^50 ^-4 minecraft:iron_block
execute as @s at @s rotated as @s run setblock ^-27 ^50 ^4 minecraft:iron_block
execute as @s at @s rotated as @s run setblock ^-27 ^51 ^-4 minecraft:iron_block
execute as @s at @s rotated as @s run setblock ^-27 ^51 ^4 minecraft:iron_block
execute as @s at @s rotated as @s run setblock ^-26 ^18 ^-4 minecraft:iron_block
execute as @s at @s rotated as @s run setblock ^-26 ^18 ^4 minecraft:iron_block
execute as @s at @s rotated as @s run setblock ^-26 ^19 ^-4 minecraft:iron_block
execute as @s at @s rotated as @s run setblock ^-26 ^19 ^4 minecraft:iron_block
execute as @s at @s rotated as @s run setblock ^-26 ^20 ^-4 minecraft:iron_block
execute as @s at @s rotated as @s run setblock ^-26 ^20 ^4 minecraft:iron_block
execute as @s at @s rotated as @s run setblock ^-26 ^21 ^-4 minecraft:iron_block
execute as @s at @s rotated as @s run setblock ^-26 ^21 ^4 minecraft:iron_block
execute as @s at @s rotated as @s run setblock ^-26 ^22 ^-4 minecraft:iron_block
execute as @s at @s rotated as @s run setblock ^-26 ^22 ^4 minecraft:iron_block
execute as @s at @s rotated as @s run setblock ^-26 ^23 ^-4 minecraft:iron_block
execute as @s at @s rotated as @s run setblock ^-26 ^23 ^4 minecraft:iron_block
execute as @s at @s rotated as @s run setblock ^-26 ^24 ^-4 minecraft:iron_block
execute as @s at @s rotated as @s run setblock ^-26 ^24 ^4 minecraft:iron_block
execute as @s at @s rotated as @s run setblock ^-26 ^25 ^-4 minecraft:iron_block
execute as @s at @s rotated as @s run setblock ^-26 ^25 ^4 minecraft:iron_block
execute as @s at @s rotated as @s run setblock ^-26 ^26 ^-4 minecraft:iron_block
execute as @s at @s rotated as @s run setblock ^-26 ^26 ^4 minecraft:iron_block
execute as @s at @s rotated as @s run setblock ^-26 ^44 ^-4 minecraft:iron_block
execute as @s at @s rotated as @s run setblock ^-26 ^44 ^4 minecraft:iron_block
execute as @s at @s rotated as @s run setblock ^-26 ^45 ^-4 minecraft:iron_block
execute as @s at @s rotated as @s run setblock ^-26 ^45 ^4 minecraft:iron_block
execute as @s at @s rotated as @s run setblock ^-26 ^46 ^-4 minecraft:iron_block
execute as @s at @s rotated as @s run setblock ^-26 ^46 ^4 minecraft:iron_block
execute as @s at @s rotated as @s run setblock ^-26 ^47 ^-4 minecraft:iron_block
execute as @s at @s rotated as @s run setblock ^-26 ^47 ^4 minecraft:iron_block
execute as @s at @s rotated as @s run setblock ^-26 ^48 ^-4 minecraft:iron_block
execute as @s at @s rotated as @s run setblock ^-26 ^48 ^4 minecraft:iron_block
execute as @s at @s rotated as @s run setblock ^-26 ^49 ^-4 minecraft:iron_block
execute as @s at @s rotated as @s run setblock ^-26 ^49 ^4 minecraft:iron_block
execute as @s at @s rotated as @s run setblock ^-26 ^50 ^-4 minecraft:iron_block
execute as @s at @s rotated as @s run setblock ^-26 ^50 ^4 minecraft:iron_block
execute as @s at @s rotated as @s run setblock ^-26 ^51 ^-4 minecraft:iron_block
execute as @s at @s rotated as @s run setblock ^-26 ^51 ^4 minecraft:iron_block
execute as @s at @s rotated as @s run setblock ^-26 ^52 ^-4 minecraft:iron_block
execute as @s at @s rotated as @s run setblock ^-26 ^52 ^4 minecraft:iron_block
execute as @s at @s rotated as @s run setblock ^-25 ^16 ^-4 minecraft:iron_block
execute as @s at @s rotated as @s run setblock ^-25 ^16 ^4 minecraft:iron_block
execute as @s at @s rotated as @s run setblock ^-25 ^17 ^-4 minecraft:iron_block
execute as @s at @s rotated as @s run setblock ^-25 ^17 ^4 minecraft:iron_block
execute as @s at @s rotated as @s run setblock ^-25 ^18 ^-4 minecraft:iron_block
execute as @s at @s rotated as @s run setblock ^-25 ^18 ^4 minecraft:iron_block
execute as @s at @s rotated as @s run setblock ^-25 ^19 ^-4 minecraft:iron_block
execute as @s at @s rotated as @s run setblock ^-25 ^19 ^4 minecraft:iron_block
execute as @s at @s rotated as @s run setblock ^-25 ^20 ^-4 minecraft:iron_block
execute as @s at @s rotated as @s run setblock ^-25 ^20 ^4 minecraft:iron_block
execute as @s at @s rotated as @s run setblock ^-25 ^21 ^-4 minecraft:iron_block
execute as @s at @s rotated as @s run setblock ^-25 ^21 ^4 minecraft:iron_block
execute as @s at @s rotated as @s run setblock ^-25 ^22 ^-4 minecraft:iron_block
execute as @s at @s rotated as @s run setblock ^-25 ^22 ^4 minecraft:iron_block
execute as @s at @s rotated as @s run setblock ^-25 ^23 ^-4 minecraft:iron_block
execute as @s at @s rotated as @s run setblock ^-25 ^23 ^4 minecraft:iron_block
execute as @s at @s rotated as @s run setblock ^-25 ^47 ^-4 minecraft:iron_block
execute as @s at @s rotated as @s run setblock ^-25 ^47 ^4 minecraft:iron_block
execute as @s at @s rotated as @s run setblock ^-25 ^48 ^-4 minecraft:iron_block
execute as @s at @s rotated as @s run setblock ^-25 ^48 ^4 minecraft:iron_block
execute as @s at @s rotated as @s run setblock ^-25 ^49 ^-4 minecraft:iron_block
execute as @s at @s rotated as @s run setblock ^-25 ^49 ^4 minecraft:iron_block
execute as @s at @s rotated as @s run setblock ^-25 ^50 ^-4 minecraft:iron_block
execute as @s at @s rotated as @s run setblock ^-25 ^50 ^4 minecraft:iron_block
execute as @s at @s rotated as @s run setblock ^-25 ^51 ^-4 minecraft:iron_block
execute as @s at @s rotated as @s run setblock ^-25 ^51 ^4 minecraft:iron_block
execute as @s at @s rotated as @s run setblock ^-25 ^52 ^-4 minecraft:iron_block
execute as @s at @s rotated as @s run setblock ^-25 ^52 ^4 minecraft:iron_block
execute as @s at @s rotated as @s run setblock ^-25 ^53 ^-4 minecraft:iron_block
execute as @s at @s rotated as @s run setblock ^-25 ^53 ^4 minecraft:iron_block
execute as @s at @s rotated as @s run setblock ^-25 ^54 ^-4 minecraft:iron_block
execute as @s at @s rotated as @s run setblock ^-25 ^54 ^4 minecraft:iron_block
execute as @s at @s rotated as @s run setblock ^-24 ^15 ^-4 minecraft:iron_block
execute as @s at @s rotated as @s run setblock ^-24 ^15 ^4 minecraft:iron_block
execute as @s at @s rotated as @s run setblock ^-24 ^16 ^-4 minecraft:iron_block
execute as @s at @s rotated as @s run setblock ^-24 ^16 ^4 minecraft:iron_block
execute as @s at @s rotated as @s run setblock ^-24 ^17 ^-4 minecraft:iron_block
execute as @s at @s rotated as @s run setblock ^-24 ^17 ^4 minecraft:iron_block
execute as @s at @s rotated as @s run setblock ^-24 ^18 ^-4 minecraft:iron_block
execute as @s at @s rotated as @s run setblock ^-24 ^18 ^4 minecraft:iron_block
execute as @s at @s rotated as @s run setblock ^-24 ^19 ^-4 minecraft:iron_block
execute as @s at @s rotated as @s run setblock ^-24 ^19 ^4 minecraft:iron_block
execute as @s at @s rotated as @s run setblock ^-24 ^20 ^-4 minecraft:iron_block
execute as @s at @s rotated as @s run setblock ^-24 ^20 ^4 minecraft:iron_block
execute as @s at @s rotated as @s run setblock ^-24 ^21 ^-4 minecraft:iron_block
execute as @s at @s rotated as @s run setblock ^-24 ^21 ^4 minecraft:iron_block
execute as @s at @s rotated as @s run setblock ^-24 ^49 ^-4 minecraft:iron_block
execute as @s at @s rotated as @s run setblock ^-24 ^49 ^4 minecraft:iron_block
execute as @s at @s rotated as @s run setblock ^-24 ^50 ^-4 minecraft:iron_block
execute as @s at @s rotated as @s run setblock ^-24 ^50 ^4 minecraft:iron_block
execute as @s at @s rotated as @s run setblock ^-24 ^51 ^-4 minecraft:iron_block
execute as @s at @s rotated as @s run setblock ^-24 ^51 ^4 minecraft:iron_block
execute as @s at @s rotated as @s run setblock ^-24 ^52 ^-4 minecraft:iron_block
execute as @s at @s rotated as @s run setblock ^-24 ^52 ^4 minecraft:iron_block
execute as @s at @s rotated as @s run setblock ^-24 ^53 ^-4 minecraft:iron_block
execute as @s at @s rotated as @s run setblock ^-24 ^53 ^4 minecraft:iron_block
execute as @s at @s rotated as @s run setblock ^-24 ^54 ^-4 minecraft:iron_block
execute as @s at @s rotated as @s run setblock ^-24 ^54 ^4 minecraft:iron_block
execute as @s at @s rotated as @s run setblock ^-24 ^55 ^-4 minecraft:iron_block
execute as @s at @s rotated as @s run setblock ^-24 ^55 ^4 minecraft:iron_block
execute as @s at @s rotated as @s run setblock ^-23 ^14 ^-4 minecraft:iron_block
execute as @s at @s rotated as @s run setblock ^-23 ^14 ^4 minecraft:iron_block
execute as @s at @s rotated as @s run setblock ^-23 ^15 ^-4 minecraft:iron_block
execute as @s at @s rotated as @s run setblock ^-23 ^15 ^4 minecraft:iron_block
execute as @s at @s rotated as @s run setblock ^-23 ^16 ^-4 minecraft:iron_block
execute as @s at @s rotated as @s run setblock ^-23 ^16 ^4 minecraft:iron_block
execute as @s at @s rotated as @s run setblock ^-23 ^17 ^-4 minecraft:iron_block
execute as @s at @s rotated as @s run setblock ^-23 ^17 ^4 minecraft:iron_block
execute as @s at @s rotated as @s run setblock ^-23 ^18 ^-4 minecraft:iron_block
execute as @s at @s rotated as @s run setblock ^-23 ^18 ^4 minecraft:iron_block
execute as @s at @s rotated as @s run setblock ^-23 ^19 ^-4 minecraft:iron_block
execute as @s at @s rotated as @s run setblock ^-23 ^19 ^4 minecraft:iron_block
execute as @s at @s rotated as @s run setblock ^-23 ^20 ^-4 minecraft:iron_block
execute as @s at @s rotated as @s run setblock ^-23 ^20 ^4 minecraft:iron_block
execute as @s at @s rotated as @s run setblock ^-23 ^50 ^-4 minecraft:iron_block
execute as @s at @s rotated as @s run setblock ^-23 ^50 ^4 minecraft:iron_block
execute as @s at @s rotated as @s run setblock ^-23 ^51 ^-4 minecraft:iron_block
execute as @s at @s rotated as @s run setblock ^-23 ^51 ^4 minecraft:iron_block
execute as @s at @s rotated as @s run setblock ^-23 ^52 ^-4 minecraft:iron_block
execute as @s at @s rotated as @s run setblock ^-23 ^52 ^4 minecraft:iron_block
execute as @s at @s rotated as @s run setblock ^-23 ^53 ^-4 minecraft:iron_block
execute as @s at @s rotated as @s run setblock ^-23 ^53 ^4 minecraft:iron_block
execute as @s at @s rotated as @s run setblock ^-23 ^54 ^-4 minecraft:iron_block
execute as @s at @s rotated as @s run setblock ^-23 ^54 ^4 minecraft:iron_block
execute as @s at @s rotated as @s run setblock ^-23 ^55 ^-4 minecraft:iron_block
execute as @s at @s rotated as @s run setblock ^-23 ^55 ^4 minecraft:iron_block
execute as @s at @s rotated as @s run setblock ^-23 ^56 ^-4 minecraft:iron_block
execute as @s at @s rotated as @s run setblock ^-23 ^56 ^4 minecraft:iron_block
execute as @s at @s rotated as @s run setblock ^-22 ^13 ^-4 minecraft:iron_block
execute as @s at @s rotated as @s run setblock ^-22 ^13 ^4 minecraft:iron_block
execute as @s at @s rotated as @s run setblock ^-22 ^14 ^-4 minecraft:iron_block
execute as @s at @s rotated as @s run setblock ^-22 ^14 ^4 minecraft:iron_block
execute as @s at @s rotated as @s run setblock ^-22 ^15 ^-4 minecraft:iron_block
execute as @s at @s rotated as @s run setblock ^-22 ^15 ^4 minecraft:iron_block
execute as @s at @s rotated as @s run setblock ^-22 ^16 ^-4 minecraft:iron_block
execute as @s at @s rotated as @s run setblock ^-22 ^16 ^4 minecraft:iron_block
execute as @s at @s rotated as @s run setblock ^-22 ^17 ^-4 minecraft:iron_block
execute as @s at @s rotated as @s run setblock ^-22 ^17 ^4 minecraft:iron_block
execute as @s at @s rotated as @s run setblock ^-22 ^18 ^-4 minecraft:iron_block
execute as @s at @s rotated as @s run setblock ^-22 ^18 ^4 minecraft:iron_block
execute as @s at @s rotated as @s run setblock ^-22 ^52 ^-4 minecraft:iron_block
execute as @s at @s rotated as @s run setblock ^-22 ^52 ^4 minecraft:iron_block
execute as @s at @s rotated as @s run setblock ^-22 ^53 ^-4 minecraft:iron_block
execute as @s at @s rotated as @s run setblock ^-22 ^53 ^4 minecraft:iron_block
execute as @s at @s rotated as @s run setblock ^-22 ^54 ^-4 minecraft:iron_block
execute as @s at @s rotated as @s run setblock ^-22 ^54 ^4 minecraft:iron_block
execute as @s at @s rotated as @s run setblock ^-22 ^55 ^-4 minecraft:iron_block
execute as @s at @s rotated as @s run setblock ^-22 ^55 ^4 minecraft:iron_block
execute as @s at @s rotated as @s run setblock ^-22 ^56 ^-4 minecraft:iron_block
execute as @s at @s rotated as @s run setblock ^-22 ^56 ^4 minecraft:iron_block
execute as @s at @s rotated as @s run setblock ^-22 ^57 ^-4 minecraft:iron_block
execute as @s at @s rotated as @s run setblock ^-22 ^57 ^4 minecraft:iron_block
execute as @s at @s rotated as @s run setblock ^-21 ^12 ^-4 minecraft:iron_block
execute as @s at @s rotated as @s run setblock ^-21 ^12 ^4 minecraft:iron_block
execute as @s at @s rotated as @s run setblock ^-21 ^13 ^-4 minecraft:iron_block
execute as @s at @s rotated as @s run setblock ^-21 ^13 ^4 minecraft:iron_block
execute as @s at @s rotated as @s run setblock ^-21 ^14 ^-4 minecraft:iron_block
execute as @s at @s rotated as @s run setblock ^-21 ^14 ^4 minecraft:iron_block
execute as @s at @s rotated as @s run setblock ^-21 ^15 ^-4 minecraft:iron_block
execute as @s at @s rotated as @s run setblock ^-21 ^15 ^4 minecraft:iron_block
execute as @s at @s rotated as @s run setblock ^-21 ^16 ^-4 minecraft:iron_block
execute as @s at @s rotated as @s run setblock ^-21 ^16 ^4 minecraft:iron_block
execute as @s at @s rotated as @s run setblock ^-21 ^17 ^-4 minecraft:iron_block
execute as @s at @s rotated as @s run setblock ^-21 ^17 ^4 minecraft:iron_block
execute as @s at @s rotated as @s run setblock ^-21 ^53 ^-4 minecraft:iron_block
execute as @s at @s rotated as @s run setblock ^-21 ^53 ^4 minecraft:iron_block
execute as @s at @s rotated as @s run setblock ^-21 ^54 ^-4 minecraft:iron_block
execute as @s at @s rotated as @s run setblock ^-21 ^54 ^4 minecraft:iron_block
execute as @s at @s rotated as @s run setblock ^-21 ^55 ^-4 minecraft:iron_block
execute as @s at @s rotated as @s run setblock ^-21 ^55 ^4 minecraft:iron_block
execute as @s at @s rotated as @s run setblock ^-21 ^56 ^-4 minecraft:iron_block
execute as @s at @s rotated as @s run setblock ^-21 ^56 ^4 minecraft:iron_block
execute as @s at @s rotated as @s run setblock ^-21 ^57 ^-4 minecraft:iron_block
execute as @s at @s rotated as @s run setblock ^-21 ^57 ^4 minecraft:iron_block
execute as @s at @s rotated as @s run setblock ^-21 ^58 ^-4 minecraft:iron_block
execute as @s at @s rotated as @s run setblock ^-21 ^58 ^4 minecraft:iron_block
execute as @s at @s rotated as @s run setblock ^-20 ^11 ^-4 minecraft:iron_block
execute as @s at @s rotated as @s run setblock ^-20 ^11 ^4 minecraft:iron_block
execute as @s at @s rotated as @s run setblock ^-20 ^12 ^-4 minecraft:iron_block
execute as @s at @s rotated as @s run setblock ^-20 ^12 ^4 minecraft:iron_block
execute as @s at @s rotated as @s run setblock ^-20 ^13 ^-4 minecraft:iron_block
execute as @s at @s rotated as @s run setblock ^-20 ^13 ^4 minecraft:iron_block
execute as @s at @s rotated as @s run setblock ^-20 ^14 ^-4 minecraft:iron_block
execute as @s at @s rotated as @s run setblock ^-20 ^14 ^4 minecraft:iron_block
execute as @s at @s rotated as @s run setblock ^-20 ^15 ^-4 minecraft:iron_block
execute as @s at @s rotated as @s run setblock ^-20 ^15 ^4 minecraft:iron_block
execute as @s at @s rotated as @s run setblock ^-20 ^16 ^-4 minecraft:iron_block
execute as @s at @s rotated as @s run setblock ^-20 ^16 ^4 minecraft:iron_block
execute as @s at @s rotated as @s run setblock ^-20 ^54 ^-4 minecraft:iron_block
execute as @s at @s rotated as @s run setblock ^-20 ^54 ^4 minecraft:iron_block
execute as @s at @s rotated as @s run setblock ^-20 ^55 ^-4 minecraft:iron_block
execute as @s at @s rotated as @s run setblock ^-20 ^55 ^4 minecraft:iron_block
execute as @s at @s rotated as @s run setblock ^-20 ^56 ^-4 minecraft:iron_block
execute as @s at @s rotated as @s run setblock ^-20 ^56 ^4 minecraft:iron_block
execute as @s at @s rotated as @s run setblock ^-20 ^57 ^-4 minecraft:iron_block
execute as @s at @s rotated as @s run setblock ^-20 ^57 ^4 minecraft:iron_block
execute as @s at @s rotated as @s run setblock ^-20 ^58 ^-4 minecraft:iron_block
execute as @s at @s rotated as @s run setblock ^-20 ^58 ^4 minecraft:iron_block
execute as @s at @s rotated as @s run setblock ^-20 ^59 ^-4 minecraft:iron_block
execute as @s at @s rotated as @s run setblock ^-20 ^59 ^4 minecraft:iron_block
execute as @s at @s rotated as @s run setblock ^-19 ^10 ^-4 minecraft:iron_block
execute as @s at @s rotated as @s run setblock ^-19 ^10 ^4 minecraft:iron_block
execute as @s at @s rotated as @s run setblock ^-19 ^11 ^-4 minecraft:iron_block
execute as @s at @s rotated as @s run setblock ^-19 ^11 ^4 minecraft:iron_block
execute as @s at @s rotated as @s run setblock ^-19 ^12 ^-4 minecraft:iron_block
execute as @s at @s rotated as @s run setblock ^-19 ^12 ^4 minecraft:iron_block
execute as @s at @s rotated as @s run setblock ^-19 ^13 ^-4 minecraft:iron_block
execute as @s at @s rotated as @s run setblock ^-19 ^13 ^4 minecraft:iron_block
execute as @s at @s rotated as @s run setblock ^-19 ^14 ^-4 minecraft:iron_block
execute as @s at @s rotated as @s run setblock ^-19 ^14 ^4 minecraft:iron_block
execute as @s at @s rotated as @s run setblock ^-19 ^15 ^-4 minecraft:iron_block
execute as @s at @s rotated as @s run setblock ^-19 ^15 ^4 minecraft:iron_block
execute as @s at @s rotated as @s run setblock ^-19 ^55 ^-4 minecraft:iron_block
execute as @s at @s rotated as @s run setblock ^-19 ^55 ^4 minecraft:iron_block
execute as @s at @s rotated as @s run setblock ^-19 ^56 ^-4 minecraft:iron_block
execute as @s at @s rotated as @s run setblock ^-19 ^56 ^4 minecraft:iron_block
execute as @s at @s rotated as @s run setblock ^-19 ^57 ^-4 minecraft:iron_block
execute as @s at @s rotated as @s run setblock ^-19 ^57 ^4 minecraft:iron_block
execute as @s at @s rotated as @s run setblock ^-19 ^58 ^-4 minecraft:iron_block
execute as @s at @s rotated as @s run setblock ^-19 ^58 ^4 minecraft:iron_block
execute as @s at @s rotated as @s run setblock ^-19 ^59 ^-4 minecraft:iron_block
execute as @s at @s rotated as @s run setblock ^-19 ^59 ^4 minecraft:iron_block
execute as @s at @s rotated as @s run setblock ^-19 ^60 ^-4 minecraft:iron_block
execute as @s at @s rotated as @s run setblock ^-19 ^60 ^4 minecraft:iron_block
execute as @s at @s rotated as @s run setblock ^-18 ^10 ^-4 minecraft:iron_block
execute as @s at @s rotated as @s run setblock ^-18 ^10 ^4 minecraft:iron_block
execute as @s at @s rotated as @s run setblock ^-18 ^11 ^-4 minecraft:iron_block
execute as @s at @s rotated as @s run setblock ^-18 ^11 ^4 minecraft:iron_block
execute as @s at @s rotated as @s run setblock ^-18 ^12 ^-4 minecraft:iron_block
execute as @s at @s rotated as @s run setblock ^-18 ^12 ^4 minecraft:iron_block
execute as @s at @s rotated as @s run setblock ^-18 ^13 ^-4 minecraft:iron_block
execute as @s at @s rotated as @s run setblock ^-18 ^13 ^4 minecraft:iron_block
execute as @s at @s rotated as @s run setblock ^-18 ^14 ^-4 minecraft:iron_block
execute as @s at @s rotated as @s run setblock ^-18 ^14 ^4 minecraft:iron_block
execute as @s at @s rotated as @s run setblock ^-18 ^56 ^-4 minecraft:iron_block
execute as @s at @s rotated as @s run setblock ^-18 ^56 ^4 minecraft:iron_block
execute as @s at @s rotated as @s run setblock ^-18 ^57 ^-4 minecraft:iron_block
execute as @s at @s rotated as @s run setblock ^-18 ^57 ^4 minecraft:iron_block
execute as @s at @s rotated as @s run setblock ^-18 ^58 ^-4 minecraft:iron_block
execute as @s at @s rotated as @s run setblock ^-18 ^58 ^4 minecraft:iron_block
execute as @s at @s rotated as @s run setblock ^-18 ^59 ^-4 minecraft:iron_block
execute as @s at @s rotated as @s run setblock ^-18 ^59 ^4 minecraft:iron_block
execute as @s at @s rotated as @s run setblock ^-18 ^60 ^-4 minecraft:iron_block
execute as @s at @s rotated as @s run setblock ^-18 ^60 ^4 minecraft:iron_block
execute as @s at @s rotated as @s run setblock ^-17 ^9 ^-4 minecraft:iron_block
execute as @s at @s rotated as @s run setblock ^-17 ^9 ^4 minecraft:iron_block
execute as @s at @s rotated as @s run setblock ^-17 ^10 ^-4 minecraft:iron_block
execute as @s at @s rotated as @s run setblock ^-17 ^10 ^4 minecraft:iron_block
execute as @s at @s rotated as @s run setblock ^-17 ^11 ^-4 minecraft:iron_block
execute as @s at @s rotated as @s run setblock ^-17 ^11 ^4 minecraft:iron_block
execute as @s at @s rotated as @s run setblock ^-17 ^12 ^-4 minecraft:iron_block
execute as @s at @s rotated as @s run setblock ^-17 ^12 ^4 minecraft:iron_block
execute as @s at @s rotated as @s run setblock ^-17 ^13 ^-4 minecraft:iron_block
execute as @s at @s rotated as @s run setblock ^-17 ^13 ^4 minecraft:iron_block
execute as @s at @s rotated as @s run setblock ^-17 ^57 ^-4 minecraft:iron_block
execute as @s at @s rotated as @s run setblock ^-17 ^57 ^4 minecraft:iron_block
execute as @s at @s rotated as @s run setblock ^-17 ^58 ^-4 minecraft:iron_block
execute as @s at @s rotated as @s run setblock ^-17 ^58 ^4 minecraft:iron_block
execute as @s at @s rotated as @s run setblock ^-17 ^59 ^-4 minecraft:iron_block
execute as @s at @s rotated as @s run setblock ^-17 ^59 ^4 minecraft:iron_block
execute as @s at @s rotated as @s run setblock ^-17 ^60 ^-4 minecraft:iron_block
execute as @s at @s rotated as @s run setblock ^-17 ^60 ^4 minecraft:iron_block
execute as @s at @s rotated as @s run setblock ^-17 ^61 ^-4 minecraft:iron_block
execute as @s at @s rotated as @s run setblock ^-17 ^61 ^4 minecraft:iron_block
execute as @s at @s rotated as @s run setblock ^-16 ^8 ^-4 minecraft:iron_block
execute as @s at @s rotated as @s run setblock ^-16 ^8 ^4 minecraft:iron_block
execute as @s at @s rotated as @s run setblock ^-16 ^9 ^-4 minecraft:iron_block
execute as @s at @s rotated as @s run setblock ^-16 ^9 ^4 minecraft:iron_block
execute as @s at @s rotated as @s run setblock ^-16 ^10 ^-4 minecraft:iron_block
execute as @s at @s rotated as @s run setblock ^-16 ^10 ^4 minecraft:iron_block
execute as @s at @s rotated as @s run setblock ^-16 ^11 ^-4 minecraft:iron_block
execute as @s at @s rotated as @s run setblock ^-16 ^11 ^4 minecraft:iron_block
execute as @s at @s rotated as @s run setblock ^-16 ^12 ^-4 minecraft:iron_block
execute as @s at @s rotated as @s run setblock ^-16 ^12 ^4 minecraft:iron_block
execute as @s at @s rotated as @s run setblock ^-16 ^58 ^-4 minecraft:iron_block
execute as @s at @s rotated as @s run setblock ^-16 ^58 ^4 minecraft:iron_block
execute as @s at @s rotated as @s run setblock ^-16 ^59 ^-4 minecraft:iron_block
execute as @s at @s rotated as @s run setblock ^-16 ^59 ^4 minecraft:iron_block
execute as @s at @s rotated as @s run setblock ^-16 ^60 ^-4 minecraft:iron_block
execute as @s at @s rotated as @s run setblock ^-16 ^60 ^4 minecraft:iron_block
execute as @s at @s rotated as @s run setblock ^-16 ^61 ^-4 minecraft:iron_block
execute as @s at @s rotated as @s run setblock ^-16 ^61 ^4 minecraft:iron_block
execute as @s at @s rotated as @s run setblock ^-16 ^62 ^-4 minecraft:iron_block
execute as @s at @s rotated as @s run setblock ^-16 ^62 ^4 minecraft:iron_block
execute as @s at @s rotated as @s run setblock ^-15 ^8 ^-4 minecraft:iron_block
execute as @s at @s rotated as @s run setblock ^-15 ^8 ^4 minecraft:iron_block
execute as @s at @s rotated as @s run setblock ^-15 ^9 ^-4 minecraft:iron_block
execute as @s at @s rotated as @s run setblock ^-15 ^9 ^4 minecraft:iron_block
execute as @s at @s rotated as @s run setblock ^-15 ^10 ^-4 minecraft:iron_block
execute as @s at @s rotated as @s run setblock ^-15 ^10 ^4 minecraft:iron_block
execute as @s at @s rotated as @s run setblock ^-15 ^11 ^-4 minecraft:iron_block
execute as @s at @s rotated as @s run setblock ^-15 ^11 ^4 minecraft:iron_block
execute as @s at @s rotated as @s run setblock ^-15 ^12 ^-4 minecraft:iron_block
execute as @s at @s rotated as @s run setblock ^-15 ^12 ^4 minecraft:iron_block
execute as @s at @s rotated as @s run setblock ^-15 ^58 ^-4 minecraft:iron_block
execute as @s at @s rotated as @s run setblock ^-15 ^58 ^4 minecraft:iron_block
execute as @s at @s rotated as @s run setblock ^-15 ^59 ^-4 minecraft:iron_block
execute as @s at @s rotated as @s run setblock ^-15 ^59 ^4 minecraft:iron_block
execute as @s at @s rotated as @s run setblock ^-15 ^60 ^-4 minecraft:iron_block
execute as @s at @s rotated as @s run setblock ^-15 ^60 ^4 minecraft:iron_block
execute as @s at @s rotated as @s run setblock ^-15 ^61 ^-4 minecraft:iron_block
execute as @s at @s rotated as @s run setblock ^-15 ^61 ^4 minecraft:iron_block
execute as @s at @s rotated as @s run setblock ^-15 ^62 ^-4 minecraft:iron_block
execute as @s at @s rotated as @s run setblock ^-15 ^62 ^4 minecraft:iron_block
execute as @s at @s rotated as @s run setblock ^-14 ^7 ^-4 minecraft:iron_block
execute as @s at @s rotated as @s run setblock ^-14 ^7 ^4 minecraft:iron_block
execute as @s at @s rotated as @s run setblock ^-14 ^8 ^-4 minecraft:iron_block
execute as @s at @s rotated as @s run setblock ^-14 ^8 ^4 minecraft:iron_block
execute as @s at @s rotated as @s run setblock ^-14 ^9 ^-4 minecraft:iron_block
execute as @s at @s rotated as @s run setblock ^-14 ^9 ^4 minecraft:iron_block
execute as @s at @s rotated as @s run setblock ^-14 ^10 ^-4 minecraft:iron_block
execute as @s at @s rotated as @s run setblock ^-14 ^10 ^4 minecraft:iron_block
execute as @s at @s rotated as @s run setblock ^-14 ^11 ^-4 minecraft:iron_block
execute as @s at @s rotated as @s run setblock ^-14 ^11 ^4 minecraft:iron_block
execute as @s at @s rotated as @s run setblock ^-14 ^59 ^-4 minecraft:iron_block
execute as @s at @s rotated as @s run setblock ^-14 ^59 ^4 minecraft:iron_block
execute as @s at @s rotated as @s run setblock ^-14 ^60 ^-4 minecraft:iron_block
execute as @s at @s rotated as @s run setblock ^-14 ^60 ^4 minecraft:iron_block
execute as @s at @s rotated as @s run setblock ^-14 ^61 ^-4 minecraft:iron_block
execute as @s at @s rotated as @s run setblock ^-14 ^61 ^4 minecraft:iron_block
execute as @s at @s rotated as @s run setblock ^-14 ^62 ^-4 minecraft:iron_block
execute as @s at @s rotated as @s run setblock ^-14 ^62 ^4 minecraft:iron_block
execute as @s at @s rotated as @s run setblock ^-14 ^63 ^-4 minecraft:iron_block
execute as @s at @s rotated as @s run setblock ^-14 ^63 ^4 minecraft:iron_block
execute as @s at @s rotated as @s run setblock ^-13 ^7 ^-4 minecraft:iron_block
execute as @s at @s rotated as @s run setblock ^-13 ^7 ^4 minecraft:iron_block
execute as @s at @s rotated as @s run setblock ^-13 ^8 ^-4 minecraft:iron_block
execute as @s at @s rotated as @s run setblock ^-13 ^8 ^4 minecraft:iron_block
execute as @s at @s rotated as @s run setblock ^-13 ^9 ^-4 minecraft:iron_block
execute as @s at @s rotated as @s run setblock ^-13 ^9 ^4 minecraft:iron_block
execute as @s at @s rotated as @s run setblock ^-13 ^10 ^-4 minecraft:iron_block
execute as @s at @s rotated as @s run setblock ^-13 ^10 ^4 minecraft:iron_block
execute as @s at @s rotated as @s run setblock ^-13 ^60 ^-4 minecraft:iron_block
execute as @s at @s rotated as @s run setblock ^-13 ^60 ^4 minecraft:iron_block
execute as @s at @s rotated as @s run setblock ^-13 ^61 ^-4 minecraft:iron_block
execute as @s at @s rotated as @s run setblock ^-13 ^61 ^4 minecraft:iron_block
execute as @s at @s rotated as @s run setblock ^-13 ^62 ^-4 minecraft:iron_block
execute as @s at @s rotated as @s run setblock ^-13 ^62 ^4 minecraft:iron_block
execute as @s at @s rotated as @s run setblock ^-13 ^63 ^-4 minecraft:iron_block
execute as @s at @s rotated as @s run setblock ^-13 ^63 ^4 minecraft:iron_block
execute as @s at @s rotated as @s run setblock ^-12 ^6 ^-4 minecraft:iron_block
execute as @s at @s rotated as @s run setblock ^-12 ^6 ^4 minecraft:iron_block
execute as @s at @s rotated as @s run setblock ^-12 ^7 ^-4 minecraft:iron_block
execute as @s at @s rotated as @s run setblock ^-12 ^7 ^4 minecraft:iron_block
execute as @s at @s rotated as @s run setblock ^-12 ^8 ^-4 minecraft:iron_block
execute as @s at @s rotated as @s run setblock ^-12 ^8 ^4 minecraft:iron_block
execute as @s at @s rotated as @s run setblock ^-12 ^9 ^-4 minecraft:iron_block
execute as @s at @s rotated as @s run setblock ^-12 ^9 ^4 minecraft:iron_block
execute as @s at @s rotated as @s run setblock ^-12 ^10 ^-4 minecraft:iron_block
execute as @s at @s rotated as @s run setblock ^-12 ^10 ^4 minecraft:iron_block
execute as @s at @s rotated as @s run setblock ^-12 ^60 ^-4 minecraft:iron_block
execute as @s at @s rotated as @s run setblock ^-12 ^60 ^4 minecraft:iron_block
execute as @s at @s rotated as @s run setblock ^-12 ^61 ^-4 minecraft:iron_block
execute as @s at @s rotated as @s run setblock ^-12 ^61 ^4 minecraft:iron_block
execute as @s at @s rotated as @s run setblock ^-12 ^62 ^-4 minecraft:iron_block
execute as @s at @s rotated as @s run setblock ^-12 ^62 ^4 minecraft:iron_block
execute as @s at @s rotated as @s run setblock ^-12 ^63 ^-4 minecraft:iron_block
execute as @s at @s rotated as @s run setblock ^-12 ^63 ^4 minecraft:iron_block
execute as @s at @s rotated as @s run setblock ^-12 ^64 ^-4 minecraft:iron_block
execute as @s at @s rotated as @s run setblock ^-12 ^64 ^4 minecraft:iron_block
execute as @s at @s rotated as @s run setblock ^-11 ^6 ^-4 minecraft:iron_block
execute as @s at @s rotated as @s run setblock ^-11 ^6 ^4 minecraft:iron_block
execute as @s at @s rotated as @s run setblock ^-11 ^7 ^-4 minecraft:iron_block
execute as @s at @s rotated as @s run setblock ^-11 ^7 ^4 minecraft:iron_block
execute as @s at @s rotated as @s run setblock ^-11 ^8 ^-4 minecraft:iron_block
execute as @s at @s rotated as @s run setblock ^-11 ^8 ^4 minecraft:iron_block
execute as @s at @s rotated as @s run setblock ^-11 ^9 ^-4 minecraft:iron_block
execute as @s at @s rotated as @s run setblock ^-11 ^9 ^4 minecraft:iron_block
execute as @s at @s rotated as @s run setblock ^-11 ^61 ^-4 minecraft:iron_block
execute as @s at @s rotated as @s run setblock ^-11 ^61 ^4 minecraft:iron_block
execute as @s at @s rotated as @s run setblock ^-11 ^62 ^-4 minecraft:iron_block
execute as @s at @s rotated as @s run setblock ^-11 ^62 ^4 minecraft:iron_block
execute as @s at @s rotated as @s run setblock ^-11 ^63 ^-4 minecraft:iron_block
execute as @s at @s rotated as @s run setblock ^-11 ^63 ^4 minecraft:iron_block
execute as @s at @s rotated as @s run setblock ^-11 ^64 ^-4 minecraft:iron_block
execute as @s at @s rotated as @s run setblock ^-11 ^64 ^4 minecraft:iron_block
execute as @s at @s rotated as @s run setblock ^-10 ^6 ^-4 minecraft:iron_block
execute as @s at @s rotated as @s run setblock ^-10 ^6 ^4 minecraft:iron_block
execute as @s at @s rotated as @s run setblock ^-10 ^7 ^-4 minecraft:iron_block
execute as @s at @s rotated as @s run setblock ^-10 ^7 ^4 minecraft:iron_block
execute as @s at @s rotated as @s run setblock ^-10 ^8 ^-4 minecraft:iron_block
execute as @s at @s rotated as @s run setblock ^-10 ^8 ^4 minecraft:iron_block
execute as @s at @s rotated as @s run setblock ^-10 ^9 ^-4 minecraft:iron_block
execute as @s at @s rotated as @s run setblock ^-10 ^9 ^4 minecraft:iron_block
execute as @s at @s rotated as @s run setblock ^-10 ^61 ^-4 minecraft:iron_block
execute as @s at @s rotated as @s run setblock ^-10 ^61 ^4 minecraft:iron_block
execute as @s at @s rotated as @s run setblock ^-10 ^62 ^-4 minecraft:iron_block
execute as @s at @s rotated as @s run setblock ^-10 ^62 ^4 minecraft:iron_block
execute as @s at @s rotated as @s run setblock ^-10 ^63 ^-4 minecraft:iron_block
execute as @s at @s rotated as @s run setblock ^-10 ^63 ^4 minecraft:iron_block
execute as @s at @s rotated as @s run setblock ^-10 ^64 ^-4 minecraft:iron_block
execute as @s at @s rotated as @s run setblock ^-10 ^64 ^4 minecraft:iron_block
execute as @s at @s rotated as @s run setblock ^-9 ^5 ^-4 minecraft:iron_block
execute as @s at @s rotated as @s run setblock ^-9 ^5 ^4 minecraft:iron_block
execute as @s at @s rotated as @s run setblock ^-9 ^6 ^-4 minecraft:iron_block
execute as @s at @s rotated as @s run setblock ^-9 ^6 ^4 minecraft:iron_block
execute as @s at @s rotated as @s run setblock ^-9 ^7 ^-4 minecraft:iron_block
execute as @s at @s rotated as @s run setblock ^-9 ^7 ^4 minecraft:iron_block
execute as @s at @s rotated as @s run setblock ^-9 ^8 ^-4 minecraft:iron_block
execute as @s at @s rotated as @s run setblock ^-9 ^8 ^4 minecraft:iron_block
execute as @s at @s rotated as @s run setblock ^-9 ^9 ^-4 minecraft:iron_block
execute as @s at @s rotated as @s run setblock ^-9 ^9 ^4 minecraft:iron_block
execute as @s at @s rotated as @s run setblock ^-9 ^61 ^-4 minecraft:iron_block
execute as @s at @s rotated as @s run setblock ^-9 ^61 ^4 minecraft:iron_block
execute as @s at @s rotated as @s run setblock ^-9 ^62 ^-4 minecraft:iron_block
execute as @s at @s rotated as @s run setblock ^-9 ^62 ^4 minecraft:iron_block
execute as @s at @s rotated as @s run setblock ^-9 ^63 ^-4 minecraft:iron_block
execute as @s at @s rotated as @s run setblock ^-9 ^63 ^4 minecraft:iron_block
execute as @s at @s rotated as @s run setblock ^-9 ^64 ^-4 minecraft:iron_block
execute as @s at @s rotated as @s run setblock ^-9 ^64 ^4 minecraft:iron_block
execute as @s at @s rotated as @s run setblock ^-9 ^65 ^-4 minecraft:iron_block
execute as @s at @s rotated as @s run setblock ^-9 ^65 ^4 minecraft:iron_block
execute as @s at @s rotated as @s run setblock ^-8 ^5 ^-4 minecraft:iron_block
execute as @s at @s rotated as @s run setblock ^-8 ^5 ^4 minecraft:iron_block
execute as @s at @s rotated as @s run setblock ^-8 ^6 ^-4 minecraft:iron_block
execute as @s at @s rotated as @s run setblock ^-8 ^6 ^4 minecraft:iron_block
execute as @s at @s rotated as @s run setblock ^-8 ^7 ^-4 minecraft:iron_block
execute as @s at @s rotated as @s run setblock ^-8 ^7 ^4 minecraft:iron_block
execute as @s at @s rotated as @s run setblock ^-8 ^8 ^-4 minecraft:iron_block
execute as @s at @s rotated as @s run setblock ^-8 ^8 ^4 minecraft:iron_block
execute as @s at @s rotated as @s run setblock ^-8 ^62 ^-4 minecraft:iron_block
execute as @s at @s rotated as @s run setblock ^-8 ^62 ^4 minecraft:iron_block
execute as @s at @s rotated as @s run setblock ^-8 ^63 ^-4 minecraft:iron_block
execute as @s at @s rotated as @s run setblock ^-8 ^63 ^4 minecraft:iron_block
execute as @s at @s rotated as @s run setblock ^-8 ^64 ^-4 minecraft:iron_block
execute as @s at @s rotated as @s run setblock ^-8 ^64 ^4 minecraft:iron_block
execute as @s at @s rotated as @s run setblock ^-8 ^65 ^-4 minecraft:iron_block
execute as @s at @s rotated as @s run setblock ^-8 ^65 ^4 minecraft:iron_block
execute as @s at @s rotated as @s run setblock ^-7 ^5 ^-4 minecraft:iron_block
execute as @s at @s rotated as @s run setblock ^-7 ^5 ^4 minecraft:iron_block
execute as @s at @s rotated as @s run setblock ^-7 ^6 ^-4 minecraft:iron_block
execute as @s at @s rotated as @s run setblock ^-7 ^6 ^4 minecraft:iron_block
execute as @s at @s rotated as @s run setblock ^-7 ^7 ^-4 minecraft:iron_block
execute as @s at @s rotated as @s run setblock ^-7 ^7 ^4 minecraft:iron_block
execute as @s at @s rotated as @s run setblock ^-7 ^8 ^-4 minecraft:iron_block
execute as @s at @s rotated as @s run setblock ^-7 ^8 ^4 minecraft:iron_block
execute as @s at @s rotated as @s run setblock ^-7 ^62 ^-4 minecraft:iron_block
execute as @s at @s rotated as @s run setblock ^-7 ^62 ^4 minecraft:iron_block
execute as @s at @s rotated as @s run setblock ^-7 ^63 ^-4 minecraft:iron_block
execute as @s at @s rotated as @s run setblock ^-7 ^63 ^4 minecraft:iron_block
execute as @s at @s rotated as @s run setblock ^-7 ^64 ^-4 minecraft:iron_block
execute as @s at @s rotated as @s run setblock ^-7 ^64 ^4 minecraft:iron_block
execute as @s at @s rotated as @s run setblock ^-7 ^65 ^-4 minecraft:iron_block
execute as @s at @s rotated as @s run setblock ^-7 ^65 ^4 minecraft:iron_block
execute as @s at @s rotated as @s run setblock ^-6 ^5 ^-4 minecraft:iron_block
execute as @s at @s rotated as @s run setblock ^-6 ^5 ^4 minecraft:iron_block
execute as @s at @s rotated as @s run setblock ^-6 ^6 ^-4 minecraft:iron_block
execute as @s at @s rotated as @s run setblock ^-6 ^6 ^4 minecraft:iron_block
execute as @s at @s rotated as @s run setblock ^-6 ^7 ^-4 minecraft:iron_block
execute as @s at @s rotated as @s run setblock ^-6 ^7 ^4 minecraft:iron_block
execute as @s at @s rotated as @s run setblock ^-6 ^8 ^-4 minecraft:iron_block
execute as @s at @s rotated as @s run setblock ^-6 ^8 ^4 minecraft:iron_block
execute as @s at @s rotated as @s run setblock ^-6 ^62 ^-4 minecraft:iron_block
execute as @s at @s rotated as @s run setblock ^-6 ^62 ^4 minecraft:iron_block
execute as @s at @s rotated as @s run setblock ^-6 ^63 ^-4 minecraft:iron_block
execute as @s at @s rotated as @s run setblock ^-6 ^63 ^4 minecraft:iron_block
execute as @s at @s rotated as @s run setblock ^-6 ^64 ^-4 minecraft:iron_block
execute as @s at @s rotated as @s run setblock ^-6 ^64 ^4 minecraft:iron_block
execute as @s at @s rotated as @s run setblock ^-6 ^65 ^-4 minecraft:iron_block
execute as @s at @s rotated as @s run setblock ^-6 ^65 ^4 minecraft:iron_block
execute as @s at @s rotated as @s run setblock ^-5 ^4 ^-4 minecraft:iron_block
execute as @s at @s rotated as @s run setblock ^-5 ^4 ^4 minecraft:iron_block
execute as @s at @s rotated as @s run setblock ^-5 ^5 ^-4 minecraft:iron_block
execute as @s at @s rotated as @s run setblock ^-5 ^5 ^4 minecraft:iron_block
execute as @s at @s rotated as @s run setblock ^-5 ^6 ^-4 minecraft:iron_block
execute as @s at @s rotated as @s run setblock ^-5 ^6 ^4 minecraft:iron_block
execute as @s at @s rotated as @s run setblock ^-5 ^7 ^-4 minecraft:iron_block
execute as @s at @s rotated as @s run setblock ^-5 ^7 ^4 minecraft:iron_block
execute as @s at @s rotated as @s run setblock ^-5 ^8 ^-4 minecraft:iron_block
execute as @s at @s rotated as @s run setblock ^-5 ^8 ^4 minecraft:iron_block
execute as @s at @s rotated as @s run setblock ^-5 ^62 ^-4 minecraft:iron_block
execute as @s at @s rotated as @s run setblock ^-5 ^62 ^4 minecraft:iron_block
execute as @s at @s rotated as @s run setblock ^-5 ^63 ^-4 minecraft:iron_block
execute as @s at @s rotated as @s run setblock ^-5 ^63 ^4 minecraft:iron_block
execute as @s at @s rotated as @s run setblock ^-5 ^64 ^-4 minecraft:iron_block
execute as @s at @s rotated as @s run setblock ^-5 ^64 ^4 minecraft:iron_block
execute as @s at @s rotated as @s run setblock ^-5 ^65 ^-4 minecraft:iron_block
execute as @s at @s rotated as @s run setblock ^-5 ^65 ^4 minecraft:iron_block
execute as @s at @s rotated as @s run setblock ^-5 ^66 ^-4 minecraft:iron_block
execute as @s at @s rotated as @s run setblock ^-5 ^66 ^4 minecraft:iron_block
execute as @s at @s rotated as @s run setblock ^-4 ^4 ^-4 minecraft:iron_block
execute as @s at @s rotated as @s run setblock ^-4 ^4 ^4 minecraft:iron_block
execute as @s at @s rotated as @s run setblock ^-4 ^5 ^-4 minecraft:iron_block
execute as @s at @s rotated as @s run setblock ^-4 ^5 ^4 minecraft:iron_block
execute as @s at @s rotated as @s run setblock ^-4 ^6 ^-4 minecraft:iron_block
execute as @s at @s rotated as @s run setblock ^-4 ^6 ^4 minecraft:iron_block
execute as @s at @s rotated as @s run setblock ^-4 ^7 ^-4 minecraft:iron_block
execute as @s at @s rotated as @s run setblock ^-4 ^7 ^4 minecraft:iron_block
execute as @s at @s rotated as @s run setblock ^-4 ^63 ^-4 minecraft:iron_block
execute as @s at @s rotated as @s run setblock ^-4 ^63 ^4 minecraft:iron_block
execute as @s at @s rotated as @s run setblock ^-4 ^64 ^-4 minecraft:iron_block
execute as @s at @s rotated as @s run setblock ^-4 ^64 ^4 minecraft:iron_block
execute as @s at @s rotated as @s run setblock ^-4 ^65 ^-4 minecraft:iron_block
execute as @s at @s rotated as @s run setblock ^-4 ^65 ^4 minecraft:iron_block
execute as @s at @s rotated as @s run setblock ^-4 ^66 ^-4 minecraft:iron_block
execute as @s at @s rotated as @s run setblock ^-4 ^66 ^4 minecraft:iron_block
execute as @s at @s rotated as @s run setblock ^-3 ^4 ^-4 minecraft:iron_block
execute as @s at @s rotated as @s run setblock ^-3 ^4 ^4 minecraft:iron_block
execute as @s at @s rotated as @s run setblock ^-3 ^5 ^-4 minecraft:iron_block
execute as @s at @s rotated as @s run setblock ^-3 ^5 ^4 minecraft:iron_block
execute as @s at @s rotated as @s run setblock ^-3 ^6 ^-4 minecraft:iron_block
execute as @s at @s rotated as @s run setblock ^-3 ^6 ^4 minecraft:iron_block
execute as @s at @s rotated as @s run setblock ^-3 ^7 ^-4 minecraft:iron_block
execute as @s at @s rotated as @s run setblock ^-3 ^7 ^4 minecraft:iron_block
execute as @s at @s rotated as @s run setblock ^-3 ^63 ^-4 minecraft:iron_block
execute as @s at @s rotated as @s run setblock ^-3 ^63 ^4 minecraft:iron_block
execute as @s at @s rotated as @s run setblock ^-3 ^64 ^-4 minecraft:iron_block
execute as @s at @s rotated as @s run setblock ^-3 ^64 ^4 minecraft:iron_block
execute as @s at @s rotated as @s run setblock ^-3 ^65 ^-4 minecraft:iron_block
execute as @s at @s rotated as @s run setblock ^-3 ^65 ^4 minecraft:iron_block
execute as @s at @s rotated as @s run setblock ^-3 ^66 ^-4 minecraft:iron_block
execute as @s at @s rotated as @s run setblock ^-3 ^66 ^4 minecraft:iron_block
execute as @s at @s rotated as @s run setblock ^-2 ^4 ^-4 minecraft:iron_block
execute as @s at @s rotated as @s run setblock ^-2 ^4 ^4 minecraft:iron_block
execute as @s at @s rotated as @s run setblock ^-2 ^5 ^-4 minecraft:iron_block
execute as @s at @s rotated as @s run setblock ^-2 ^5 ^4 minecraft:iron_block
execute as @s at @s rotated as @s run setblock ^-2 ^6 ^-4 minecraft:iron_block
execute as @s at @s rotated as @s run setblock ^-2 ^6 ^4 minecraft:iron_block
execute as @s at @s rotated as @s run setblock ^-2 ^7 ^-4 minecraft:iron_block
execute as @s at @s rotated as @s run setblock ^-2 ^7 ^4 minecraft:iron_block
execute as @s at @s rotated as @s run setblock ^-2 ^63 ^-4 minecraft:iron_block
execute as @s at @s rotated as @s run setblock ^-2 ^63 ^4 minecraft:iron_block
execute as @s at @s rotated as @s run setblock ^-2 ^64 ^-4 minecraft:iron_block
execute as @s at @s rotated as @s run setblock ^-2 ^64 ^4 minecraft:iron_block
execute as @s at @s rotated as @s run setblock ^-2 ^65 ^-4 minecraft:iron_block
execute as @s at @s rotated as @s run setblock ^-2 ^65 ^4 minecraft:iron_block
execute as @s at @s rotated as @s run setblock ^-2 ^66 ^-4 minecraft:iron_block
execute as @s at @s rotated as @s run setblock ^-2 ^66 ^4 minecraft:iron_block
execute as @s at @s rotated as @s run setblock ^-1 ^4 ^-4 minecraft:iron_block
execute as @s at @s rotated as @s run setblock ^-1 ^4 ^4 minecraft:iron_block
execute as @s at @s rotated as @s run setblock ^-1 ^5 ^-4 minecraft:iron_block
execute as @s at @s rotated as @s run setblock ^-1 ^5 ^4 minecraft:iron_block
execute as @s at @s rotated as @s run setblock ^-1 ^6 ^-4 minecraft:iron_block
execute as @s at @s rotated as @s run setblock ^-1 ^6 ^4 minecraft:iron_block
execute as @s at @s rotated as @s run setblock ^-1 ^7 ^-4 minecraft:iron_block
execute as @s at @s rotated as @s run setblock ^-1 ^7 ^4 minecraft:iron_block
execute as @s at @s rotated as @s run setblock ^-1 ^63 ^-4 minecraft:iron_block
execute as @s at @s rotated as @s run setblock ^-1 ^63 ^4 minecraft:iron_block
execute as @s at @s rotated as @s run setblock ^-1 ^64 ^-4 minecraft:iron_block
execute as @s at @s rotated as @s run setblock ^-1 ^64 ^4 minecraft:iron_block
execute as @s at @s rotated as @s run setblock ^-1 ^65 ^-4 minecraft:iron_block
execute as @s at @s rotated as @s run setblock ^-1 ^65 ^4 minecraft:iron_block
execute as @s at @s rotated as @s run setblock ^-1 ^66 ^-4 minecraft:iron_block
execute as @s at @s rotated as @s run setblock ^-1 ^66 ^4 minecraft:iron_block
execute as @s at @s rotated as @s run setblock ^ ^4 ^-4 minecraft:iron_block
execute as @s at @s rotated as @s run setblock ^ ^4 ^4 minecraft:iron_block
execute as @s at @s rotated as @s run setblock ^ ^5 ^-4 minecraft:iron_block
execute as @s at @s rotated as @s run setblock ^ ^5 ^4 minecraft:iron_block
execute as @s at @s rotated as @s run setblock ^ ^6 ^-4 minecraft:iron_block
execute as @s at @s rotated as @s run setblock ^ ^6 ^4 minecraft:iron_block
execute as @s at @s rotated as @s run setblock ^ ^7 ^-4 minecraft:iron_block
execute as @s at @s rotated as @s run setblock ^ ^7 ^4 minecraft:iron_block
execute as @s at @s rotated as @s run setblock ^ ^63 ^-4 minecraft:iron_block
execute as @s at @s rotated as @s run setblock ^ ^63 ^4 minecraft:iron_block
execute as @s at @s rotated as @s run setblock ^ ^64 ^-4 minecraft:iron_block
execute as @s at @s rotated as @s run setblock ^ ^64 ^4 minecraft:iron_block
execute as @s at @s rotated as @s run setblock ^ ^65 ^-4 minecraft:iron_block
execute as @s at @s rotated as @s run setblock ^ ^65 ^4 minecraft:iron_block
execute as @s at @s rotated as @s run setblock ^ ^66 ^-4 minecraft:iron_block
execute as @s at @s rotated as @s run setblock ^ ^66 ^4 minecraft:iron_block
execute as @s at @s rotated as @s run setblock ^1 ^4 ^-4 minecraft:iron_block
execute as @s at @s rotated as @s run setblock ^1 ^4 ^4 minecraft:iron_block
execute as @s at @s rotated as @s run setblock ^1 ^5 ^-4 minecraft:iron_block
execute as @s at @s rotated as @s run setblock ^1 ^5 ^4 minecraft:iron_block
execute as @s at @s rotated as @s run setblock ^1 ^6 ^-4 minecraft:iron_block
execute as @s at @s rotated as @s run setblock ^1 ^6 ^4 minecraft:iron_block
execute as @s at @s rotated as @s run setblock ^1 ^7 ^-4 minecraft:iron_block
execute as @s at @s rotated as @s run setblock ^1 ^7 ^4 minecraft:iron_block
execute as @s at @s rotated as @s run setblock ^1 ^63 ^-4 minecraft:iron_block
execute as @s at @s rotated as @s run setblock ^1 ^63 ^4 minecraft:iron_block
execute as @s at @s rotated as @s run setblock ^1 ^64 ^-4 minecraft:iron_block
execute as @s at @s rotated as @s run setblock ^1 ^64 ^4 minecraft:iron_block
execute as @s at @s rotated as @s run setblock ^1 ^65 ^-4 minecraft:iron_block
execute as @s at @s rotated as @s run setblock ^1 ^65 ^4 minecraft:iron_block
execute as @s at @s rotated as @s run setblock ^1 ^66 ^-4 minecraft:iron_block
execute as @s at @s rotated as @s run setblock ^1 ^66 ^4 minecraft:iron_block
execute as @s at @s rotated as @s run setblock ^2 ^4 ^-4 minecraft:iron_block
execute as @s at @s rotated as @s run setblock ^2 ^4 ^4 minecraft:iron_block
execute as @s at @s rotated as @s run setblock ^2 ^5 ^-4 minecraft:iron_block
execute as @s at @s rotated as @s run setblock ^2 ^5 ^4 minecraft:iron_block
execute as @s at @s rotated as @s run setblock ^2 ^6 ^-4 minecraft:iron_block
execute as @s at @s rotated as @s run setblock ^2 ^6 ^4 minecraft:iron_block
execute as @s at @s rotated as @s run setblock ^2 ^7 ^-4 minecraft:iron_block
execute as @s at @s rotated as @s run setblock ^2 ^7 ^4 minecraft:iron_block
execute as @s at @s rotated as @s run setblock ^2 ^63 ^-4 minecraft:iron_block
execute as @s at @s rotated as @s run setblock ^2 ^63 ^4 minecraft:iron_block
execute as @s at @s rotated as @s run setblock ^2 ^64 ^-4 minecraft:iron_block
execute as @s at @s rotated as @s run setblock ^2 ^64 ^4 minecraft:iron_block
execute as @s at @s rotated as @s run setblock ^2 ^65 ^-4 minecraft:iron_block
execute as @s at @s rotated as @s run setblock ^2 ^65 ^4 minecraft:iron_block
execute as @s at @s rotated as @s run setblock ^2 ^66 ^-4 minecraft:iron_block
execute as @s at @s rotated as @s run setblock ^2 ^66 ^4 minecraft:iron_block
execute as @s at @s rotated as @s run setblock ^3 ^4 ^-4 minecraft:iron_block
execute as @s at @s rotated as @s run setblock ^3 ^4 ^4 minecraft:iron_block
execute as @s at @s rotated as @s run setblock ^3 ^5 ^-4 minecraft:iron_block
execute as @s at @s rotated as @s run setblock ^3 ^5 ^4 minecraft:iron_block
execute as @s at @s rotated as @s run setblock ^3 ^6 ^-4 minecraft:iron_block
execute as @s at @s rotated as @s run setblock ^3 ^6 ^4 minecraft:iron_block
execute as @s at @s rotated as @s run setblock ^3 ^7 ^-4 minecraft:iron_block
execute as @s at @s rotated as @s run setblock ^3 ^7 ^4 minecraft:iron_block
execute as @s at @s rotated as @s run setblock ^3 ^63 ^-4 minecraft:iron_block
execute as @s at @s rotated as @s run setblock ^3 ^63 ^4 minecraft:iron_block
execute as @s at @s rotated as @s run setblock ^3 ^64 ^-4 minecraft:iron_block
execute as @s at @s rotated as @s run setblock ^3 ^64 ^4 minecraft:iron_block
execute as @s at @s rotated as @s run setblock ^3 ^65 ^-4 minecraft:iron_block
execute as @s at @s rotated as @s run setblock ^3 ^65 ^4 minecraft:iron_block
execute as @s at @s rotated as @s run setblock ^3 ^66 ^-4 minecraft:iron_block
execute as @s at @s rotated as @s run setblock ^3 ^66 ^4 minecraft:iron_block
execute as @s at @s rotated as @s run setblock ^4 ^4 ^-4 minecraft:iron_block
execute as @s at @s rotated as @s run setblock ^4 ^4 ^4 minecraft:iron_block
execute as @s at @s rotated as @s run setblock ^4 ^5 ^-4 minecraft:iron_block
execute as @s at @s rotated as @s run setblock ^4 ^5 ^4 minecraft:iron_block
execute as @s at @s rotated as @s run setblock ^4 ^6 ^-4 minecraft:iron_block
execute as @s at @s rotated as @s run setblock ^4 ^6 ^4 minecraft:iron_block
execute as @s at @s rotated as @s run setblock ^4 ^7 ^-4 minecraft:iron_block
execute as @s at @s rotated as @s run setblock ^4 ^7 ^4 minecraft:iron_block
execute as @s at @s rotated as @s run setblock ^4 ^63 ^-4 minecraft:iron_block
execute as @s at @s rotated as @s run setblock ^4 ^63 ^4 minecraft:iron_block
execute as @s at @s rotated as @s run setblock ^4 ^64 ^-4 minecraft:iron_block
execute as @s at @s rotated as @s run setblock ^4 ^64 ^4 minecraft:iron_block
execute as @s at @s rotated as @s run setblock ^4 ^65 ^-4 minecraft:iron_block
execute as @s at @s rotated as @s run setblock ^4 ^65 ^4 minecraft:iron_block
execute as @s at @s rotated as @s run setblock ^4 ^66 ^-4 minecraft:iron_block
execute as @s at @s rotated as @s run setblock ^4 ^66 ^4 minecraft:iron_block
execute as @s at @s rotated as @s run setblock ^5 ^4 ^-4 minecraft:iron_block
execute as @s at @s rotated as @s run setblock ^5 ^4 ^4 minecraft:iron_block
execute as @s at @s rotated as @s run setblock ^5 ^5 ^-4 minecraft:iron_block
execute as @s at @s rotated as @s run setblock ^5 ^5 ^4 minecraft:iron_block
execute as @s at @s rotated as @s run setblock ^5 ^6 ^-4 minecraft:iron_block
execute as @s at @s rotated as @s run setblock ^5 ^6 ^4 minecraft:iron_block
execute as @s at @s rotated as @s run setblock ^5 ^7 ^-4 minecraft:iron_block
execute as @s at @s rotated as @s run setblock ^5 ^7 ^4 minecraft:iron_block
execute as @s at @s rotated as @s run setblock ^5 ^8 ^-4 minecraft:iron_block
execute as @s at @s rotated as @s run setblock ^5 ^8 ^4 minecraft:iron_block
execute as @s at @s rotated as @s run setblock ^5 ^62 ^-4 minecraft:iron_block
execute as @s at @s rotated as @s run setblock ^5 ^62 ^4 minecraft:iron_block
execute as @s at @s rotated as @s run setblock ^5 ^63 ^-4 minecraft:iron_block
execute as @s at @s rotated as @s run setblock ^5 ^63 ^4 minecraft:iron_block
execute as @s at @s rotated as @s run setblock ^5 ^64 ^-4 minecraft:iron_block
execute as @s at @s rotated as @s run setblock ^5 ^64 ^4 minecraft:iron_block
execute as @s at @s rotated as @s run setblock ^5 ^65 ^-4 minecraft:iron_block
execute as @s at @s rotated as @s run setblock ^5 ^65 ^4 minecraft:iron_block
execute as @s at @s rotated as @s run setblock ^5 ^66 ^-4 minecraft:iron_block
execute as @s at @s rotated as @s run setblock ^5 ^66 ^4 minecraft:iron_block
execute as @s at @s rotated as @s run setblock ^6 ^5 ^-4 minecraft:iron_block
execute as @s at @s rotated as @s run setblock ^6 ^5 ^4 minecraft:iron_block
execute as @s at @s rotated as @s run setblock ^6 ^6 ^-4 minecraft:iron_block
execute as @s at @s rotated as @s run setblock ^6 ^6 ^4 minecraft:iron_block
execute as @s at @s rotated as @s run setblock ^6 ^7 ^-4 minecraft:iron_block
execute as @s at @s rotated as @s run setblock ^6 ^7 ^4 minecraft:iron_block
execute as @s at @s rotated as @s run setblock ^6 ^8 ^-4 minecraft:iron_block
execute as @s at @s rotated as @s run setblock ^6 ^8 ^4 minecraft:iron_block
execute as @s at @s rotated as @s run setblock ^6 ^62 ^-4 minecraft:iron_block
execute as @s at @s rotated as @s run setblock ^6 ^62 ^4 minecraft:iron_block
execute as @s at @s rotated as @s run setblock ^6 ^63 ^-4 minecraft:iron_block
execute as @s at @s rotated as @s run setblock ^6 ^63 ^4 minecraft:iron_block
execute as @s at @s rotated as @s run setblock ^6 ^64 ^-4 minecraft:iron_block
execute as @s at @s rotated as @s run setblock ^6 ^64 ^4 minecraft:iron_block
execute as @s at @s rotated as @s run setblock ^6 ^65 ^-4 minecraft:iron_block
execute as @s at @s rotated as @s run setblock ^6 ^65 ^4 minecraft:iron_block
execute as @s at @s rotated as @s run setblock ^7 ^5 ^-4 minecraft:iron_block
execute as @s at @s rotated as @s run setblock ^7 ^5 ^4 minecraft:iron_block
execute as @s at @s rotated as @s run setblock ^7 ^6 ^-4 minecraft:iron_block
execute as @s at @s rotated as @s run setblock ^7 ^6 ^4 minecraft:iron_block
execute as @s at @s rotated as @s run setblock ^7 ^7 ^-4 minecraft:iron_block
execute as @s at @s rotated as @s run setblock ^7 ^7 ^4 minecraft:iron_block
execute as @s at @s rotated as @s run setblock ^7 ^8 ^-4 minecraft:iron_block
execute as @s at @s rotated as @s run setblock ^7 ^8 ^4 minecraft:iron_block
execute as @s at @s rotated as @s run setblock ^7 ^62 ^-4 minecraft:iron_block
execute as @s at @s rotated as @s run setblock ^7 ^62 ^4 minecraft:iron_block
execute as @s at @s rotated as @s run setblock ^7 ^63 ^-4 minecraft:iron_block
execute as @s at @s rotated as @s run setblock ^7 ^63 ^4 minecraft:iron_block
execute as @s at @s rotated as @s run setblock ^7 ^64 ^-4 minecraft:iron_block
execute as @s at @s rotated as @s run setblock ^7 ^64 ^4 minecraft:iron_block
execute as @s at @s rotated as @s run setblock ^7 ^65 ^-4 minecraft:iron_block
execute as @s at @s rotated as @s run setblock ^7 ^65 ^4 minecraft:iron_block
execute as @s at @s rotated as @s run setblock ^8 ^5 ^-4 minecraft:iron_block
execute as @s at @s rotated as @s run setblock ^8 ^5 ^4 minecraft:iron_block
execute as @s at @s rotated as @s run setblock ^8 ^6 ^-4 minecraft:iron_block
execute as @s at @s rotated as @s run setblock ^8 ^6 ^4 minecraft:iron_block
execute as @s at @s rotated as @s run setblock ^8 ^7 ^-4 minecraft:iron_block
execute as @s at @s rotated as @s run setblock ^8 ^7 ^4 minecraft:iron_block
execute as @s at @s rotated as @s run setblock ^8 ^8 ^-4 minecraft:iron_block
execute as @s at @s rotated as @s run setblock ^8 ^8 ^4 minecraft:iron_block
execute as @s at @s rotated as @s run setblock ^8 ^62 ^-4 minecraft:iron_block
execute as @s at @s rotated as @s run setblock ^8 ^62 ^4 minecraft:iron_block
execute as @s at @s rotated as @s run setblock ^8 ^63 ^-4 minecraft:iron_block
execute as @s at @s rotated as @s run setblock ^8 ^63 ^4 minecraft:iron_block
execute as @s at @s rotated as @s run setblock ^8 ^64 ^-4 minecraft:iron_block
execute as @s at @s rotated as @s run setblock ^8 ^64 ^4 minecraft:iron_block
execute as @s at @s rotated as @s run setblock ^8 ^65 ^-4 minecraft:iron_block
execute as @s at @s rotated as @s run setblock ^8 ^65 ^4 minecraft:iron_block
execute as @s at @s rotated as @s run setblock ^9 ^5 ^-4 minecraft:iron_block
execute as @s at @s rotated as @s run setblock ^9 ^5 ^4 minecraft:iron_block
execute as @s at @s rotated as @s run setblock ^9 ^6 ^-4 minecraft:iron_block
execute as @s at @s rotated as @s run setblock ^9 ^6 ^4 minecraft:iron_block
execute as @s at @s rotated as @s run setblock ^9 ^7 ^-4 minecraft:iron_block
execute as @s at @s rotated as @s run setblock ^9 ^7 ^4 minecraft:iron_block
execute as @s at @s rotated as @s run setblock ^9 ^8 ^-4 minecraft:iron_block
execute as @s at @s rotated as @s run setblock ^9 ^8 ^4 minecraft:iron_block
execute as @s at @s rotated as @s run setblock ^9 ^9 ^-4 minecraft:iron_block
execute as @s at @s rotated as @s run setblock ^9 ^9 ^4 minecraft:iron_block
execute as @s at @s rotated as @s run setblock ^9 ^61 ^-4 minecraft:iron_block
execute as @s at @s rotated as @s run setblock ^9 ^61 ^4 minecraft:iron_block
execute as @s at @s rotated as @s run setblock ^9 ^62 ^-4 minecraft:iron_block
execute as @s at @s rotated as @s run setblock ^9 ^62 ^4 minecraft:iron_block
execute as @s at @s rotated as @s run setblock ^9 ^63 ^-4 minecraft:iron_block
execute as @s at @s rotated as @s run setblock ^9 ^63 ^4 minecraft:iron_block
execute as @s at @s rotated as @s run setblock ^9 ^64 ^-4 minecraft:iron_block
execute as @s at @s rotated as @s run setblock ^9 ^64 ^4 minecraft:iron_block
execute as @s at @s rotated as @s run setblock ^9 ^65 ^-4 minecraft:iron_block
execute as @s at @s rotated as @s run setblock ^9 ^65 ^4 minecraft:iron_block
execute as @s at @s rotated as @s run setblock ^10 ^6 ^-4 minecraft:iron_block
execute as @s at @s rotated as @s run setblock ^10 ^6 ^4 minecraft:iron_block
execute as @s at @s rotated as @s run setblock ^10 ^7 ^-4 minecraft:iron_block
execute as @s at @s rotated as @s run setblock ^10 ^7 ^4 minecraft:iron_block
execute as @s at @s rotated as @s run setblock ^10 ^8 ^-4 minecraft:iron_block
execute as @s at @s rotated as @s run setblock ^10 ^8 ^4 minecraft:iron_block
execute as @s at @s rotated as @s run setblock ^10 ^9 ^-4 minecraft:iron_block
execute as @s at @s rotated as @s run setblock ^10 ^9 ^4 minecraft:iron_block
execute as @s at @s rotated as @s run setblock ^10 ^61 ^-4 minecraft:iron_block
execute as @s at @s rotated as @s run setblock ^10 ^61 ^4 minecraft:iron_block
execute as @s at @s rotated as @s run setblock ^10 ^62 ^-4 minecraft:iron_block
execute as @s at @s rotated as @s run setblock ^10 ^62 ^4 minecraft:iron_block
execute as @s at @s rotated as @s run setblock ^10 ^63 ^-4 minecraft:iron_block
execute as @s at @s rotated as @s run setblock ^10 ^63 ^4 minecraft:iron_block
execute as @s at @s rotated as @s run setblock ^10 ^64 ^-4 minecraft:iron_block
execute as @s at @s rotated as @s run setblock ^10 ^64 ^4 minecraft:iron_block
execute as @s at @s rotated as @s run setblock ^11 ^6 ^-4 minecraft:iron_block
execute as @s at @s rotated as @s run setblock ^11 ^6 ^4 minecraft:iron_block
execute as @s at @s rotated as @s run setblock ^11 ^7 ^-4 minecraft:iron_block
execute as @s at @s rotated as @s run setblock ^11 ^7 ^4 minecraft:iron_block
execute as @s at @s rotated as @s run setblock ^11 ^8 ^-4 minecraft:iron_block
execute as @s at @s rotated as @s run setblock ^11 ^8 ^4 minecraft:iron_block
execute as @s at @s rotated as @s run setblock ^11 ^9 ^-4 minecraft:iron_block
execute as @s at @s rotated as @s run setblock ^11 ^9 ^4 minecraft:iron_block
execute as @s at @s rotated as @s run setblock ^11 ^61 ^-4 minecraft:iron_block
execute as @s at @s rotated as @s run setblock ^11 ^61 ^4 minecraft:iron_block
execute as @s at @s rotated as @s run setblock ^11 ^62 ^-4 minecraft:iron_block
execute as @s at @s rotated as @s run setblock ^11 ^62 ^4 minecraft:iron_block
execute as @s at @s rotated as @s run setblock ^11 ^63 ^-4 minecraft:iron_block
execute as @s at @s rotated as @s run setblock ^11 ^63 ^4 minecraft:iron_block
execute as @s at @s rotated as @s run setblock ^11 ^64 ^-4 minecraft:iron_block
execute as @s at @s rotated as @s run setblock ^11 ^64 ^4 minecraft:iron_block
execute as @s at @s rotated as @s run setblock ^12 ^6 ^-4 minecraft:iron_block
execute as @s at @s rotated as @s run setblock ^12 ^6 ^4 minecraft:iron_block
execute as @s at @s rotated as @s run setblock ^12 ^7 ^-4 minecraft:iron_block
execute as @s at @s rotated as @s run setblock ^12 ^7 ^4 minecraft:iron_block
execute as @s at @s rotated as @s run setblock ^12 ^8 ^-4 minecraft:iron_block
execute as @s at @s rotated as @s run setblock ^12 ^8 ^4 minecraft:iron_block
execute as @s at @s rotated as @s run setblock ^12 ^9 ^-4 minecraft:iron_block
execute as @s at @s rotated as @s run setblock ^12 ^9 ^4 minecraft:iron_block
execute as @s at @s rotated as @s run setblock ^12 ^10 ^-4 minecraft:iron_block
execute as @s at @s rotated as @s run setblock ^12 ^10 ^4 minecraft:iron_block
execute as @s at @s rotated as @s run setblock ^12 ^60 ^-4 minecraft:iron_block
execute as @s at @s rotated as @s run setblock ^12 ^60 ^4 minecraft:iron_block
execute as @s at @s rotated as @s run setblock ^12 ^61 ^-4 minecraft:iron_block
execute as @s at @s rotated as @s run setblock ^12 ^61 ^4 minecraft:iron_block
execute as @s at @s rotated as @s run setblock ^12 ^62 ^-4 minecraft:iron_block
execute as @s at @s rotated as @s run setblock ^12 ^62 ^4 minecraft:iron_block
execute as @s at @s rotated as @s run setblock ^12 ^63 ^-4 minecraft:iron_block
execute as @s at @s rotated as @s run setblock ^12 ^63 ^4 minecraft:iron_block
execute as @s at @s rotated as @s run setblock ^12 ^64 ^-4 minecraft:iron_block
execute as @s at @s rotated as @s run setblock ^12 ^64 ^4 minecraft:iron_block
execute as @s at @s rotated as @s run setblock ^13 ^7 ^-4 minecraft:iron_block
execute as @s at @s rotated as @s run setblock ^13 ^7 ^4 minecraft:iron_block
execute as @s at @s rotated as @s run setblock ^13 ^8 ^-4 minecraft:iron_block
execute as @s at @s rotated as @s run setblock ^13 ^8 ^4 minecraft:iron_block
execute as @s at @s rotated as @s run setblock ^13 ^9 ^-4 minecraft:iron_block
execute as @s at @s rotated as @s run setblock ^13 ^9 ^4 minecraft:iron_block
execute as @s at @s rotated as @s run setblock ^13 ^10 ^-4 minecraft:iron_block
execute as @s at @s rotated as @s run setblock ^13 ^10 ^4 minecraft:iron_block
execute as @s at @s rotated as @s run setblock ^13 ^60 ^-4 minecraft:iron_block
execute as @s at @s rotated as @s run setblock ^13 ^60 ^4 minecraft:iron_block
execute as @s at @s rotated as @s run setblock ^13 ^61 ^-4 minecraft:iron_block
execute as @s at @s rotated as @s run setblock ^13 ^61 ^4 minecraft:iron_block
execute as @s at @s rotated as @s run setblock ^13 ^62 ^-4 minecraft:iron_block
execute as @s at @s rotated as @s run setblock ^13 ^62 ^4 minecraft:iron_block
execute as @s at @s rotated as @s run setblock ^13 ^63 ^-4 minecraft:iron_block
execute as @s at @s rotated as @s run setblock ^13 ^63 ^4 minecraft:iron_block
execute as @s at @s rotated as @s run setblock ^14 ^7 ^-4 minecraft:iron_block
execute as @s at @s rotated as @s run setblock ^14 ^7 ^4 minecraft:iron_block
execute as @s at @s rotated as @s run setblock ^14 ^8 ^-4 minecraft:iron_block
execute as @s at @s rotated as @s run setblock ^14 ^8 ^4 minecraft:iron_block
execute as @s at @s rotated as @s run setblock ^14 ^9 ^-4 minecraft:iron_block
execute as @s at @s rotated as @s run setblock ^14 ^9 ^4 minecraft:iron_block
execute as @s at @s rotated as @s run setblock ^14 ^10 ^-4 minecraft:iron_block
execute as @s at @s rotated as @s run setblock ^14 ^10 ^4 minecraft:iron_block
execute as @s at @s rotated as @s run setblock ^14 ^11 ^-4 minecraft:iron_block
execute as @s at @s rotated as @s run setblock ^14 ^11 ^4 minecraft:iron_block
execute as @s at @s rotated as @s run setblock ^14 ^59 ^-4 minecraft:iron_block
execute as @s at @s rotated as @s run setblock ^14 ^59 ^4 minecraft:iron_block
execute as @s at @s rotated as @s run setblock ^14 ^60 ^-4 minecraft:iron_block
execute as @s at @s rotated as @s run setblock ^14 ^60 ^4 minecraft:iron_block
execute as @s at @s rotated as @s run setblock ^14 ^61 ^-4 minecraft:iron_block
execute as @s at @s rotated as @s run setblock ^14 ^61 ^4 minecraft:iron_block
execute as @s at @s rotated as @s run setblock ^14 ^62 ^-4 minecraft:iron_block
execute as @s at @s rotated as @s run setblock ^14 ^62 ^4 minecraft:iron_block
execute as @s at @s rotated as @s run setblock ^14 ^63 ^-4 minecraft:iron_block
