# CRIMSON COMET ROLLER COASTER - Minecraft Bedrock Edition
# Build size: approximately 101 x 121 x 52 blocks.
# Stand at ground level at the front-center of a clear area, face a CARDINAL direction,
# look horizontally, then run: /function theme_park_crimson_comet_roller_coaster
# All placements use Bedrock caret-local coordinates, so the attraction follows your facing.
# Run once in a clear, flat area. Cheats must be enabled.

# === SNAP PLAYER TO BLOCK CENTER AND NEAREST CARDINAL ===
execute if entity @s[rym=-45,ry=45] as @s at @s align xz run tp @s ~0.5 ~ ~0.5 0 0
execute if entity @s[rym=45,ry=135] as @s at @s align xz run tp @s ~0.5 ~ ~0.5 90 0
execute if entity @s[rym=135,ry=180] as @s at @s align xz run tp @s ~0.5 ~ ~0.5 180 0
execute if entity @s[rym=-180,ry=-135] as @s at @s align xz run tp @s ~0.5 ~ ~0.5 180 0
execute if entity @s[rym=-135,ry=-45] as @s at @s align xz run tp @s ~0.5 ~ ~0.5 -90 0

execute as @s at @s rotated as @s run say Crimson Comet construction started

# === FOUNDATION, PROMENADE, AND PERIMETER ===
execute as @s at @s rotated as @s run fill ^-50 ^-2 ^-60 ^50 ^-2 ^60 minecraft:stone_bricks
execute as @s at @s rotated as @s run fill ^-49 ^-1 ^-59 ^49 ^-1 ^59 minecraft:grass_block
execute as @s at @s rotated as @s run fill ^-49 ^-1 ^-59 ^49 ^-1 ^-55 minecraft:smooth_stone
execute as @s at @s rotated as @s run fill ^-49 ^-1 ^55 ^49 ^-1 ^59 minecraft:smooth_stone
execute as @s at @s rotated as @s run fill ^-49 ^-1 ^-54 ^-45 ^-1 ^54 minecraft:smooth_stone
execute as @s at @s rotated as @s run fill ^45 ^-1 ^-54 ^49 ^-1 ^54 minecraft:smooth_stone
execute as @s at @s rotated as @s run fill ^-6 ^-1 ^-59 ^6 ^-1 ^-23 minecraft:polished_andesite
execute as @s at @s rotated as @s run fill ^-44 ^-1 ^-54 ^-10 ^-1 ^-26 minecraft:gray_concrete
execute as @s at @s rotated as @s run fill ^10 ^-1 ^-54 ^32 ^-1 ^-35 minecraft:polished_andesite
execute as @s at @s rotated as @s run fill ^-49 ^0 ^-59 ^-11 ^0 ^-59 minecraft:spruce_fence
execute as @s at @s rotated as @s run fill ^11 ^0 ^-59 ^49 ^0 ^-59 minecraft:spruce_fence
execute as @s at @s rotated as @s run fill ^-49 ^0 ^-58 ^-49 ^0 ^59 minecraft:spruce_fence
execute as @s at @s rotated as @s run fill ^49 ^0 ^-58 ^49 ^0 ^59 minecraft:spruce_fence
execute as @s at @s rotated as @s run fill ^-48 ^0 ^59 ^48 ^0 ^59 minecraft:spruce_fence

# === GRAND ENTRANCE AND MARQUEE ===
execute as @s at @s rotated as @s run fill ^-10 ^0 ^-60 ^-7 ^10 ^-57 minecraft:polished_blackstone_bricks
execute as @s at @s rotated as @s run fill ^7 ^0 ^-60 ^10 ^10 ^-57 minecraft:polished_blackstone_bricks
execute as @s at @s rotated as @s run fill ^-9 ^8 ^-60 ^9 ^11 ^-57 minecraft:black_concrete
execute as @s at @s rotated as @s run fill ^-7 ^9 ^-61 ^7 ^10 ^-61 minecraft:red_concrete
execute as @s at @s rotated as @s run fill ^-5 ^11 ^-60 ^5 ^13 ^-58 minecraft:red_concrete
execute as @s at @s rotated as @s run fill ^-3 ^13 ^-59 ^3 ^15 ^-59 minecraft:orange_concrete
execute as @s at @s rotated as @s run setblock ^0 ^16 ^-59 minecraft:yellow_concrete
execute as @s at @s rotated as @s run setblock ^-8 ^10 ^-62 minecraft:sea_lantern
execute as @s at @s rotated as @s run setblock ^-4 ^10 ^-62 minecraft:sea_lantern
execute as @s at @s rotated as @s run setblock ^0 ^10 ^-62 minecraft:sea_lantern
execute as @s at @s rotated as @s run setblock ^4 ^10 ^-62 minecraft:sea_lantern
execute as @s at @s rotated as @s run setblock ^8 ^10 ^-62 minecraft:sea_lantern
execute as @s at @s rotated as @s run fill ^-9 ^1 ^-56 ^-7 ^5 ^-54 minecraft:quartz_block
execute as @s at @s rotated as @s run fill ^7 ^1 ^-56 ^9 ^5 ^-54 minecraft:quartz_block
execute as @s at @s rotated as @s run fill ^-8 ^2 ^-57 ^-8 ^4 ^-57 minecraft:light_blue_stained_glass
execute as @s at @s rotated as @s run fill ^8 ^2 ^-57 ^8 ^4 ^-57 minecraft:light_blue_stained_glass
execute as @s at @s rotated as @s run fill ^-5 ^0 ^-54 ^-5 ^3 ^-54 minecraft:dark_oak_fence
execute as @s at @s rotated as @s run setblock ^-5 ^4 ^-54 minecraft:lantern
execute as @s at @s rotated as @s run fill ^0 ^0 ^-54 ^0 ^3 ^-54 minecraft:dark_oak_fence
execute as @s at @s rotated as @s run setblock ^0 ^4 ^-54 minecraft:lantern
execute as @s at @s rotated as @s run fill ^5 ^0 ^-54 ^5 ^3 ^-54 minecraft:dark_oak_fence
execute as @s at @s rotated as @s run setblock ^5 ^4 ^-54 minecraft:lantern

# === SWITCHBACK QUEUE AND TICKET AREA ===
execute as @s at @s rotated as @s run fill ^-43 ^-1 ^-52 ^-12 ^-1 ^-49 minecraft:red_concrete
execute as @s at @s rotated as @s run fill ^-43 ^-1 ^-46 ^-12 ^-1 ^-43 minecraft:black_concrete
execute as @s at @s rotated as @s run fill ^-43 ^-1 ^-40 ^-12 ^-1 ^-37 minecraft:red_concrete
execute as @s at @s rotated as @s run fill ^-43 ^-1 ^-34 ^-12 ^-1 ^-31 minecraft:black_concrete
execute as @s at @s rotated as @s run fill ^-44 ^0 ^-53 ^-11 ^0 ^-53 minecraft:spruce_fence
execute as @s at @s rotated as @s run fill ^-44 ^0 ^-48 ^-11 ^0 ^-48 minecraft:spruce_fence
execute as @s at @s rotated as @s run fill ^-44 ^0 ^-42 ^-11 ^0 ^-42 minecraft:spruce_fence
execute as @s at @s rotated as @s run fill ^-44 ^0 ^-36 ^-11 ^0 ^-36 minecraft:spruce_fence
execute as @s at @s rotated as @s run fill ^-44 ^0 ^-30 ^-11 ^0 ^-30 minecraft:spruce_fence
execute as @s at @s rotated as @s run fill ^-44 ^0 ^-53 ^-44 ^0 ^-30 minecraft:spruce_fence
execute as @s at @s rotated as @s run fill ^-11 ^0 ^-53 ^-11 ^0 ^-49 minecraft:spruce_fence
execute as @s at @s rotated as @s run fill ^-11 ^0 ^-47 ^-11 ^0 ^-43 minecraft:spruce_fence
execute as @s at @s rotated as @s run fill ^-11 ^0 ^-41 ^-11 ^0 ^-37 minecraft:spruce_fence
execute as @s at @s rotated as @s run fill ^-11 ^0 ^-35 ^-11 ^0 ^-30 minecraft:spruce_fence
execute as @s at @s rotated as @s run fill ^-42 ^0 ^-51 ^-42 ^3 ^-51 minecraft:dark_oak_fence
execute as @s at @s rotated as @s run setblock ^-42 ^4 ^-51 minecraft:lantern
execute as @s at @s rotated as @s run fill ^-13 ^0 ^-45 ^-13 ^3 ^-45 minecraft:dark_oak_fence
execute as @s at @s rotated as @s run setblock ^-13 ^4 ^-45 minecraft:lantern
execute as @s at @s rotated as @s run fill ^-42 ^0 ^-39 ^-42 ^3 ^-39 minecraft:dark_oak_fence
execute as @s at @s rotated as @s run setblock ^-42 ^4 ^-39 minecraft:lantern
execute as @s at @s rotated as @s run fill ^-13 ^0 ^-33 ^-13 ^3 ^-33 minecraft:dark_oak_fence
execute as @s at @s rotated as @s run setblock ^-13 ^4 ^-33 minecraft:lantern
execute as @s at @s rotated as @s run fill ^12 ^0 ^-53 ^20 ^5 ^-45 minecraft:white_concrete hollow
execute as @s at @s rotated as @s run fill ^13 ^1 ^-54 ^19 ^3 ^-54 minecraft:light_blue_stained_glass
execute as @s at @s rotated as @s run fill ^12 ^6 ^-53 ^20 ^6 ^-45 minecraft:red_concrete
execute as @s at @s rotated as @s run fill ^14 ^7 ^-51 ^18 ^8 ^-47 minecraft:orange_concrete
execute as @s at @s rotated as @s run setblock ^16 ^9 ^-49 minecraft:sea_lantern
execute as @s at @s rotated as @s run fill ^23 ^0 ^-53 ^31 ^5 ^-45 minecraft:polished_blackstone_bricks hollow
execute as @s at @s rotated as @s run fill ^24 ^1 ^-54 ^30 ^3 ^-54 minecraft:red_stained_glass
execute as @s at @s rotated as @s run fill ^23 ^6 ^-53 ^31 ^6 ^-45 minecraft:black_concrete
execute as @s at @s rotated as @s run fill ^26 ^7 ^-50 ^28 ^9 ^-48 minecraft:red_concrete
execute as @s at @s rotated as @s run setblock ^27 ^10 ^-49 minecraft:yellow_concrete

# === ELEVATED STATION AND BOARDING HOUSE ===
execute as @s at @s rotated as @s run fill ^-8 ^0 ^-50 ^-8 ^4 ^-50 minecraft:polished_blackstone_bricks
execute as @s at @s rotated as @s run fill ^-8 ^0 ^-42 ^-8 ^4 ^-42 minecraft:polished_blackstone_bricks
execute as @s at @s rotated as @s run fill ^-8 ^0 ^-34 ^-8 ^4 ^-34 minecraft:polished_blackstone_bricks
execute as @s at @s rotated as @s run fill ^-8 ^0 ^-27 ^-8 ^4 ^-27 minecraft:polished_blackstone_bricks
execute as @s at @s rotated as @s run fill ^8 ^0 ^-50 ^8 ^4 ^-50 minecraft:polished_blackstone_bricks
execute as @s at @s rotated as @s run fill ^8 ^0 ^-42 ^8 ^4 ^-42 minecraft:polished_blackstone_bricks
execute as @s at @s rotated as @s run fill ^8 ^0 ^-34 ^8 ^4 ^-34 minecraft:polished_blackstone_bricks
execute as @s at @s rotated as @s run fill ^8 ^0 ^-27 ^8 ^4 ^-27 minecraft:polished_blackstone_bricks
execute as @s at @s rotated as @s run fill ^-8 ^5 ^-51 ^-2 ^5 ^-27 minecraft:deepslate_tiles
execute as @s at @s rotated as @s run fill ^2 ^5 ^-51 ^8 ^5 ^-27 minecraft:deepslate_tiles
execute as @s at @s rotated as @s run fill ^-1 ^5 ^-51 ^-1 ^5 ^-27 minecraft:yellow_concrete
execute as @s at @s rotated as @s run fill ^1 ^5 ^-51 ^1 ^5 ^-27 minecraft:yellow_concrete
execute as @s at @s rotated as @s run fill ^-8 ^6 ^-51 ^-8 ^8 ^-27 minecraft:iron_bars
execute as @s at @s rotated as @s run fill ^8 ^6 ^-51 ^8 ^8 ^-27 minecraft:iron_bars
execute as @s at @s rotated as @s run fill ^-8 ^6 ^-50 ^-8 ^14 ^-50 minecraft:red_concrete
execute as @s at @s rotated as @s run setblock ^-8 ^11 ^-50 minecraft:sea_lantern
execute as @s at @s rotated as @s run fill ^-8 ^6 ^-42 ^-8 ^14 ^-42 minecraft:red_concrete
execute as @s at @s rotated as @s run setblock ^-8 ^11 ^-42 minecraft:sea_lantern
execute as @s at @s rotated as @s run fill ^-8 ^6 ^-34 ^-8 ^14 ^-34 minecraft:red_concrete
execute as @s at @s rotated as @s run setblock ^-8 ^11 ^-34 minecraft:sea_lantern
execute as @s at @s rotated as @s run fill ^-8 ^6 ^-27 ^-8 ^14 ^-27 minecraft:red_concrete
execute as @s at @s rotated as @s run setblock ^-8 ^11 ^-27 minecraft:sea_lantern
execute as @s at @s rotated as @s run fill ^8 ^6 ^-50 ^8 ^14 ^-50 minecraft:red_concrete
execute as @s at @s rotated as @s run setblock ^8 ^11 ^-50 minecraft:sea_lantern
execute as @s at @s rotated as @s run fill ^8 ^6 ^-42 ^8 ^14 ^-42 minecraft:red_concrete
execute as @s at @s rotated as @s run setblock ^8 ^11 ^-42 minecraft:sea_lantern
execute as @s at @s rotated as @s run fill ^8 ^6 ^-34 ^8 ^14 ^-34 minecraft:red_concrete
execute as @s at @s rotated as @s run setblock ^8 ^11 ^-34 minecraft:sea_lantern
execute as @s at @s rotated as @s run fill ^8 ^6 ^-27 ^8 ^14 ^-27 minecraft:red_concrete
execute as @s at @s rotated as @s run setblock ^8 ^11 ^-27 minecraft:sea_lantern
execute as @s at @s rotated as @s run fill ^-9 ^15 ^-52 ^9 ^16 ^-26 minecraft:black_concrete
execute as @s at @s rotated as @s run fill ^-8 ^17 ^-51 ^8 ^17 ^-27 minecraft:red_concrete
execute as @s at @s rotated as @s run fill ^-5 ^18 ^-45 ^5 ^20 ^-33 minecraft:orange_concrete
execute as @s at @s rotated as @s run fill ^-3 ^21 ^-42 ^3 ^22 ^-36 minecraft:yellow_concrete
execute as @s at @s rotated as @s run fill ^-7 ^9 ^-28 ^7 ^12 ^-27 minecraft:black_concrete
execute as @s at @s rotated as @s run fill ^-5 ^10 ^-26 ^5 ^11 ^-26 minecraft:red_concrete
execute as @s at @s rotated as @s run setblock ^-4 ^10 ^-25 minecraft:sea_lantern
execute as @s at @s rotated as @s run setblock ^0 ^10 ^-25 minecraft:sea_lantern
execute as @s at @s rotated as @s run setblock ^4 ^10 ^-25 minecraft:sea_lantern
execute as @s at @s rotated as @s run fill ^-7 ^6 ^-40 ^-3 ^10 ^-33 minecraft:dark_oak_planks hollow
execute as @s at @s rotated as @s run fill ^-6 ^7 ^-41 ^-4 ^9 ^-41 minecraft:light_blue_stained_glass
execute as @s at @s rotated as @s run setblock ^-5 ^11 ^-37 minecraft:lantern
execute as @s at @s rotated as @s run fill ^4 ^6 ^-39 ^7 ^7 ^-31 minecraft:smooth_stone
execute as @s at @s rotated as @s run setblock ^5 ^8 ^-38 minecraft:spruce_fence
execute as @s at @s rotated as @s run setblock ^5 ^8 ^-35 minecraft:spruce_fence
execute as @s at @s rotated as @s run setblock ^5 ^8 ^-32 minecraft:spruce_fence
execute as @s at @s rotated as @s run fill ^-11 ^0 ^-28 ^-9 ^0 ^-28 minecraft:stone_bricks
execute as @s at @s rotated as @s run fill ^-11 ^1 ^-27 ^-9 ^1 ^-27 minecraft:stone_bricks
execute as @s at @s rotated as @s run fill ^-11 ^2 ^-26 ^-9 ^2 ^-26 minecraft:stone_bricks
execute as @s at @s rotated as @s run fill ^-11 ^3 ^-25 ^-9 ^3 ^-25 minecraft:stone_bricks
execute as @s at @s rotated as @s run fill ^-11 ^4 ^-24 ^-9 ^4 ^-24 minecraft:stone_bricks
execute as @s at @s rotated as @s run fill ^-12 ^0 ^-28 ^-12 ^4 ^-24 minecraft:spruce_fence
execute as @s at @s rotated as @s run fill ^-8 ^0 ^-28 ^-8 ^4 ^-24 minecraft:spruce_fence

# === CENTRAL COMET LAGOON ===
execute as @s at @s rotated as @s run fill ^-16 ^-1 ^12 ^16 ^-1 ^41 minecraft:cyan_concrete
execute as @s at @s rotated as @s run fill ^-14 ^-1 ^14 ^14 ^-1 ^39 minecraft:water
execute as @s at @s rotated as @s run fill ^-12 ^-1 ^12 ^12 ^-1 ^12 minecraft:smooth_stone
execute as @s at @s rotated as @s run fill ^-12 ^-1 ^41 ^12 ^-1 ^41 minecraft:smooth_stone
execute as @s at @s rotated as @s run fill ^-16 ^-1 ^16 ^-16 ^-1 ^37 minecraft:smooth_stone
execute as @s at @s rotated as @s run fill ^16 ^-1 ^16 ^16 ^-1 ^37 minecraft:smooth_stone
execute as @s at @s rotated as @s run fill ^-9 ^0 ^19 ^-9 ^2 ^19 minecraft:prismarine_bricks
execute as @s at @s rotated as @s run setblock ^-9 ^3 ^19 minecraft:sea_lantern
execute as @s at @s rotated as @s run fill ^-9 ^0 ^34 ^-9 ^2 ^34 minecraft:prismarine_bricks
execute as @s at @s rotated as @s run setblock ^-9 ^3 ^34 minecraft:sea_lantern
execute as @s at @s rotated as @s run fill ^9 ^0 ^19 ^9 ^2 ^19 minecraft:prismarine_bricks
execute as @s at @s rotated as @s run setblock ^9 ^3 ^19 minecraft:sea_lantern
execute as @s at @s rotated as @s run fill ^9 ^0 ^34 ^9 ^2 ^34 minecraft:prismarine_bricks
execute as @s at @s rotated as @s run setblock ^9 ^3 ^34 minecraft:sea_lantern
execute as @s at @s rotated as @s run fill ^-2 ^0 ^25 ^2 ^0 ^29 minecraft:quartz_block
execute as @s at @s rotated as @s run fill ^-1 ^1 ^26 ^1 ^4 ^28 minecraft:quartz_block
execute as @s at @s rotated as @s run setblock ^0 ^5 ^27 minecraft:sea_lantern
execute as @s at @s rotated as @s run fill ^0 ^6 ^27 ^0 ^9 ^27 minecraft:water
execute as @s at @s rotated as @s run fill ^-20 ^0 ^10 ^-20 ^2 ^10 minecraft:dark_oak_fence
execute as @s at @s rotated as @s run setblock ^-20 ^3 ^10 minecraft:lantern
execute as @s at @s rotated as @s run fill ^-21 ^0 ^20 ^-21 ^2 ^20 minecraft:dark_oak_fence
execute as @s at @s rotated as @s run setblock ^-21 ^3 ^20 minecraft:lantern
execute as @s at @s rotated as @s run fill ^-21 ^0 ^32 ^-21 ^2 ^32 minecraft:dark_oak_fence
execute as @s at @s rotated as @s run setblock ^-21 ^3 ^32 minecraft:lantern
execute as @s at @s rotated as @s run fill ^-20 ^0 ^43 ^-20 ^2 ^43 minecraft:dark_oak_fence
execute as @s at @s rotated as @s run setblock ^-20 ^3 ^43 minecraft:lantern
execute as @s at @s rotated as @s run fill ^20 ^0 ^10 ^20 ^2 ^10 minecraft:dark_oak_fence
execute as @s at @s rotated as @s run setblock ^20 ^3 ^10 minecraft:lantern
execute as @s at @s rotated as @s run fill ^21 ^0 ^20 ^21 ^2 ^20 minecraft:dark_oak_fence
execute as @s at @s rotated as @s run setblock ^21 ^3 ^20 minecraft:lantern
execute as @s at @s rotated as @s run fill ^21 ^0 ^32 ^21 ^2 ^32 minecraft:dark_oak_fence
execute as @s at @s rotated as @s run setblock ^21 ^3 ^32 minecraft:lantern
execute as @s at @s rotated as @s run fill ^20 ^0 ^43 ^20 ^2 ^43 minecraft:dark_oak_fence
execute as @s at @s rotated as @s run setblock ^20 ^3 ^43 minecraft:lantern
execute as @s at @s rotated as @s run fill ^-24 ^0 ^13 ^-24 ^3 ^13 minecraft:oak_log
execute as @s at @s rotated as @s run fill ^-26 ^4 ^11 ^-22 ^5 ^15 minecraft:oak_leaves
execute as @s at @s rotated as @s run fill ^-25 ^6 ^12 ^-23 ^6 ^14 minecraft:oak_leaves
execute as @s at @s rotated as @s run fill ^-25 ^0 ^17 ^-25 ^3 ^17 minecraft:oak_log
execute as @s at @s rotated as @s run fill ^-27 ^4 ^15 ^-23 ^5 ^19 minecraft:oak_leaves
execute as @s at @s rotated as @s run fill ^-26 ^6 ^16 ^-24 ^6 ^18 minecraft:oak_leaves
execute as @s at @s rotated as @s run fill ^-23 ^0 ^22 ^-23 ^3 ^22 minecraft:oak_log
execute as @s at @s rotated as @s run fill ^-25 ^4 ^20 ^-21 ^5 ^24 minecraft:oak_leaves
execute as @s at @s rotated as @s run fill ^-24 ^6 ^21 ^-22 ^6 ^23 minecraft:oak_leaves
execute as @s at @s rotated as @s run fill ^-24 ^0 ^38 ^-24 ^3 ^38 minecraft:oak_log
execute as @s at @s rotated as @s run fill ^-26 ^4 ^36 ^-22 ^5 ^40 minecraft:oak_leaves
execute as @s at @s rotated as @s run fill ^-25 ^6 ^37 ^-23 ^6 ^39 minecraft:oak_leaves
execute as @s at @s rotated as @s run fill ^24 ^0 ^13 ^24 ^3 ^13 minecraft:oak_log
execute as @s at @s rotated as @s run fill ^22 ^4 ^11 ^26 ^5 ^15 minecraft:oak_leaves
execute as @s at @s rotated as @s run fill ^23 ^6 ^12 ^25 ^6 ^14 minecraft:oak_leaves
execute as @s at @s rotated as @s run fill ^25 ^0 ^18 ^25 ^3 ^18 minecraft:oak_log
execute as @s at @s rotated as @s run fill ^23 ^4 ^16 ^27 ^5 ^20 minecraft:oak_leaves
execute as @s at @s rotated as @s run fill ^24 ^6 ^17 ^26 ^6 ^19 minecraft:oak_leaves
execute as @s at @s rotated as @s run fill ^23 ^0 ^23 ^23 ^3 ^23 minecraft:oak_log
execute as @s at @s rotated as @s run fill ^21 ^4 ^21 ^25 ^5 ^25 minecraft:oak_leaves
execute as @s at @s rotated as @s run fill ^22 ^6 ^22 ^24 ^6 ^24 minecraft:oak_leaves
execute as @s at @s rotated as @s run fill ^24 ^0 ^38 ^24 ^3 ^38 minecraft:oak_log
execute as @s at @s rotated as @s run fill ^22 ^4 ^36 ^26 ^5 ^40 minecraft:oak_leaves
execute as @s at @s rotated as @s run fill ^23 ^6 ^37 ^25 ^6 ^39 minecraft:oak_leaves
execute as @s at @s rotated as @s run setblock ^-18 ^0 ^7 minecraft:poppy
execute as @s at @s rotated as @s run setblock ^-14 ^0 ^8 minecraft:dandelion
execute as @s at @s rotated as @s run setblock ^-10 ^0 ^7 minecraft:azure_bluet
execute as @s at @s rotated as @s run setblock ^10 ^0 ^7 minecraft:poppy
execute as @s at @s rotated as @s run setblock ^14 ^0 ^8 minecraft:dandelion
execute as @s at @s rotated as @s run setblock ^18 ^0 ^7 minecraft:azure_bluet
execute as @s at @s rotated as @s run setblock ^-18 ^0 ^46 minecraft:dandelion
execute as @s at @s rotated as @s run setblock ^-12 ^0 ^47 minecraft:poppy
execute as @s at @s rotated as @s run setblock ^12 ^0 ^47 minecraft:poppy
execute as @s at @s rotated as @s run setblock ^18 ^0 ^46 minecraft:dandelion

# === CRIMSON COMET SCULPTURE ===
execute as @s at @s rotated as @s run fill ^25 ^0 ^-17 ^25 ^5 ^-17 minecraft:polished_blackstone_bricks
execute as @s at @s rotated as @s run fill ^22 ^6 ^-20 ^28 ^12 ^-14 minecraft:red_concrete
execute as @s at @s rotated as @s run fill ^21 ^8 ^-18 ^29 ^10 ^-16 minecraft:red_concrete
execute as @s at @s rotated as @s run fill ^23 ^7 ^-21 ^27 ^11 ^-13 minecraft:orange_concrete
execute as @s at @s rotated as @s run fill ^24 ^8 ^-22 ^26 ^10 ^-12 minecraft:yellow_concrete
execute as @s at @s rotated as @s run setblock ^25 ^9 ^-23 minecraft:sea_lantern
execute as @s at @s rotated as @s run fill ^19 ^7 ^-18 ^21 ^9 ^-16 minecraft:red_stained_glass
execute as @s at @s rotated as @s run fill ^15 ^6 ^-18 ^18 ^8 ^-16 minecraft:orange_stained_glass
execute as @s at @s rotated as @s run fill ^11 ^5 ^-18 ^14 ^7 ^-16 minecraft:yellow_stained_glass
execute as @s at @s rotated as @s run setblock ^10 ^6 ^-17 minecraft:sea_lantern
execute as @s at @s rotated as @s run fill ^23 ^13 ^-18 ^27 ^13 ^-16 minecraft:black_concrete
execute as @s at @s rotated as @s run fill ^24 ^14 ^-18 ^26 ^15 ^-16 minecraft:red_concrete

# === PHOTO SHOP, MAINTENANCE BAY, AND PARK DETAILS ===
execute as @s at @s rotated as @s run fill ^26 ^0 ^44 ^39 ^6 ^54 minecraft:dark_oak_planks hollow
execute as @s at @s rotated as @s run fill ^27 ^1 ^43 ^38 ^4 ^43 minecraft:light_blue_stained_glass
execute as @s at @s rotated as @s run fill ^26 ^7 ^44 ^39 ^7 ^54 minecraft:red_concrete
execute as @s at @s rotated as @s run fill ^29 ^8 ^46 ^36 ^10 ^52 minecraft:black_concrete
execute as @s at @s rotated as @s run fill ^31 ^9 ^45 ^34 ^11 ^45 minecraft:yellow_concrete
execute as @s at @s rotated as @s run fill ^28 ^0 ^39 ^28 ^2 ^39 minecraft:dark_oak_fence
execute as @s at @s rotated as @s run setblock ^28 ^3 ^39 minecraft:lantern
execute as @s at @s rotated as @s run fill ^32 ^0 ^39 ^32 ^2 ^39 minecraft:dark_oak_fence
execute as @s at @s rotated as @s run setblock ^32 ^3 ^39 minecraft:lantern
execute as @s at @s rotated as @s run fill ^36 ^0 ^39 ^36 ^2 ^39 minecraft:dark_oak_fence
execute as @s at @s rotated as @s run setblock ^36 ^3 ^39 minecraft:lantern
execute as @s at @s rotated as @s run fill ^40 ^0 ^39 ^40 ^2 ^39 minecraft:dark_oak_fence
execute as @s at @s rotated as @s run setblock ^40 ^3 ^39 minecraft:lantern
execute as @s at @s rotated as @s run fill ^-45 ^0 ^18 ^-36 ^7 ^34 minecraft:polished_blackstone_bricks hollow
execute as @s at @s rotated as @s run fill ^-44 ^1 ^17 ^-37 ^5 ^17 minecraft:iron_bars
execute as @s at @s rotated as @s run fill ^-45 ^8 ^18 ^-36 ^8 ^34 minecraft:black_concrete
execute as @s at @s rotated as @s run fill ^-43 ^1 ^32 ^-38 ^5 ^34 minecraft:gray_concrete
execute as @s at @s rotated as @s run fill ^-43 ^0 ^37 ^-38 ^0 ^41 minecraft:smooth_stone
execute as @s at @s rotated as @s run setblock ^-42 ^1 ^39 minecraft:barrel
execute as @s at @s rotated as @s run setblock ^-39 ^1 ^39 minecraft:barrel
execute as @s at @s rotated as @s run fill ^-47 ^0 ^-10 ^-47 ^3 ^-10 minecraft:dark_oak_fence
execute as @s at @s rotated as @s run setblock ^-47 ^4 ^-10 minecraft:lantern
execute as @s at @s rotated as @s run fill ^47 ^0 ^-10 ^47 ^3 ^-10 minecraft:dark_oak_fence
execute as @s at @s rotated as @s run setblock ^47 ^4 ^-10 minecraft:lantern
execute as @s at @s rotated as @s run fill ^-47 ^0 ^0 ^-47 ^3 ^0 minecraft:dark_oak_fence
execute as @s at @s rotated as @s run setblock ^-47 ^4 ^0 minecraft:lantern
execute as @s at @s rotated as @s run fill ^47 ^0 ^0 ^47 ^3 ^0 minecraft:dark_oak_fence
execute as @s at @s rotated as @s run setblock ^47 ^4 ^0 minecraft:lantern
execute as @s at @s rotated as @s run fill ^-47 ^0 ^10 ^-47 ^3 ^10 minecraft:dark_oak_fence
execute as @s at @s rotated as @s run setblock ^-47 ^4 ^10 minecraft:lantern
execute as @s at @s rotated as @s run fill ^47 ^0 ^10 ^47 ^3 ^10 minecraft:dark_oak_fence
execute as @s at @s rotated as @s run setblock ^47 ^4 ^10 minecraft:lantern
execute as @s at @s rotated as @s run fill ^-47 ^0 ^20 ^-47 ^3 ^20 minecraft:dark_oak_fence
execute as @s at @s rotated as @s run setblock ^-47 ^4 ^20 minecraft:lantern
execute as @s at @s rotated as @s run fill ^47 ^0 ^20 ^47 ^3 ^20 minecraft:dark_oak_fence
execute as @s at @s rotated as @s run setblock ^47 ^4 ^20 minecraft:lantern
execute as @s at @s rotated as @s run fill ^-47 ^0 ^30 ^-47 ^3 ^30 minecraft:dark_oak_fence
execute as @s at @s rotated as @s run setblock ^-47 ^4 ^30 minecraft:lantern
execute as @s at @s rotated as @s run fill ^47 ^0 ^30 ^47 ^3 ^30 minecraft:dark_oak_fence
execute as @s at @s rotated as @s run setblock ^47 ^4 ^30 minecraft:lantern
execute as @s at @s rotated as @s run fill ^-47 ^0 ^40 ^-47 ^3 ^40 minecraft:dark_oak_fence
execute as @s at @s rotated as @s run setblock ^-47 ^4 ^40 minecraft:lantern
execute as @s at @s rotated as @s run fill ^47 ^0 ^40 ^47 ^3 ^40 minecraft:dark_oak_fence
execute as @s at @s rotated as @s run setblock ^47 ^4 ^40 minecraft:lantern
execute as @s at @s rotated as @s run fill ^-47 ^0 ^50 ^-47 ^3 ^50 minecraft:dark_oak_fence
execute as @s at @s rotated as @s run setblock ^-47 ^4 ^50 minecraft:lantern
execute as @s at @s rotated as @s run fill ^47 ^0 ^50 ^47 ^3 ^50 minecraft:dark_oak_fence
execute as @s at @s rotated as @s run setblock ^47 ^4 ^50 minecraft:lantern
execute as @s at @s rotated as @s run fill ^-40 ^0 ^57 ^-40 ^3 ^57 minecraft:dark_oak_fence
execute as @s at @s rotated as @s run setblock ^-40 ^4 ^57 minecraft:lantern
execute as @s at @s rotated as @s run fill ^-30 ^0 ^57 ^-30 ^3 ^57 minecraft:dark_oak_fence
execute as @s at @s rotated as @s run setblock ^-30 ^4 ^57 minecraft:lantern
execute as @s at @s rotated as @s run fill ^-20 ^0 ^57 ^-20 ^3 ^57 minecraft:dark_oak_fence
execute as @s at @s rotated as @s run setblock ^-20 ^4 ^57 minecraft:lantern
execute as @s at @s rotated as @s run fill ^-10 ^0 ^57 ^-10 ^3 ^57 minecraft:dark_oak_fence
execute as @s at @s rotated as @s run setblock ^-10 ^4 ^57 minecraft:lantern
execute as @s at @s rotated as @s run fill ^10 ^0 ^57 ^10 ^3 ^57 minecraft:dark_oak_fence
execute as @s at @s rotated as @s run setblock ^10 ^4 ^57 minecraft:lantern
execute as @s at @s rotated as @s run fill ^20 ^0 ^57 ^20 ^3 ^57 minecraft:dark_oak_fence
execute as @s at @s rotated as @s run setblock ^20 ^4 ^57 minecraft:lantern
execute as @s at @s rotated as @s run fill ^30 ^0 ^57 ^30 ^3 ^57 minecraft:dark_oak_fence
execute as @s at @s rotated as @s run setblock ^30 ^4 ^57 minecraft:lantern
execute as @s at @s rotated as @s run fill ^40 ^0 ^57 ^40 ^3 ^57 minecraft:dark_oak_fence
execute as @s at @s rotated as @s run setblock ^40 ^4 ^57 minecraft:lantern

# === TRACK SUPPORT TOWERS ===
execute as @s at @s rotated as @s run fill ^0 ^0 ^-24 ^0 ^11 ^-24 minecraft:polished_blackstone_bricks
execute as @s at @s rotated as @s run fill ^0 ^0 ^-16 ^0 ^19 ^-16 minecraft:polished_blackstone_bricks
execute as @s at @s rotated as @s run setblock ^-1 ^10 ^-16 minecraft:red_concrete
execute as @s at @s rotated as @s run setblock ^1 ^10 ^-16 minecraft:red_concrete
execute as @s at @s rotated as @s run fill ^0 ^0 ^-8 ^0 ^27 ^-8 minecraft:polished_blackstone_bricks
execute as @s at @s rotated as @s run setblock ^-1 ^14 ^-8 minecraft:red_concrete
execute as @s at @s rotated as @s run setblock ^1 ^14 ^-8 minecraft:red_concrete
execute as @s at @s rotated as @s run fill ^0 ^0 ^0 ^0 ^35 ^0 minecraft:polished_blackstone_bricks
execute as @s at @s rotated as @s run setblock ^-1 ^18 ^0 minecraft:red_concrete
execute as @s at @s rotated as @s run setblock ^1 ^18 ^0 minecraft:red_concrete
execute as @s at @s rotated as @s run fill ^0 ^0 ^8 ^0 ^43 ^8 minecraft:polished_blackstone_bricks
execute as @s at @s rotated as @s run setblock ^-1 ^22 ^8 minecraft:red_concrete
execute as @s at @s rotated as @s run setblock ^1 ^22 ^8 minecraft:red_concrete
execute as @s at @s rotated as @s run fill ^0 ^0 ^16 ^0 ^50 ^16 minecraft:polished_blackstone_bricks
execute as @s at @s rotated as @s run setblock ^-1 ^25 ^16 minecraft:red_concrete
execute as @s at @s rotated as @s run setblock ^1 ^25 ^16 minecraft:red_concrete
execute as @s at @s rotated as @s run fill ^4 ^0 ^20 ^4 ^50 ^20 minecraft:polished_blackstone_bricks
execute as @s at @s rotated as @s run setblock ^3 ^25 ^20 minecraft:red_concrete
execute as @s at @s rotated as @s run setblock ^5 ^25 ^20 minecraft:red_concrete
execute as @s at @s rotated as @s run fill ^12 ^0 ^20 ^12 ^50 ^20 minecraft:polished_blackstone_bricks
execute as @s at @s rotated as @s run setblock ^11 ^25 ^20 minecraft:red_concrete
execute as @s at @s rotated as @s run setblock ^13 ^25 ^20 minecraft:red_concrete
execute as @s at @s rotated as @s run fill ^20 ^0 ^20 ^20 ^50 ^20 minecraft:polished_blackstone_bricks
execute as @s at @s rotated as @s run setblock ^19 ^25 ^20 minecraft:red_concrete
execute as @s at @s rotated as @s run setblock ^21 ^25 ^20 minecraft:red_concrete
execute as @s at @s rotated as @s run fill ^28 ^0 ^20 ^28 ^50 ^20 minecraft:polished_blackstone_bricks
execute as @s at @s rotated as @s run setblock ^27 ^25 ^20 minecraft:red_concrete
execute as @s at @s rotated as @s run setblock ^29 ^25 ^20 minecraft:red_concrete
execute as @s at @s rotated as @s run fill ^36 ^0 ^20 ^36 ^50 ^20 minecraft:polished_blackstone_bricks
execute as @s at @s rotated as @s run setblock ^35 ^25 ^20 minecraft:red_concrete
execute as @s at @s rotated as @s run setblock ^37 ^25 ^20 minecraft:red_concrete
execute as @s at @s rotated as @s run fill ^42 ^0 ^22 ^42 ^48 ^22 minecraft:polished_blackstone_bricks
execute as @s at @s rotated as @s run setblock ^41 ^24 ^22 minecraft:red_concrete
execute as @s at @s rotated as @s run setblock ^43 ^24 ^22 minecraft:red_concrete
execute as @s at @s rotated as @s run fill ^42 ^0 ^30 ^42 ^40 ^30 minecraft:polished_blackstone_bricks
execute as @s at @s rotated as @s run setblock ^41 ^20 ^30 minecraft:red_concrete
execute as @s at @s rotated as @s run setblock ^43 ^20 ^30 minecraft:red_concrete
execute as @s at @s rotated as @s run fill ^42 ^0 ^38 ^42 ^32 ^38 minecraft:polished_blackstone_bricks
execute as @s at @s rotated as @s run setblock ^41 ^16 ^38 minecraft:red_concrete
execute as @s at @s rotated as @s run setblock ^43 ^16 ^38 minecraft:red_concrete
execute as @s at @s rotated as @s run fill ^42 ^0 ^46 ^42 ^24 ^46 minecraft:polished_blackstone_bricks
execute as @s at @s rotated as @s run setblock ^41 ^12 ^46 minecraft:red_concrete
execute as @s at @s rotated as @s run setblock ^43 ^12 ^46 minecraft:red_concrete
execute as @s at @s rotated as @s run fill ^42 ^0 ^54 ^42 ^16 ^54 minecraft:polished_blackstone_bricks
execute as @s at @s rotated as @s run fill ^39 ^0 ^59 ^39 ^12 ^59 minecraft:polished_blackstone_bricks
execute as @s at @s rotated as @s run fill ^31 ^0 ^59 ^31 ^12 ^59 minecraft:polished_blackstone_bricks
execute as @s at @s rotated as @s run fill ^23 ^0 ^59 ^23 ^12 ^59 minecraft:polished_blackstone_bricks
execute as @s at @s rotated as @s run fill ^15 ^0 ^59 ^15 ^12 ^59 minecraft:polished_blackstone_bricks
execute as @s at @s rotated as @s run fill ^7 ^0 ^59 ^7 ^15 ^59 minecraft:polished_blackstone_bricks
execute as @s at @s rotated as @s run fill ^-1 ^0 ^59 ^-1 ^23 ^59 minecraft:polished_blackstone_bricks
execute as @s at @s rotated as @s run setblock ^-2 ^12 ^59 minecraft:red_concrete
execute as @s at @s rotated as @s run setblock ^0 ^12 ^59 minecraft:red_concrete
execute as @s at @s rotated as @s run fill ^-9 ^0 ^59 ^-9 ^31 ^59 minecraft:polished_blackstone_bricks
execute as @s at @s rotated as @s run setblock ^-10 ^16 ^59 minecraft:red_concrete
execute as @s at @s rotated as @s run setblock ^-8 ^16 ^59 minecraft:red_concrete
execute as @s at @s rotated as @s run fill ^-17 ^0 ^59 ^-17 ^25 ^59 minecraft:polished_blackstone_bricks
execute as @s at @s rotated as @s run setblock ^-18 ^13 ^59 minecraft:red_concrete
execute as @s at @s rotated as @s run setblock ^-16 ^13 ^59 minecraft:red_concrete
execute as @s at @s rotated as @s run fill ^-25 ^0 ^59 ^-25 ^17 ^59 minecraft:polished_blackstone_bricks
execute as @s at @s rotated as @s run fill ^-31 ^0 ^57 ^-31 ^12 ^57 minecraft:polished_blackstone_bricks
execute as @s at @s rotated as @s run fill ^-31 ^0 ^49 ^-31 ^12 ^49 minecraft:polished_blackstone_bricks
execute as @s at @s rotated as @s run fill ^-31 ^0 ^41 ^-31 ^12 ^41 minecraft:polished_blackstone_bricks
execute as @s at @s rotated as @s run fill ^-31 ^0 ^33 ^-31 ^14 ^33 minecraft:polished_blackstone_bricks
execute as @s at @s rotated as @s run fill ^-31 ^0 ^25 ^-31 ^22 ^25 minecraft:polished_blackstone_bricks
execute as @s at @s rotated as @s run setblock ^-32 ^11 ^25 minecraft:red_concrete
execute as @s at @s rotated as @s run setblock ^-30 ^11 ^25 minecraft:red_concrete
execute as @s at @s rotated as @s run fill ^-31 ^0 ^17 ^-31 ^20 ^17 minecraft:polished_blackstone_bricks
execute as @s at @s rotated as @s run setblock ^-32 ^10 ^17 minecraft:red_concrete
execute as @s at @s rotated as @s run setblock ^-30 ^10 ^17 minecraft:red_concrete
execute as @s at @s rotated as @s run fill ^-31 ^0 ^9 ^-31 ^12 ^9 minecraft:polished_blackstone_bricks
execute as @s at @s rotated as @s run fill ^-38 ^0 ^8 ^-38 ^12 ^8 minecraft:polished_blackstone_bricks
execute as @s at @s rotated as @s run fill ^-2 ^0 ^-20 ^-2 ^16 ^-20 minecraft:polished_blackstone_bricks
execute as @s at @s rotated as @s run setblock ^-2 ^17 ^-20 minecraft:red_concrete
execute as @s at @s rotated as @s run fill ^2 ^0 ^-20 ^2 ^16 ^-20 minecraft:polished_blackstone_bricks
execute as @s at @s rotated as @s run setblock ^2 ^17 ^-20 minecraft:red_concrete
execute as @s at @s rotated as @s run fill ^-2 ^0 ^-4 ^-2 ^32 ^-4 minecraft:polished_blackstone_bricks
execute as @s at @s rotated as @s run setblock ^-2 ^33 ^-4 minecraft:red_concrete
execute as @s at @s rotated as @s run fill ^2 ^0 ^-4 ^2 ^32 ^-4 minecraft:polished_blackstone_bricks
execute as @s at @s rotated as @s run setblock ^2 ^33 ^-4 minecraft:red_concrete
execute as @s at @s rotated as @s run fill ^-2 ^0 ^12 ^-2 ^48 ^12 minecraft:polished_blackstone_bricks
execute as @s at @s rotated as @s run setblock ^-2 ^49 ^12 minecraft:red_concrete
execute as @s at @s rotated as @s run fill ^2 ^0 ^12 ^2 ^48 ^12 minecraft:polished_blackstone_bricks
execute as @s at @s rotated as @s run setblock ^2 ^49 ^12 minecraft:red_concrete
execute as @s at @s rotated as @s run fill ^18 ^0 ^18 ^18 ^50 ^18 minecraft:polished_blackstone_bricks
execute as @s at @s rotated as @s run setblock ^18 ^51 ^18 minecraft:red_concrete
execute as @s at @s rotated as @s run fill ^34 ^0 ^18 ^34 ^50 ^18 minecraft:polished_blackstone_bricks
execute as @s at @s rotated as @s run setblock ^34 ^51 ^18 minecraft:red_concrete
execute as @s at @s rotated as @s run fill ^40 ^0 ^32 ^40 ^40 ^32 minecraft:polished_blackstone_bricks
execute as @s at @s rotated as @s run setblock ^40 ^41 ^32 minecraft:red_concrete
execute as @s at @s rotated as @s run fill ^40 ^0 ^48 ^40 ^24 ^48 minecraft:polished_blackstone_bricks
execute as @s at @s rotated as @s run setblock ^40 ^25 ^48 minecraft:red_concrete
execute as @s at @s rotated as @s run fill ^-8 ^0 ^57 ^-8 ^31 ^57 minecraft:polished_blackstone_bricks
execute as @s at @s rotated as @s run setblock ^-8 ^32 ^57 minecraft:red_concrete
execute as @s at @s rotated as @s run fill ^-24 ^0 ^57 ^-24 ^18 ^57 minecraft:polished_blackstone_bricks
execute as @s at @s rotated as @s run setblock ^-24 ^19 ^57 minecraft:red_concrete
execute as @s at @s rotated as @s run fill ^-33 ^0 ^28 ^-33 ^22 ^28 minecraft:polished_blackstone_bricks
execute as @s at @s rotated as @s run setblock ^-33 ^23 ^28 minecraft:red_concrete
execute as @s at @s rotated as @s run fill ^-44 ^0 ^-8 ^-44 ^8 ^-8 minecraft:polished_blackstone_bricks
execute as @s at @s rotated as @s run setblock ^-44 ^9 ^-8 minecraft:red_concrete
execute as @s at @s rotated as @s run fill ^-44 ^0 ^-32 ^-44 ^8 ^-32 minecraft:polished_blackstone_bricks
execute as @s at @s rotated as @s run setblock ^-44 ^9 ^-32 minecraft:red_concrete
execute as @s at @s rotated as @s run fill ^-2 ^15 ^-20 ^2 ^15 ^-20 minecraft:red_concrete
execute as @s at @s rotated as @s run fill ^-2 ^31 ^-4 ^2 ^31 ^-4 minecraft:red_concrete
execute as @s at @s rotated as @s run fill ^-2 ^47 ^12 ^2 ^47 ^12 minecraft:red_concrete
execute as @s at @s rotated as @s run fill ^18 ^48 ^18 ^34 ^48 ^18 minecraft:red_concrete
execute as @s at @s rotated as @s run fill ^40 ^38 ^32 ^42 ^38 ^32 minecraft:red_concrete
execute as @s at @s rotated as @s run fill ^40 ^22 ^48 ^42 ^22 ^48 minecraft:red_concrete
execute as @s at @s rotated as @s run fill ^-10 ^29 ^57 ^-6 ^29 ^57 minecraft:red_concrete
execute as @s at @s rotated as @s run fill ^-26 ^16 ^57 ^-22 ^16 ^57 minecraft:red_concrete
execute as @s at @s rotated as @s run fill ^-33 ^20 ^28 ^-29 ^20 ^28 minecraft:red_concrete

# === LIFT-HILL CATWALK AND SAFETY LIGHTS ===
execute as @s at @s rotated as @s run setblock ^-2 ^6 ^-28 minecraft:black_concrete
execute as @s at @s rotated as @s run setblock ^-2 ^7 ^-28 minecraft:iron_bars
execute as @s at @s rotated as @s run setblock ^-3 ^7 ^-28 minecraft:sea_lantern
execute as @s at @s rotated as @s run setblock ^-2 ^7 ^-27 minecraft:black_concrete
execute as @s at @s rotated as @s run setblock ^-2 ^8 ^-27 minecraft:iron_bars
execute as @s at @s rotated as @s run setblock ^-2 ^8 ^-26 minecraft:black_concrete
execute as @s at @s rotated as @s run setblock ^-2 ^9 ^-26 minecraft:iron_bars
execute as @s at @s rotated as @s run setblock ^-2 ^9 ^-25 minecraft:black_concrete
execute as @s at @s rotated as @s run setblock ^-2 ^10 ^-25 minecraft:iron_bars
execute as @s at @s rotated as @s run setblock ^-2 ^10 ^-24 minecraft:black_concrete
execute as @s at @s rotated as @s run setblock ^-2 ^11 ^-24 minecraft:iron_bars
execute as @s at @s rotated as @s run setblock ^-2 ^11 ^-23 minecraft:black_concrete
execute as @s at @s rotated as @s run setblock ^-2 ^12 ^-23 minecraft:iron_bars
execute as @s at @s rotated as @s run setblock ^-2 ^12 ^-22 minecraft:black_concrete
execute as @s at @s rotated as @s run setblock ^-2 ^13 ^-22 minecraft:iron_bars
execute as @s at @s rotated as @s run setblock ^-3 ^13 ^-22 minecraft:sea_lantern
execute as @s at @s rotated as @s run setblock ^-2 ^13 ^-21 minecraft:black_concrete
execute as @s at @s rotated as @s run setblock ^-2 ^14 ^-21 minecraft:iron_bars
execute as @s at @s rotated as @s run setblock ^-2 ^14 ^-20 minecraft:black_concrete
execute as @s at @s rotated as @s run setblock ^-2 ^15 ^-20 minecraft:iron_bars
execute as @s at @s rotated as @s run setblock ^-2 ^15 ^-19 minecraft:black_concrete
execute as @s at @s rotated as @s run setblock ^-2 ^16 ^-19 minecraft:iron_bars
execute as @s at @s rotated as @s run setblock ^-2 ^16 ^-18 minecraft:black_concrete
execute as @s at @s rotated as @s run setblock ^-2 ^17 ^-18 minecraft:iron_bars
execute as @s at @s rotated as @s run setblock ^-2 ^17 ^-17 minecraft:black_concrete
execute as @s at @s rotated as @s run setblock ^-2 ^18 ^-17 minecraft:iron_bars
execute as @s at @s rotated as @s run setblock ^-2 ^18 ^-16 minecraft:black_concrete
execute as @s at @s rotated as @s run setblock ^-2 ^19 ^-16 minecraft:iron_bars
execute as @s at @s rotated as @s run setblock ^-3 ^19 ^-16 minecraft:sea_lantern
execute as @s at @s rotated as @s run setblock ^-2 ^19 ^-15 minecraft:black_concrete
execute as @s at @s rotated as @s run setblock ^-2 ^20 ^-15 minecraft:iron_bars
execute as @s at @s rotated as @s run setblock ^-2 ^20 ^-14 minecraft:black_concrete
execute as @s at @s rotated as @s run setblock ^-2 ^21 ^-14 minecraft:iron_bars
execute as @s at @s rotated as @s run setblock ^-2 ^21 ^-13 minecraft:black_concrete
execute as @s at @s rotated as @s run setblock ^-2 ^22 ^-13 minecraft:iron_bars
execute as @s at @s rotated as @s run setblock ^-2 ^22 ^-12 minecraft:black_concrete
execute as @s at @s rotated as @s run setblock ^-2 ^23 ^-12 minecraft:iron_bars
execute as @s at @s rotated as @s run setblock ^-2 ^23 ^-11 minecraft:black_concrete
execute as @s at @s rotated as @s run setblock ^-2 ^24 ^-11 minecraft:iron_bars
execute as @s at @s rotated as @s run setblock ^-2 ^24 ^-10 minecraft:black_concrete
execute as @s at @s rotated as @s run setblock ^-2 ^25 ^-10 minecraft:iron_bars
execute as @s at @s rotated as @s run setblock ^-3 ^25 ^-10 minecraft:sea_lantern
execute as @s at @s rotated as @s run setblock ^-2 ^25 ^-9 minecraft:black_concrete
execute as @s at @s rotated as @s run setblock ^-2 ^26 ^-9 minecraft:iron_bars
execute as @s at @s rotated as @s run setblock ^-2 ^26 ^-8 minecraft:black_concrete
execute as @s at @s rotated as @s run setblock ^-2 ^27 ^-8 minecraft:iron_bars
execute as @s at @s rotated as @s run setblock ^-2 ^27 ^-7 minecraft:black_concrete
execute as @s at @s rotated as @s run setblock ^-2 ^28 ^-7 minecraft:iron_bars
execute as @s at @s rotated as @s run setblock ^-2 ^28 ^-6 minecraft:black_concrete
execute as @s at @s rotated as @s run setblock ^-2 ^29 ^-6 minecraft:iron_bars
execute as @s at @s rotated as @s run setblock ^-2 ^29 ^-5 minecraft:black_concrete
execute as @s at @s rotated as @s run setblock ^-2 ^30 ^-5 minecraft:iron_bars
execute as @s at @s rotated as @s run setblock ^-2 ^30 ^-4 minecraft:black_concrete
execute as @s at @s rotated as @s run setblock ^-2 ^31 ^-4 minecraft:iron_bars
execute as @s at @s rotated as @s run setblock ^-3 ^31 ^-4 minecraft:sea_lantern
execute as @s at @s rotated as @s run setblock ^-2 ^31 ^-3 minecraft:black_concrete
execute as @s at @s rotated as @s run setblock ^-2 ^32 ^-3 minecraft:iron_bars
execute as @s at @s rotated as @s run setblock ^-2 ^32 ^-2 minecraft:black_concrete
execute as @s at @s rotated as @s run setblock ^-2 ^33 ^-2 minecraft:iron_bars
execute as @s at @s rotated as @s run setblock ^-2 ^33 ^-1 minecraft:black_concrete
execute as @s at @s rotated as @s run setblock ^-2 ^34 ^-1 minecraft:iron_bars
execute as @s at @s rotated as @s run setblock ^-2 ^34 ^0 minecraft:black_concrete
execute as @s at @s rotated as @s run setblock ^-2 ^35 ^0 minecraft:iron_bars
execute as @s at @s rotated as @s run setblock ^-2 ^35 ^1 minecraft:black_concrete
execute as @s at @s rotated as @s run setblock ^-2 ^36 ^1 minecraft:iron_bars
execute as @s at @s rotated as @s run setblock ^-2 ^36 ^2 minecraft:black_concrete
execute as @s at @s rotated as @s run setblock ^-2 ^37 ^2 minecraft:iron_bars
execute as @s at @s rotated as @s run setblock ^-3 ^37 ^2 minecraft:sea_lantern
execute as @s at @s rotated as @s run setblock ^-2 ^37 ^3 minecraft:black_concrete
execute as @s at @s rotated as @s run setblock ^-2 ^38 ^3 minecraft:iron_bars
execute as @s at @s rotated as @s run setblock ^-2 ^38 ^4 minecraft:black_concrete
execute as @s at @s rotated as @s run setblock ^-2 ^39 ^4 minecraft:iron_bars
execute as @s at @s rotated as @s run setblock ^-2 ^39 ^5 minecraft:black_concrete
execute as @s at @s rotated as @s run setblock ^-2 ^40 ^5 minecraft:iron_bars
execute as @s at @s rotated as @s run setblock ^-2 ^40 ^6 minecraft:black_concrete
execute as @s at @s rotated as @s run setblock ^-2 ^41 ^6 minecraft:iron_bars
execute as @s at @s rotated as @s run setblock ^-2 ^41 ^7 minecraft:black_concrete
execute as @s at @s rotated as @s run setblock ^-2 ^42 ^7 minecraft:iron_bars
execute as @s at @s rotated as @s run setblock ^-2 ^42 ^8 minecraft:black_concrete
execute as @s at @s rotated as @s run setblock ^-2 ^43 ^8 minecraft:iron_bars
execute as @s at @s rotated as @s run setblock ^-3 ^43 ^8 minecraft:sea_lantern
execute as @s at @s rotated as @s run setblock ^-2 ^43 ^9 minecraft:black_concrete
execute as @s at @s rotated as @s run setblock ^-2 ^44 ^9 minecraft:iron_bars
execute as @s at @s rotated as @s run setblock ^-2 ^44 ^10 minecraft:black_concrete
execute as @s at @s rotated as @s run setblock ^-2 ^45 ^10 minecraft:iron_bars
execute as @s at @s rotated as @s run setblock ^-2 ^45 ^11 minecraft:black_concrete
execute as @s at @s rotated as @s run setblock ^-2 ^46 ^11 minecraft:iron_bars
execute as @s at @s rotated as @s run setblock ^-2 ^46 ^12 minecraft:black_concrete
execute as @s at @s rotated as @s run setblock ^-2 ^47 ^12 minecraft:iron_bars
execute as @s at @s rotated as @s run setblock ^-2 ^47 ^13 minecraft:black_concrete
execute as @s at @s rotated as @s run setblock ^-2 ^48 ^13 minecraft:iron_bars
execute as @s at @s rotated as @s run setblock ^-2 ^48 ^14 minecraft:black_concrete
execute as @s at @s rotated as @s run setblock ^-2 ^49 ^14 minecraft:iron_bars
execute as @s at @s rotated as @s run setblock ^-3 ^49 ^14 minecraft:sea_lantern
execute as @s at @s rotated as @s run setblock ^-2 ^49 ^15 minecraft:black_concrete
execute as @s at @s rotated as @s run setblock ^-2 ^50 ^15 minecraft:iron_bars
execute as @s at @s rotated as @s run setblock ^0 ^52 ^15 minecraft:sea_lantern
execute as @s at @s rotated as @s run setblock ^10 ^52 ^20 minecraft:sea_lantern
execute as @s at @s rotated as @s run setblock ^20 ^52 ^20 minecraft:sea_lantern
execute as @s at @s rotated as @s run setblock ^30 ^52 ^20 minecraft:sea_lantern
execute as @s at @s rotated as @s run setblock ^40 ^52 ^20 minecraft:sea_lantern
execute as @s at @s rotated as @s run setblock ^42 ^43 ^28 minecraft:sea_lantern
execute as @s at @s rotated as @s run setblock ^42 ^35 ^36 minecraft:sea_lantern
execute as @s at @s rotated as @s run setblock ^42 ^27 ^44 minecraft:sea_lantern
execute as @s at @s rotated as @s run setblock ^42 ^19 ^52 minecraft:sea_lantern
execute as @s at @s rotated as @s run setblock ^-1 ^34 ^59 minecraft:sea_lantern
execute as @s at @s rotated as @s run setblock ^-20 ^24 ^59 minecraft:sea_lantern
execute as @s at @s rotated as @s run setblock ^-31 ^27 ^22 minecraft:sea_lantern
execute as @s at @s rotated as @s run setblock ^-31 ^20 ^29 minecraft:sea_lantern
execute as @s at @s rotated as @s run setblock ^-46 ^7 ^-10 minecraft:sea_lantern
execute as @s at @s rotated as @s run setblock ^-46 ^7 ^-30 minecraft:sea_lantern

# === TRACK BED AND POWERED CLOSED CIRCUIT ===
execute as @s at @s rotated as @s run setblock ^0 ^5 ^-48 minecraft:redstone_block
execute as @s at @s rotated as @s run setblock ^0 ^5 ^-47 minecraft:redstone_block
execute as @s at @s rotated as @s run setblock ^0 ^5 ^-46 minecraft:red_concrete
execute as @s at @s rotated as @s run setblock ^0 ^5 ^-45 minecraft:red_concrete
execute as @s at @s rotated as @s run setblock ^0 ^5 ^-44 minecraft:red_concrete
execute as @s at @s rotated as @s run setblock ^0 ^5 ^-43 minecraft:redstone_block
execute as @s at @s rotated as @s run setblock ^0 ^5 ^-42 minecraft:red_concrete
execute as @s at @s rotated as @s run setblock ^0 ^5 ^-41 minecraft:redstone_block
execute as @s at @s rotated as @s run setblock ^0 ^5 ^-40 minecraft:red_concrete
execute as @s at @s rotated as @s run setblock ^0 ^5 ^-39 minecraft:redstone_block
execute as @s at @s rotated as @s run setblock ^0 ^5 ^-38 minecraft:red_concrete
execute as @s at @s rotated as @s run setblock ^0 ^5 ^-37 minecraft:red_concrete
execute as @s at @s rotated as @s run setblock ^0 ^5 ^-36 minecraft:red_concrete
execute as @s at @s rotated as @s run setblock ^0 ^5 ^-35 minecraft:redstone_block
execute as @s at @s rotated as @s run setblock ^0 ^5 ^-34 minecraft:redstone_block
execute as @s at @s rotated as @s run setblock ^0 ^5 ^-33 minecraft:red_concrete
execute as @s at @s rotated as @s run setblock ^0 ^5 ^-32 minecraft:red_concrete
execute as @s at @s rotated as @s run setblock ^0 ^5 ^-31 minecraft:redstone_block
execute as @s at @s rotated as @s run setblock ^0 ^5 ^-30 minecraft:red_concrete
execute as @s at @s rotated as @s run setblock ^0 ^6 ^-29 minecraft:red_concrete
execute as @s at @s rotated as @s run setblock ^0 ^7 ^-28 minecraft:red_concrete
execute as @s at @s rotated as @s run setblock ^0 ^8 ^-27 minecraft:redstone_block
execute as @s at @s rotated as @s run setblock ^0 ^9 ^-26 minecraft:red_concrete
execute as @s at @s rotated as @s run setblock ^0 ^10 ^-25 minecraft:red_concrete
execute as @s at @s rotated as @s run setblock ^0 ^11 ^-24 minecraft:red_concrete
execute as @s at @s rotated as @s run setblock ^0 ^12 ^-23 minecraft:red_concrete
execute as @s at @s rotated as @s run setblock ^0 ^13 ^-22 minecraft:red_concrete
execute as @s at @s rotated as @s run setblock ^0 ^14 ^-21 minecraft:red_concrete
execute as @s at @s rotated as @s run setblock ^0 ^15 ^-20 minecraft:redstone_block
execute as @s at @s rotated as @s run setblock ^0 ^16 ^-19 minecraft:red_concrete
execute as @s at @s rotated as @s run setblock ^0 ^17 ^-18 minecraft:red_concrete
execute as @s at @s rotated as @s run setblock ^0 ^18 ^-17 minecraft:red_concrete
execute as @s at @s rotated as @s run setblock ^0 ^19 ^-16 minecraft:red_concrete
execute as @s at @s rotated as @s run setblock ^0 ^20 ^-15 minecraft:red_concrete
execute as @s at @s rotated as @s run setblock ^0 ^21 ^-14 minecraft:red_concrete
execute as @s at @s rotated as @s run setblock ^0 ^22 ^-13 minecraft:redstone_block
execute as @s at @s rotated as @s run setblock ^0 ^23 ^-12 minecraft:red_concrete
execute as @s at @s rotated as @s run setblock ^0 ^24 ^-11 minecraft:red_concrete
execute as @s at @s rotated as @s run setblock ^0 ^25 ^-10 minecraft:red_concrete
execute as @s at @s rotated as @s run setblock ^0 ^26 ^-9 minecraft:red_concrete
execute as @s at @s rotated as @s run setblock ^0 ^27 ^-8 minecraft:red_concrete
execute as @s at @s rotated as @s run setblock ^0 ^28 ^-7 minecraft:red_concrete
execute as @s at @s rotated as @s run setblock ^0 ^29 ^-6 minecraft:redstone_block
execute as @s at @s rotated as @s run setblock ^0 ^30 ^-5 minecraft:red_concrete
execute as @s at @s rotated as @s run setblock ^0 ^31 ^-4 minecraft:red_concrete
execute as @s at @s rotated as @s run setblock ^0 ^32 ^-3 minecraft:red_concrete
execute as @s at @s rotated as @s run setblock ^0 ^33 ^-2 minecraft:red_concrete
execute as @s at @s rotated as @s run setblock ^0 ^34 ^-1 minecraft:red_concrete
execute as @s at @s rotated as @s run setblock ^0 ^35 ^0 minecraft:red_concrete
execute as @s at @s rotated as @s run setblock ^0 ^36 ^1 minecraft:redstone_block
execute as @s at @s rotated as @s run setblock ^0 ^37 ^2 minecraft:red_concrete
execute as @s at @s rotated as @s run setblock ^0 ^38 ^3 minecraft:red_concrete
execute as @s at @s rotated as @s run setblock ^0 ^39 ^4 minecraft:red_concrete
execute as @s at @s rotated as @s run setblock ^0 ^40 ^5 minecraft:red_concrete
execute as @s at @s rotated as @s run setblock ^0 ^41 ^6 minecraft:red_concrete
execute as @s at @s rotated as @s run setblock ^0 ^42 ^7 minecraft:red_concrete
execute as @s at @s rotated as @s run setblock ^0 ^43 ^8 minecraft:redstone_block
execute as @s at @s rotated as @s run setblock ^0 ^44 ^9 minecraft:red_concrete
execute as @s at @s rotated as @s run setblock ^0 ^45 ^10 minecraft:red_concrete
execute as @s at @s rotated as @s run setblock ^0 ^46 ^11 minecraft:red_concrete
execute as @s at @s rotated as @s run setblock ^0 ^47 ^12 minecraft:red_concrete
execute as @s at @s rotated as @s run setblock ^0 ^48 ^13 minecraft:red_concrete
execute as @s at @s rotated as @s run setblock ^0 ^49 ^14 minecraft:red_concrete
execute as @s at @s rotated as @s run setblock ^0 ^50 ^15 minecraft:redstone_block
execute as @s at @s rotated as @s run setblock ^0 ^50 ^16 minecraft:red_concrete
execute as @s at @s rotated as @s run setblock ^0 ^50 ^17 minecraft:red_concrete
execute as @s at @s rotated as @s run setblock ^0 ^50 ^18 minecraft:red_concrete
execute as @s at @s rotated as @s run setblock ^0 ^50 ^19 minecraft:red_concrete
execute as @s at @s rotated as @s run setblock ^0 ^50 ^20 minecraft:red_concrete
execute as @s at @s rotated as @s run setblock ^1 ^50 ^20 minecraft:red_concrete
execute as @s at @s rotated as @s run setblock ^2 ^50 ^20 minecraft:redstone_block
execute as @s at @s rotated as @s run setblock ^3 ^50 ^20 minecraft:red_concrete
execute as @s at @s rotated as @s run setblock ^4 ^50 ^20 minecraft:red_concrete
execute as @s at @s rotated as @s run setblock ^5 ^50 ^20 minecraft:red_concrete
execute as @s at @s rotated as @s run setblock ^6 ^50 ^20 minecraft:red_concrete
execute as @s at @s rotated as @s run setblock ^7 ^50 ^20 minecraft:red_concrete
execute as @s at @s rotated as @s run setblock ^8 ^50 ^20 minecraft:red_concrete
execute as @s at @s rotated as @s run setblock ^9 ^50 ^20 minecraft:redstone_block
execute as @s at @s rotated as @s run setblock ^10 ^50 ^20 minecraft:red_concrete
execute as @s at @s rotated as @s run setblock ^11 ^50 ^20 minecraft:red_concrete
execute as @s at @s rotated as @s run setblock ^12 ^50 ^20 minecraft:red_concrete
execute as @s at @s rotated as @s run setblock ^13 ^50 ^20 minecraft:red_concrete
execute as @s at @s rotated as @s run setblock ^14 ^50 ^20 minecraft:red_concrete
execute as @s at @s rotated as @s run setblock ^15 ^50 ^20 minecraft:red_concrete
execute as @s at @s rotated as @s run setblock ^16 ^50 ^20 minecraft:redstone_block
execute as @s at @s rotated as @s run setblock ^17 ^50 ^20 minecraft:red_concrete
execute as @s at @s rotated as @s run setblock ^18 ^50 ^20 minecraft:red_concrete
execute as @s at @s rotated as @s run setblock ^19 ^50 ^20 minecraft:red_concrete
execute as @s at @s rotated as @s run setblock ^20 ^50 ^20 minecraft:red_concrete
execute as @s at @s rotated as @s run setblock ^21 ^50 ^20 minecraft:red_concrete
execute as @s at @s rotated as @s run setblock ^22 ^50 ^20 minecraft:red_concrete
execute as @s at @s rotated as @s run setblock ^23 ^50 ^20 minecraft:redstone_block
execute as @s at @s rotated as @s run setblock ^24 ^50 ^20 minecraft:red_concrete
execute as @s at @s rotated as @s run setblock ^25 ^50 ^20 minecraft:red_concrete
execute as @s at @s rotated as @s run setblock ^26 ^50 ^20 minecraft:red_concrete
execute as @s at @s rotated as @s run setblock ^27 ^50 ^20 minecraft:red_concrete
execute as @s at @s rotated as @s run setblock ^28 ^50 ^20 minecraft:red_concrete
execute as @s at @s rotated as @s run setblock ^29 ^50 ^20 minecraft:red_concrete
execute as @s at @s rotated as @s run setblock ^30 ^50 ^20 minecraft:redstone_block
execute as @s at @s rotated as @s run setblock ^31 ^50 ^20 minecraft:red_concrete
execute as @s at @s rotated as @s run setblock ^32 ^50 ^20 minecraft:red_concrete
execute as @s at @s rotated as @s run setblock ^33 ^50 ^20 minecraft:red_concrete
execute as @s at @s rotated as @s run setblock ^34 ^50 ^20 minecraft:red_concrete
execute as @s at @s rotated as @s run setblock ^35 ^50 ^20 minecraft:red_concrete
execute as @s at @s rotated as @s run setblock ^36 ^50 ^20 minecraft:red_concrete
execute as @s at @s rotated as @s run setblock ^37 ^50 ^20 minecraft:redstone_block
execute as @s at @s rotated as @s run setblock ^38 ^50 ^20 minecraft:red_concrete
execute as @s at @s rotated as @s run setblock ^39 ^50 ^20 minecraft:red_concrete
execute as @s at @s rotated as @s run setblock ^40 ^50 ^20 minecraft:red_concrete
execute as @s at @s rotated as @s run setblock ^41 ^50 ^20 minecraft:red_concrete
execute as @s at @s rotated as @s run setblock ^42 ^50 ^20 minecraft:red_concrete
execute as @s at @s rotated as @s run setblock ^42 ^49 ^21 minecraft:red_concrete
execute as @s at @s rotated as @s run setblock ^42 ^48 ^22 minecraft:redstone_block
execute as @s at @s rotated as @s run setblock ^42 ^47 ^23 minecraft:red_concrete
execute as @s at @s rotated as @s run setblock ^42 ^46 ^24 minecraft:red_concrete
execute as @s at @s rotated as @s run setblock ^42 ^45 ^25 minecraft:red_concrete
execute as @s at @s rotated as @s run setblock ^42 ^44 ^26 minecraft:red_concrete
execute as @s at @s rotated as @s run setblock ^42 ^43 ^27 minecraft:red_concrete
execute as @s at @s rotated as @s run setblock ^42 ^42 ^28 minecraft:red_concrete
execute as @s at @s rotated as @s run setblock ^42 ^41 ^29 minecraft:redstone_block
execute as @s at @s rotated as @s run setblock ^42 ^40 ^30 minecraft:red_concrete
execute as @s at @s rotated as @s run setblock ^42 ^39 ^31 minecraft:red_concrete
execute as @s at @s rotated as @s run setblock ^42 ^38 ^32 minecraft:red_concrete
execute as @s at @s rotated as @s run setblock ^42 ^37 ^33 minecraft:red_concrete
execute as @s at @s rotated as @s run setblock ^42 ^36 ^34 minecraft:red_concrete
execute as @s at @s rotated as @s run setblock ^42 ^35 ^35 minecraft:red_concrete
execute as @s at @s rotated as @s run setblock ^42 ^34 ^36 minecraft:redstone_block
execute as @s at @s rotated as @s run setblock ^42 ^33 ^37 minecraft:red_concrete
execute as @s at @s rotated as @s run setblock ^42 ^32 ^38 minecraft:red_concrete
execute as @s at @s rotated as @s run setblock ^42 ^31 ^39 minecraft:red_concrete
execute as @s at @s rotated as @s run setblock ^42 ^30 ^40 minecraft:red_concrete
execute as @s at @s rotated as @s run setblock ^42 ^29 ^41 minecraft:red_concrete
execute as @s at @s rotated as @s run setblock ^42 ^28 ^42 minecraft:red_concrete
execute as @s at @s rotated as @s run setblock ^42 ^27 ^43 minecraft:redstone_block
execute as @s at @s rotated as @s run setblock ^42 ^26 ^44 minecraft:red_concrete
execute as @s at @s rotated as @s run setblock ^42 ^25 ^45 minecraft:red_concrete
execute as @s at @s rotated as @s run setblock ^42 ^24 ^46 minecraft:red_concrete
execute as @s at @s rotated as @s run setblock ^42 ^23 ^47 minecraft:red_concrete
execute as @s at @s rotated as @s run setblock ^42 ^22 ^48 minecraft:red_concrete
execute as @s at @s rotated as @s run setblock ^42 ^21 ^49 minecraft:red_concrete
execute as @s at @s rotated as @s run setblock ^42 ^20 ^50 minecraft:redstone_block
execute as @s at @s rotated as @s run setblock ^42 ^19 ^51 minecraft:red_concrete
execute as @s at @s rotated as @s run setblock ^42 ^18 ^52 minecraft:red_concrete
execute as @s at @s rotated as @s run setblock ^42 ^17 ^53 minecraft:red_concrete
execute as @s at @s rotated as @s run setblock ^42 ^16 ^54 minecraft:red_concrete
execute as @s at @s rotated as @s run setblock ^42 ^15 ^55 minecraft:red_concrete
execute as @s at @s rotated as @s run setblock ^42 ^14 ^56 minecraft:red_concrete
execute as @s at @s rotated as @s run setblock ^42 ^13 ^57 minecraft:redstone_block
execute as @s at @s rotated as @s run setblock ^42 ^12 ^58 minecraft:red_concrete
execute as @s at @s rotated as @s run setblock ^42 ^12 ^59 minecraft:red_concrete
execute as @s at @s rotated as @s run setblock ^41 ^12 ^59 minecraft:red_concrete
execute as @s at @s rotated as @s run setblock ^40 ^12 ^59 minecraft:red_concrete
execute as @s at @s rotated as @s run setblock ^39 ^12 ^59 minecraft:red_concrete
execute as @s at @s rotated as @s run setblock ^38 ^12 ^59 minecraft:red_concrete
execute as @s at @s rotated as @s run setblock ^37 ^12 ^59 minecraft:redstone_block
execute as @s at @s rotated as @s run setblock ^36 ^12 ^59 minecraft:red_concrete
execute as @s at @s rotated as @s run setblock ^35 ^12 ^59 minecraft:red_concrete
execute as @s at @s rotated as @s run setblock ^34 ^12 ^59 minecraft:red_concrete
execute as @s at @s rotated as @s run setblock ^33 ^12 ^59 minecraft:red_concrete
execute as @s at @s rotated as @s run setblock ^32 ^12 ^59 minecraft:red_concrete
execute as @s at @s rotated as @s run setblock ^31 ^12 ^59 minecraft:red_concrete
execute as @s at @s rotated as @s run setblock ^30 ^12 ^59 minecraft:redstone_block
execute as @s at @s rotated as @s run setblock ^29 ^12 ^59 minecraft:red_concrete
execute as @s at @s rotated as @s run setblock ^28 ^12 ^59 minecraft:red_concrete
execute as @s at @s rotated as @s run setblock ^27 ^12 ^59 minecraft:red_concrete
execute as @s at @s rotated as @s run setblock ^26 ^12 ^59 minecraft:red_concrete
execute as @s at @s rotated as @s run setblock ^25 ^12 ^59 minecraft:red_concrete
execute as @s at @s rotated as @s run setblock ^24 ^12 ^59 minecraft:red_concrete
execute as @s at @s rotated as @s run setblock ^23 ^12 ^59 minecraft:redstone_block
execute as @s at @s rotated as @s run setblock ^22 ^12 ^59 minecraft:red_concrete
execute as @s at @s rotated as @s run setblock ^21 ^12 ^59 minecraft:red_concrete
execute as @s at @s rotated as @s run setblock ^20 ^12 ^59 minecraft:red_concrete
execute as @s at @s rotated as @s run setblock ^19 ^12 ^59 minecraft:red_concrete
execute as @s at @s rotated as @s run setblock ^18 ^12 ^59 minecraft:red_concrete
execute as @s at @s rotated as @s run setblock ^17 ^12 ^59 minecraft:red_concrete
execute as @s at @s rotated as @s run setblock ^16 ^12 ^59 minecraft:redstone_block
execute as @s at @s rotated as @s run setblock ^15 ^12 ^59 minecraft:red_concrete
execute as @s at @s rotated as @s run setblock ^14 ^12 ^59 minecraft:red_concrete
execute as @s at @s rotated as @s run setblock ^13 ^12 ^59 minecraft:red_concrete
execute as @s at @s rotated as @s run setblock ^12 ^12 ^59 minecraft:red_concrete
execute as @s at @s rotated as @s run setblock ^11 ^12 ^59 minecraft:red_concrete
execute as @s at @s rotated as @s run setblock ^10 ^12 ^59 minecraft:red_concrete
execute as @s at @s rotated as @s run setblock ^9 ^13 ^59 minecraft:redstone_block
execute as @s at @s rotated as @s run setblock ^8 ^14 ^59 minecraft:red_concrete
execute as @s at @s rotated as @s run setblock ^7 ^15 ^59 minecraft:red_concrete
execute as @s at @s rotated as @s run setblock ^6 ^16 ^59 minecraft:red_concrete
execute as @s at @s rotated as @s run setblock ^5 ^17 ^59 minecraft:red_concrete
execute as @s at @s rotated as @s run setblock ^4 ^18 ^59 minecraft:red_concrete
execute as @s at @s rotated as @s run setblock ^3 ^19 ^59 minecraft:red_concrete
execute as @s at @s rotated as @s run setblock ^2 ^20 ^59 minecraft:redstone_block
execute as @s at @s rotated as @s run setblock ^1 ^21 ^59 minecraft:red_concrete
execute as @s at @s rotated as @s run setblock ^0 ^22 ^59 minecraft:red_concrete
execute as @s at @s rotated as @s run setblock ^-1 ^23 ^59 minecraft:red_concrete
execute as @s at @s rotated as @s run setblock ^-2 ^24 ^59 minecraft:red_concrete
execute as @s at @s rotated as @s run setblock ^-3 ^25 ^59 minecraft:red_concrete
execute as @s at @s rotated as @s run setblock ^-4 ^26 ^59 minecraft:red_concrete
execute as @s at @s rotated as @s run setblock ^-5 ^27 ^59 minecraft:redstone_block
execute as @s at @s rotated as @s run setblock ^-6 ^28 ^59 minecraft:red_concrete
execute as @s at @s rotated as @s run setblock ^-7 ^29 ^59 minecraft:red_concrete
execute as @s at @s rotated as @s run setblock ^-8 ^30 ^59 minecraft:red_concrete
execute as @s at @s rotated as @s run setblock ^-9 ^31 ^59 minecraft:red_concrete
execute as @s at @s rotated as @s run setblock ^-10 ^32 ^59 minecraft:red_concrete
execute as @s at @s rotated as @s run setblock ^-11 ^31 ^59 minecraft:red_concrete
execute as @s at @s rotated as @s run setblock ^-12 ^30 ^59 minecraft:redstone_block
execute as @s at @s rotated as @s run setblock ^-13 ^29 ^59 minecraft:red_concrete
execute as @s at @s rotated as @s run setblock ^-14 ^28 ^59 minecraft:red_concrete
execute as @s at @s rotated as @s run setblock ^-15 ^27 ^59 minecraft:red_concrete
execute as @s at @s rotated as @s run setblock ^-16 ^26 ^59 minecraft:red_concrete
execute as @s at @s rotated as @s run setblock ^-17 ^25 ^59 minecraft:red_concrete
execute as @s at @s rotated as @s run setblock ^-18 ^24 ^59 minecraft:red_concrete
execute as @s at @s rotated as @s run setblock ^-19 ^23 ^59 minecraft:redstone_block
execute as @s at @s rotated as @s run setblock ^-20 ^22 ^59 minecraft:red_concrete
execute as @s at @s rotated as @s run setblock ^-21 ^21 ^59 minecraft:red_concrete
execute as @s at @s rotated as @s run setblock ^-22 ^20 ^59 minecraft:red_concrete
execute as @s at @s rotated as @s run setblock ^-23 ^19 ^59 minecraft:red_concrete
execute as @s at @s rotated as @s run setblock ^-24 ^18 ^59 minecraft:red_concrete
execute as @s at @s rotated as @s run setblock ^-25 ^17 ^59 minecraft:red_concrete
execute as @s at @s rotated as @s run setblock ^-26 ^16 ^59 minecraft:redstone_block
execute as @s at @s rotated as @s run setblock ^-27 ^15 ^59 minecraft:red_concrete
execute as @s at @s rotated as @s run setblock ^-28 ^14 ^59 minecraft:red_concrete
execute as @s at @s rotated as @s run setblock ^-29 ^13 ^59 minecraft:red_concrete
execute as @s at @s rotated as @s run setblock ^-30 ^12 ^59 minecraft:red_concrete
execute as @s at @s rotated as @s run setblock ^-31 ^12 ^59 minecraft:red_concrete
execute as @s at @s rotated as @s run setblock ^-31 ^12 ^58 minecraft:red_concrete
execute as @s at @s rotated as @s run setblock ^-31 ^12 ^57 minecraft:redstone_block
execute as @s at @s rotated as @s run setblock ^-31 ^12 ^56 minecraft:red_concrete
execute as @s at @s rotated as @s run setblock ^-31 ^12 ^55 minecraft:red_concrete
execute as @s at @s rotated as @s run setblock ^-31 ^12 ^54 minecraft:red_concrete
execute as @s at @s rotated as @s run setblock ^-31 ^12 ^53 minecraft:red_concrete
execute as @s at @s rotated as @s run setblock ^-31 ^12 ^52 minecraft:red_concrete
execute as @s at @s rotated as @s run setblock ^-31 ^12 ^51 minecraft:red_concrete
execute as @s at @s rotated as @s run setblock ^-31 ^12 ^50 minecraft:redstone_block
execute as @s at @s rotated as @s run setblock ^-31 ^12 ^49 minecraft:red_concrete
execute as @s at @s rotated as @s run setblock ^-31 ^12 ^48 minecraft:red_concrete
execute as @s at @s rotated as @s run setblock ^-31 ^12 ^47 minecraft:red_concrete
execute as @s at @s rotated as @s run setblock ^-31 ^12 ^46 minecraft:red_concrete
execute as @s at @s rotated as @s run setblock ^-31 ^12 ^45 minecraft:red_concrete
execute as @s at @s rotated as @s run setblock ^-31 ^12 ^44 minecraft:red_concrete
execute as @s at @s rotated as @s run setblock ^-31 ^12 ^43 minecraft:redstone_block
execute as @s at @s rotated as @s run setblock ^-31 ^12 ^42 minecraft:red_concrete
execute as @s at @s rotated as @s run setblock ^-31 ^12 ^41 minecraft:red_concrete
execute as @s at @s rotated as @s run setblock ^-31 ^12 ^40 minecraft:red_concrete
execute as @s at @s rotated as @s run setblock ^-31 ^12 ^39 minecraft:red_concrete
execute as @s at @s rotated as @s run setblock ^-31 ^12 ^38 minecraft:red_concrete
execute as @s at @s rotated as @s run setblock ^-31 ^12 ^37 minecraft:red_concrete
execute as @s at @s rotated as @s run setblock ^-31 ^12 ^36 minecraft:redstone_block
execute as @s at @s rotated as @s run setblock ^-31 ^12 ^35 minecraft:red_concrete
execute as @s at @s rotated as @s run setblock ^-31 ^13 ^34 minecraft:red_concrete
execute as @s at @s rotated as @s run setblock ^-31 ^14 ^33 minecraft:red_concrete
execute as @s at @s rotated as @s run setblock ^-31 ^15 ^32 minecraft:red_concrete
execute as @s at @s rotated as @s run setblock ^-31 ^16 ^31 minecraft:red_concrete
execute as @s at @s rotated as @s run setblock ^-31 ^17 ^30 minecraft:red_concrete
execute as @s at @s rotated as @s run setblock ^-31 ^18 ^29 minecraft:redstone_block
execute as @s at @s rotated as @s run setblock ^-31 ^19 ^28 minecraft:red_concrete
execute as @s at @s rotated as @s run setblock ^-31 ^20 ^27 minecraft:red_concrete
execute as @s at @s rotated as @s run setblock ^-31 ^21 ^26 minecraft:red_concrete
execute as @s at @s rotated as @s run setblock ^-31 ^22 ^25 minecraft:red_concrete
execute as @s at @s rotated as @s run setblock ^-31 ^23 ^24 minecraft:red_concrete
execute as @s at @s rotated as @s run setblock ^-31 ^24 ^23 minecraft:red_concrete
execute as @s at @s rotated as @s run setblock ^-31 ^25 ^22 minecraft:redstone_block
execute as @s at @s rotated as @s run setblock ^-31 ^24 ^21 minecraft:red_concrete
execute as @s at @s rotated as @s run setblock ^-31 ^23 ^20 minecraft:red_concrete
execute as @s at @s rotated as @s run setblock ^-31 ^22 ^19 minecraft:red_concrete
execute as @s at @s rotated as @s run setblock ^-31 ^21 ^18 minecraft:red_concrete
execute as @s at @s rotated as @s run setblock ^-31 ^20 ^17 minecraft:red_concrete
execute as @s at @s rotated as @s run setblock ^-31 ^19 ^16 minecraft:red_concrete
execute as @s at @s rotated as @s run setblock ^-31 ^18 ^15 minecraft:redstone_block
execute as @s at @s rotated as @s run setblock ^-31 ^17 ^14 minecraft:red_concrete
execute as @s at @s rotated as @s run setblock ^-31 ^16 ^13 minecraft:red_concrete
execute as @s at @s rotated as @s run setblock ^-31 ^15 ^12 minecraft:red_concrete
execute as @s at @s rotated as @s run setblock ^-31 ^14 ^11 minecraft:red_concrete
execute as @s at @s rotated as @s run setblock ^-31 ^13 ^10 minecraft:red_concrete
execute as @s at @s rotated as @s run setblock ^-31 ^12 ^9 minecraft:red_concrete
execute as @s at @s rotated as @s run setblock ^-31 ^12 ^8 minecraft:red_concrete
execute as @s at @s rotated as @s run setblock ^-32 ^12 ^8 minecraft:red_concrete
execute as @s at @s rotated as @s run setblock ^-33 ^12 ^8 minecraft:red_concrete
execute as @s at @s rotated as @s run setblock ^-34 ^12 ^8 minecraft:red_concrete
execute as @s at @s rotated as @s run setblock ^-35 ^12 ^8 minecraft:red_concrete
execute as @s at @s rotated as @s run setblock ^-36 ^12 ^8 minecraft:red_concrete
execute as @s at @s rotated as @s run setblock ^-37 ^12 ^8 minecraft:red_concrete
execute as @s at @s rotated as @s run setblock ^-38 ^12 ^8 minecraft:redstone_block
execute as @s at @s rotated as @s run setblock ^-39 ^12 ^8 minecraft:red_concrete
execute as @s at @s rotated as @s run setblock ^-40 ^12 ^8 minecraft:red_concrete
execute as @s at @s rotated as @s run setblock ^-41 ^12 ^8 minecraft:red_concrete
execute as @s at @s rotated as @s run setblock ^-42 ^12 ^8 minecraft:red_concrete
execute as @s at @s rotated as @s run setblock ^-43 ^12 ^8 minecraft:red_concrete
execute as @s at @s rotated as @s run setblock ^-44 ^12 ^8 minecraft:red_concrete
execute as @s at @s rotated as @s run setblock ^-45 ^12 ^8 minecraft:redstone_block
execute as @s at @s rotated as @s run setblock ^-46 ^12 ^8 minecraft:red_concrete
execute as @s at @s rotated as @s run setblock ^-46 ^11 ^7 minecraft:red_concrete
execute as @s at @s rotated as @s run setblock ^-46 ^10 ^6 minecraft:red_concrete
execute as @s at @s rotated as @s run setblock ^-46 ^9 ^5 minecraft:red_concrete
execute as @s at @s rotated as @s run setblock ^-46 ^8 ^4 minecraft:red_concrete
execute as @s at @s rotated as @s run setblock ^-46 ^7 ^3 minecraft:red_concrete
execute as @s at @s rotated as @s run setblock ^-46 ^6 ^2 minecraft:redstone_block
execute as @s at @s rotated as @s run setblock ^-46 ^5 ^1 minecraft:red_concrete
execute as @s at @s rotated as @s run setblock ^-46 ^5 ^0 minecraft:red_concrete
execute as @s at @s rotated as @s run setblock ^-46 ^5 ^-1 minecraft:red_concrete
execute as @s at @s rotated as @s run setblock ^-46 ^5 ^-2 minecraft:red_concrete
execute as @s at @s rotated as @s run setblock ^-46 ^5 ^-3 minecraft:red_concrete
execute as @s at @s rotated as @s run setblock ^-46 ^5 ^-4 minecraft:red_concrete
execute as @s at @s rotated as @s run setblock ^-46 ^5 ^-5 minecraft:redstone_block
execute as @s at @s rotated as @s run setblock ^-46 ^5 ^-6 minecraft:red_concrete
execute as @s at @s rotated as @s run setblock ^-46 ^5 ^-7 minecraft:red_concrete
execute as @s at @s rotated as @s run setblock ^-46 ^5 ^-8 minecraft:red_concrete
execute as @s at @s rotated as @s run setblock ^-46 ^5 ^-9 minecraft:red_concrete
execute as @s at @s rotated as @s run setblock ^-46 ^5 ^-10 minecraft:red_concrete
execute as @s at @s rotated as @s run setblock ^-46 ^5 ^-11 minecraft:red_concrete
execute as @s at @s rotated as @s run setblock ^-46 ^5 ^-12 minecraft:redstone_block
execute as @s at @s rotated as @s run setblock ^-46 ^5 ^-13 minecraft:red_concrete
execute as @s at @s rotated as @s run setblock ^-46 ^5 ^-14 minecraft:red_concrete
execute as @s at @s rotated as @s run setblock ^-46 ^5 ^-15 minecraft:red_concrete
execute as @s at @s rotated as @s run setblock ^-46 ^5 ^-16 minecraft:red_concrete
execute as @s at @s rotated as @s run setblock ^-46 ^5 ^-17 minecraft:red_concrete
execute as @s at @s rotated as @s run setblock ^-46 ^5 ^-18 minecraft:red_concrete
execute as @s at @s rotated as @s run setblock ^-46 ^5 ^-19 minecraft:redstone_block
execute as @s at @s rotated as @s run setblock ^-46 ^5 ^-20 minecraft:red_concrete
execute as @s at @s rotated as @s run setblock ^-46 ^5 ^-21 minecraft:red_concrete
execute as @s at @s rotated as @s run setblock ^-46 ^5 ^-22 minecraft:red_concrete
execute as @s at @s rotated as @s run setblock ^-46 ^5 ^-23 minecraft:red_concrete
execute as @s at @s rotated as @s run setblock ^-46 ^5 ^-24 minecraft:red_concrete
execute as @s at @s rotated as @s run setblock ^-46 ^5 ^-25 minecraft:red_concrete
execute as @s at @s rotated as @s run setblock ^-46 ^5 ^-26 minecraft:redstone_block
execute as @s at @s rotated as @s run setblock ^-46 ^5 ^-27 minecraft:red_concrete
execute as @s at @s rotated as @s run setblock ^-46 ^5 ^-28 minecraft:red_concrete
execute as @s at @s rotated as @s run setblock ^-46 ^5 ^-29 minecraft:red_concrete
execute as @s at @s rotated as @s run setblock ^-46 ^5 ^-30 minecraft:red_concrete
execute as @s at @s rotated as @s run setblock ^-46 ^5 ^-31 minecraft:red_concrete
execute as @s at @s rotated as @s run setblock ^-46 ^5 ^-32 minecraft:red_concrete
execute as @s at @s rotated as @s run setblock ^-46 ^5 ^-33 minecraft:redstone_block
execute as @s at @s rotated as @s run setblock ^-46 ^5 ^-34 minecraft:red_concrete
execute as @s at @s rotated as @s run setblock ^-46 ^5 ^-35 minecraft:red_concrete
execute as @s at @s rotated as @s run setblock ^-46 ^5 ^-36 minecraft:red_concrete
execute as @s at @s rotated as @s run setblock ^-46 ^5 ^-37 minecraft:red_concrete
execute as @s at @s rotated as @s run setblock ^-46 ^5 ^-38 minecraft:red_concrete
execute as @s at @s rotated as @s run setblock ^-46 ^5 ^-39 minecraft:red_concrete
execute as @s at @s rotated as @s run setblock ^-46 ^5 ^-40 minecraft:redstone_block
execute as @s at @s rotated as @s run setblock ^-46 ^5 ^-41 minecraft:red_concrete
execute as @s at @s rotated as @s run setblock ^-46 ^5 ^-42 minecraft:red_concrete
execute as @s at @s rotated as @s run setblock ^-46 ^5 ^-43 minecraft:red_concrete
execute as @s at @s rotated as @s run setblock ^-46 ^5 ^-44 minecraft:red_concrete
execute as @s at @s rotated as @s run setblock ^-46 ^5 ^-45 minecraft:red_concrete
execute as @s at @s rotated as @s run setblock ^-46 ^5 ^-46 minecraft:red_concrete
execute as @s at @s rotated as @s run setblock ^-46 ^5 ^-47 minecraft:redstone_block
execute as @s at @s rotated as @s run setblock ^-46 ^5 ^-48 minecraft:red_concrete
execute as @s at @s rotated as @s run setblock ^-46 ^5 ^-49 minecraft:red_concrete
execute as @s at @s rotated as @s run setblock ^-45 ^5 ^-49 minecraft:red_concrete
execute as @s at @s rotated as @s run setblock ^-44 ^5 ^-49 minecraft:red_concrete
execute as @s at @s rotated as @s run setblock ^-43 ^5 ^-49 minecraft:red_concrete
execute as @s at @s rotated as @s run setblock ^-42 ^5 ^-49 minecraft:red_concrete
execute as @s at @s rotated as @s run setblock ^-41 ^5 ^-49 minecraft:redstone_block
execute as @s at @s rotated as @s run setblock ^-40 ^5 ^-49 minecraft:red_concrete
execute as @s at @s rotated as @s run setblock ^-39 ^5 ^-49 minecraft:red_concrete
execute as @s at @s rotated as @s run setblock ^-38 ^5 ^-49 minecraft:red_concrete
execute as @s at @s rotated as @s run setblock ^-37 ^5 ^-49 minecraft:red_concrete
execute as @s at @s rotated as @s run setblock ^-36 ^5 ^-49 minecraft:red_concrete
execute as @s at @s rotated as @s run setblock ^-35 ^5 ^-49 minecraft:red_concrete
execute as @s at @s rotated as @s run setblock ^-34 ^5 ^-49 minecraft:redstone_block
execute as @s at @s rotated as @s run setblock ^-33 ^5 ^-49 minecraft:red_concrete
execute as @s at @s rotated as @s run setblock ^-32 ^5 ^-49 minecraft:red_concrete
execute as @s at @s rotated as @s run setblock ^-31 ^5 ^-49 minecraft:red_concrete
execute as @s at @s rotated as @s run setblock ^-30 ^5 ^-49 minecraft:red_concrete
execute as @s at @s rotated as @s run setblock ^-29 ^5 ^-49 minecraft:red_concrete
execute as @s at @s rotated as @s run setblock ^-28 ^5 ^-49 minecraft:red_concrete
execute as @s at @s rotated as @s run setblock ^-27 ^5 ^-49 minecraft:redstone_block
execute as @s at @s rotated as @s run setblock ^-26 ^5 ^-49 minecraft:red_concrete
execute as @s at @s rotated as @s run setblock ^-25 ^5 ^-49 minecraft:red_concrete
execute as @s at @s rotated as @s run setblock ^-24 ^5 ^-49 minecraft:red_concrete
execute as @s at @s rotated as @s run setblock ^-23 ^5 ^-49 minecraft:red_concrete
execute as @s at @s rotated as @s run setblock ^-22 ^5 ^-49 minecraft:red_concrete
execute as @s at @s rotated as @s run setblock ^-21 ^5 ^-49 minecraft:red_concrete
execute as @s at @s rotated as @s run setblock ^-20 ^5 ^-49 minecraft:redstone_block
execute as @s at @s rotated as @s run setblock ^-19 ^5 ^-49 minecraft:red_concrete
execute as @s at @s rotated as @s run setblock ^-18 ^5 ^-49 minecraft:red_concrete
execute as @s at @s rotated as @s run setblock ^-17 ^5 ^-49 minecraft:red_concrete
execute as @s at @s rotated as @s run setblock ^-16 ^5 ^-49 minecraft:red_concrete
execute as @s at @s rotated as @s run setblock ^-15 ^5 ^-49 minecraft:red_concrete
execute as @s at @s rotated as @s run setblock ^-14 ^5 ^-49 minecraft:red_concrete
execute as @s at @s rotated as @s run setblock ^-13 ^5 ^-49 minecraft:redstone_block
execute as @s at @s rotated as @s run setblock ^-12 ^5 ^-49 minecraft:red_concrete
execute as @s at @s rotated as @s run setblock ^-11 ^5 ^-49 minecraft:red_concrete
execute as @s at @s rotated as @s run setblock ^-10 ^5 ^-49 minecraft:red_concrete
execute as @s at @s rotated as @s run setblock ^-9 ^5 ^-49 minecraft:red_concrete
execute as @s at @s rotated as @s run setblock ^-8 ^5 ^-49 minecraft:red_concrete
execute as @s at @s rotated as @s run setblock ^-7 ^5 ^-49 minecraft:red_concrete
execute as @s at @s rotated as @s run setblock ^-6 ^5 ^-49 minecraft:redstone_block
execute as @s at @s rotated as @s run setblock ^-5 ^5 ^-49 minecraft:red_concrete
execute as @s at @s rotated as @s run setblock ^-4 ^5 ^-49 minecraft:red_concrete
execute as @s at @s rotated as @s run setblock ^-3 ^5 ^-49 minecraft:red_concrete
execute as @s at @s rotated as @s run setblock ^-2 ^5 ^-49 minecraft:red_concrete
execute as @s at @s rotated as @s run setblock ^-1 ^5 ^-49 minecraft:red_concrete
execute as @s at @s rotated as @s run setblock ^0 ^5 ^-49 minecraft:red_concrete

# Rails are placed in travel order so Bedrock forms slopes and corners automatically.
execute as @s at @s rotated as @s run setblock ^0 ^6 ^-48 minecraft:golden_rail
execute as @s at @s rotated as @s run setblock ^0 ^6 ^-47 minecraft:golden_rail
execute as @s at @s rotated as @s run setblock ^0 ^6 ^-46 minecraft:rail
execute as @s at @s rotated as @s run setblock ^0 ^6 ^-45 minecraft:rail
execute as @s at @s rotated as @s run setblock ^0 ^6 ^-44 minecraft:rail
execute as @s at @s rotated as @s run setblock ^0 ^6 ^-43 minecraft:golden_rail
execute as @s at @s rotated as @s run setblock ^0 ^6 ^-42 minecraft:rail
execute as @s at @s rotated as @s run setblock ^0 ^6 ^-41 minecraft:golden_rail
execute as @s at @s rotated as @s run setblock ^0 ^6 ^-40 minecraft:rail
execute as @s at @s rotated as @s run setblock ^0 ^6 ^-39 minecraft:golden_rail
execute as @s at @s rotated as @s run setblock ^0 ^6 ^-38 minecraft:rail
execute as @s at @s rotated as @s run setblock ^0 ^6 ^-37 minecraft:rail
execute as @s at @s rotated as @s run setblock ^0 ^6 ^-36 minecraft:rail
execute as @s at @s rotated as @s run setblock ^0 ^6 ^-35 minecraft:golden_rail
execute as @s at @s rotated as @s run setblock ^0 ^6 ^-34 minecraft:golden_rail
execute as @s at @s rotated as @s run setblock ^0 ^6 ^-33 minecraft:rail
execute as @s at @s rotated as @s run setblock ^0 ^6 ^-32 minecraft:rail
execute as @s at @s rotated as @s run setblock ^0 ^6 ^-31 minecraft:golden_rail
execute as @s at @s rotated as @s run setblock ^0 ^6 ^-30 minecraft:rail
execute as @s at @s rotated as @s run setblock ^0 ^7 ^-29 minecraft:rail
execute as @s at @s rotated as @s run setblock ^0 ^8 ^-28 minecraft:rail
execute as @s at @s rotated as @s run setblock ^0 ^9 ^-27 minecraft:golden_rail
execute as @s at @s rotated as @s run setblock ^0 ^10 ^-26 minecraft:rail
execute as @s at @s rotated as @s run setblock ^0 ^11 ^-25 minecraft:rail
execute as @s at @s rotated as @s run setblock ^0 ^12 ^-24 minecraft:rail
execute as @s at @s rotated as @s run setblock ^0 ^13 ^-23 minecraft:rail
execute as @s at @s rotated as @s run setblock ^0 ^14 ^-22 minecraft:rail
execute as @s at @s rotated as @s run setblock ^0 ^15 ^-21 minecraft:rail
execute as @s at @s rotated as @s run setblock ^0 ^16 ^-20 minecraft:golden_rail
execute as @s at @s rotated as @s run setblock ^0 ^17 ^-19 minecraft:rail
execute as @s at @s rotated as @s run setblock ^0 ^18 ^-18 minecraft:rail
execute as @s at @s rotated as @s run setblock ^0 ^19 ^-17 minecraft:rail
execute as @s at @s rotated as @s run setblock ^0 ^20 ^-16 minecraft:rail
execute as @s at @s rotated as @s run setblock ^0 ^21 ^-15 minecraft:rail
execute as @s at @s rotated as @s run setblock ^0 ^22 ^-14 minecraft:rail
execute as @s at @s rotated as @s run setblock ^0 ^23 ^-13 minecraft:golden_rail
execute as @s at @s rotated as @s run setblock ^0 ^24 ^-12 minecraft:rail
execute as @s at @s rotated as @s run setblock ^0 ^25 ^-11 minecraft:rail
execute as @s at @s rotated as @s run setblock ^0 ^26 ^-10 minecraft:rail
execute as @s at @s rotated as @s run setblock ^0 ^27 ^-9 minecraft:rail
execute as @s at @s rotated as @s run setblock ^0 ^28 ^-8 minecraft:rail
execute as @s at @s rotated as @s run setblock ^0 ^29 ^-7 minecraft:rail
execute as @s at @s rotated as @s run setblock ^0 ^30 ^-6 minecraft:golden_rail
execute as @s at @s rotated as @s run setblock ^0 ^31 ^-5 minecraft:rail
execute as @s at @s rotated as @s run setblock ^0 ^32 ^-4 minecraft:rail
execute as @s at @s rotated as @s run setblock ^0 ^33 ^-3 minecraft:rail
execute as @s at @s rotated as @s run setblock ^0 ^34 ^-2 minecraft:rail
execute as @s at @s rotated as @s run setblock ^0 ^35 ^-1 minecraft:rail
execute as @s at @s rotated as @s run setblock ^0 ^36 ^0 minecraft:rail
execute as @s at @s rotated as @s run setblock ^0 ^37 ^1 minecraft:golden_rail
execute as @s at @s rotated as @s run setblock ^0 ^38 ^2 minecraft:rail
execute as @s at @s rotated as @s run setblock ^0 ^39 ^3 minecraft:rail
execute as @s at @s rotated as @s run setblock ^0 ^40 ^4 minecraft:rail
execute as @s at @s rotated as @s run setblock ^0 ^41 ^5 minecraft:rail
execute as @s at @s rotated as @s run setblock ^0 ^42 ^6 minecraft:rail
execute as @s at @s rotated as @s run setblock ^0 ^43 ^7 minecraft:rail
execute as @s at @s rotated as @s run setblock ^0 ^44 ^8 minecraft:golden_rail
execute as @s at @s rotated as @s run setblock ^0 ^45 ^9 minecraft:rail
execute as @s at @s rotated as @s run setblock ^0 ^46 ^10 minecraft:rail
execute as @s at @s rotated as @s run setblock ^0 ^47 ^11 minecraft:rail
execute as @s at @s rotated as @s run setblock ^0 ^48 ^12 minecraft:rail
execute as @s at @s rotated as @s run setblock ^0 ^49 ^13 minecraft:rail
execute as @s at @s rotated as @s run setblock ^0 ^50 ^14 minecraft:rail
execute as @s at @s rotated as @s run setblock ^0 ^51 ^15 minecraft:golden_rail
execute as @s at @s rotated as @s run setblock ^0 ^51 ^16 minecraft:rail
execute as @s at @s rotated as @s run setblock ^0 ^51 ^17 minecraft:rail
execute as @s at @s rotated as @s run setblock ^0 ^51 ^18 minecraft:rail
execute as @s at @s rotated as @s run setblock ^0 ^51 ^19 minecraft:rail
execute as @s at @s rotated as @s run setblock ^0 ^51 ^20 minecraft:rail
execute as @s at @s rotated as @s run setblock ^1 ^51 ^20 minecraft:rail
execute as @s at @s rotated as @s run setblock ^2 ^51 ^20 minecraft:golden_rail
execute as @s at @s rotated as @s run setblock ^3 ^51 ^20 minecraft:rail
execute as @s at @s rotated as @s run setblock ^4 ^51 ^20 minecraft:rail
execute as @s at @s rotated as @s run setblock ^5 ^51 ^20 minecraft:rail
execute as @s at @s rotated as @s run setblock ^6 ^51 ^20 minecraft:rail
execute as @s at @s rotated as @s run setblock ^7 ^51 ^20 minecraft:rail
execute as @s at @s rotated as @s run setblock ^8 ^51 ^20 minecraft:rail
execute as @s at @s rotated as @s run setblock ^9 ^51 ^20 minecraft:golden_rail
execute as @s at @s rotated as @s run setblock ^10 ^51 ^20 minecraft:rail
execute as @s at @s rotated as @s run setblock ^11 ^51 ^20 minecraft:rail
execute as @s at @s rotated as @s run setblock ^12 ^51 ^20 minecraft:rail
execute as @s at @s rotated as @s run setblock ^13 ^51 ^20 minecraft:rail
execute as @s at @s rotated as @s run setblock ^14 ^51 ^20 minecraft:rail
execute as @s at @s rotated as @s run setblock ^15 ^51 ^20 minecraft:rail
execute as @s at @s rotated as @s run setblock ^16 ^51 ^20 minecraft:golden_rail
execute as @s at @s rotated as @s run setblock ^17 ^51 ^20 minecraft:rail
execute as @s at @s rotated as @s run setblock ^18 ^51 ^20 minecraft:rail
execute as @s at @s rotated as @s run setblock ^19 ^51 ^20 minecraft:rail
execute as @s at @s rotated as @s run setblock ^20 ^51 ^20 minecraft:rail
execute as @s at @s rotated as @s run setblock ^21 ^51 ^20 minecraft:rail
execute as @s at @s rotated as @s run setblock ^22 ^51 ^20 minecraft:rail
execute as @s at @s rotated as @s run setblock ^23 ^51 ^20 minecraft:golden_rail
execute as @s at @s rotated as @s run setblock ^24 ^51 ^20 minecraft:rail
execute as @s at @s rotated as @s run setblock ^25 ^51 ^20 minecraft:rail
execute as @s at @s rotated as @s run setblock ^26 ^51 ^20 minecraft:rail
execute as @s at @s rotated as @s run setblock ^27 ^51 ^20 minecraft:rail
execute as @s at @s rotated as @s run setblock ^28 ^51 ^20 minecraft:rail
execute as @s at @s rotated as @s run setblock ^29 ^51 ^20 minecraft:rail
execute as @s at @s rotated as @s run setblock ^30 ^51 ^20 minecraft:golden_rail
execute as @s at @s rotated as @s run setblock ^31 ^51 ^20 minecraft:rail
execute as @s at @s rotated as @s run setblock ^32 ^51 ^20 minecraft:rail
execute as @s at @s rotated as @s run setblock ^33 ^51 ^20 minecraft:rail
execute as @s at @s rotated as @s run setblock ^34 ^51 ^20 minecraft:rail
execute as @s at @s rotated as @s run setblock ^35 ^51 ^20 minecraft:rail
execute as @s at @s rotated as @s run setblock ^36 ^51 ^20 minecraft:rail
execute as @s at @s rotated as @s run setblock ^37 ^51 ^20 minecraft:golden_rail
execute as @s at @s rotated as @s run setblock ^38 ^51 ^20 minecraft:rail
execute as @s at @s rotated as @s run setblock ^39 ^51 ^20 minecraft:rail
execute as @s at @s rotated as @s run setblock ^40 ^51 ^20 minecraft:rail
execute as @s at @s rotated as @s run setblock ^41 ^51 ^20 minecraft:rail
execute as @s at @s rotated as @s run setblock ^42 ^51 ^20 minecraft:rail
execute as @s at @s rotated as @s run setblock ^42 ^50 ^21 minecraft:rail
execute as @s at @s rotated as @s run setblock ^42 ^49 ^22 minecraft:golden_rail
execute as @s at @s rotated as @s run setblock ^42 ^48 ^23 minecraft:rail
execute as @s at @s rotated as @s run setblock ^42 ^47 ^24 minecraft:rail
execute as @s at @s rotated as @s run setblock ^42 ^46 ^25 minecraft:rail
execute as @s at @s rotated as @s run setblock ^42 ^45 ^26 minecraft:rail
execute as @s at @s rotated as @s run setblock ^42 ^44 ^27 minecraft:rail
execute as @s at @s rotated as @s run setblock ^42 ^43 ^28 minecraft:rail
execute as @s at @s rotated as @s run setblock ^42 ^42 ^29 minecraft:golden_rail
execute as @s at @s rotated as @s run setblock ^42 ^41 ^30 minecraft:rail
execute as @s at @s rotated as @s run setblock ^42 ^40 ^31 minecraft:rail
execute as @s at @s rotated as @s run setblock ^42 ^39 ^32 minecraft:rail
execute as @s at @s rotated as @s run setblock ^42 ^38 ^33 minecraft:rail
execute as @s at @s rotated as @s run setblock ^42 ^37 ^34 minecraft:rail
execute as @s at @s rotated as @s run setblock ^42 ^36 ^35 minecraft:rail
execute as @s at @s rotated as @s run setblock ^42 ^35 ^36 minecraft:golden_rail
execute as @s at @s rotated as @s run setblock ^42 ^34 ^37 minecraft:rail
execute as @s at @s rotated as @s run setblock ^42 ^33 ^38 minecraft:rail
execute as @s at @s rotated as @s run setblock ^42 ^32 ^39 minecraft:rail
execute as @s at @s rotated as @s run setblock ^42 ^31 ^40 minecraft:rail
execute as @s at @s rotated as @s run setblock ^42 ^30 ^41 minecraft:rail
execute as @s at @s rotated as @s run setblock ^42 ^29 ^42 minecraft:rail
execute as @s at @s rotated as @s run setblock ^42 ^28 ^43 minecraft:golden_rail
execute as @s at @s rotated as @s run setblock ^42 ^27 ^44 minecraft:rail
execute as @s at @s rotated as @s run setblock ^42 ^26 ^45 minecraft:rail
execute as @s at @s rotated as @s run setblock ^42 ^25 ^46 minecraft:rail
execute as @s at @s rotated as @s run setblock ^42 ^24 ^47 minecraft:rail
execute as @s at @s rotated as @s run setblock ^42 ^23 ^48 minecraft:rail
execute as @s at @s rotated as @s run setblock ^42 ^22 ^49 minecraft:rail
execute as @s at @s rotated as @s run setblock ^42 ^21 ^50 minecraft:golden_rail
execute as @s at @s rotated as @s run setblock ^42 ^20 ^51 minecraft:rail
execute as @s at @s rotated as @s run setblock ^42 ^19 ^52 minecraft:rail
execute as @s at @s rotated as @s run setblock ^42 ^18 ^53 minecraft:rail
execute as @s at @s rotated as @s run setblock ^42 ^17 ^54 minecraft:rail
execute as @s at @s rotated as @s run setblock ^42 ^16 ^55 minecraft:rail
execute as @s at @s rotated as @s run setblock ^42 ^15 ^56 minecraft:rail
execute as @s at @s rotated as @s run setblock ^42 ^14 ^57 minecraft:golden_rail
execute as @s at @s rotated as @s run setblock ^42 ^13 ^58 minecraft:rail
execute as @s at @s rotated as @s run setblock ^42 ^13 ^59 minecraft:rail
execute as @s at @s rotated as @s run setblock ^41 ^13 ^59 minecraft:rail
execute as @s at @s rotated as @s run setblock ^40 ^13 ^59 minecraft:rail
execute as @s at @s rotated as @s run setblock ^39 ^13 ^59 minecraft:rail
execute as @s at @s rotated as @s run setblock ^38 ^13 ^59 minecraft:rail
execute as @s at @s rotated as @s run setblock ^37 ^13 ^59 minecraft:golden_rail
execute as @s at @s rotated as @s run setblock ^36 ^13 ^59 minecraft:rail
execute as @s at @s rotated as @s run setblock ^35 ^13 ^59 minecraft:rail
execute as @s at @s rotated as @s run setblock ^34 ^13 ^59 minecraft:rail
execute as @s at @s rotated as @s run setblock ^33 ^13 ^59 minecraft:rail
execute as @s at @s rotated as @s run setblock ^32 ^13 ^59 minecraft:rail
execute as @s at @s rotated as @s run setblock ^31 ^13 ^59 minecraft:rail
execute as @s at @s rotated as @s run setblock ^30 ^13 ^59 minecraft:golden_rail
execute as @s at @s rotated as @s run setblock ^29 ^13 ^59 minecraft:rail
execute as @s at @s rotated as @s run setblock ^28 ^13 ^59 minecraft:rail
execute as @s at @s rotated as @s run setblock ^27 ^13 ^59 minecraft:rail
execute as @s at @s rotated as @s run setblock ^26 ^13 ^59 minecraft:rail
execute as @s at @s rotated as @s run setblock ^25 ^13 ^59 minecraft:rail
execute as @s at @s rotated as @s run setblock ^24 ^13 ^59 minecraft:rail
execute as @s at @s rotated as @s run setblock ^23 ^13 ^59 minecraft:golden_rail
execute as @s at @s rotated as @s run setblock ^22 ^13 ^59 minecraft:rail
execute as @s at @s rotated as @s run setblock ^21 ^13 ^59 minecraft:rail
execute as @s at @s rotated as @s run setblock ^20 ^13 ^59 minecraft:rail
execute as @s at @s rotated as @s run setblock ^19 ^13 ^59 minecraft:rail
execute as @s at @s rotated as @s run setblock ^18 ^13 ^59 minecraft:rail
execute as @s at @s rotated as @s run setblock ^17 ^13 ^59 minecraft:rail
execute as @s at @s rotated as @s run setblock ^16 ^13 ^59 minecraft:golden_rail
execute as @s at @s rotated as @s run setblock ^15 ^13 ^59 minecraft:rail
execute as @s at @s rotated as @s run setblock ^14 ^13 ^59 minecraft:rail
execute as @s at @s rotated as @s run setblock ^13 ^13 ^59 minecraft:rail
execute as @s at @s rotated as @s run setblock ^12 ^13 ^59 minecraft:rail
execute as @s at @s rotated as @s run setblock ^11 ^13 ^59 minecraft:rail
execute as @s at @s rotated as @s run setblock ^10 ^13 ^59 minecraft:rail
execute as @s at @s rotated as @s run setblock ^9 ^14 ^59 minecraft:golden_rail
execute as @s at @s rotated as @s run setblock ^8 ^15 ^59 minecraft:rail
execute as @s at @s rotated as @s run setblock ^7 ^16 ^59 minecraft:rail
execute as @s at @s rotated as @s run setblock ^6 ^17 ^59 minecraft:rail
execute as @s at @s rotated as @s run setblock ^5 ^18 ^59 minecraft:rail
execute as @s at @s rotated as @s run setblock ^4 ^19 ^59 minecraft:rail
execute as @s at @s rotated as @s run setblock ^3 ^20 ^59 minecraft:rail
execute as @s at @s rotated as @s run setblock ^2 ^21 ^59 minecraft:golden_rail
execute as @s at @s rotated as @s run setblock ^1 ^22 ^59 minecraft:rail
execute as @s at @s rotated as @s run setblock ^0 ^23 ^59 minecraft:rail
execute as @s at @s rotated as @s run setblock ^-1 ^24 ^59 minecraft:rail
execute as @s at @s rotated as @s run setblock ^-2 ^25 ^59 minecraft:rail
execute as @s at @s rotated as @s run setblock ^-3 ^26 ^59 minecraft:rail
execute as @s at @s rotated as @s run setblock ^-4 ^27 ^59 minecraft:rail
execute as @s at @s rotated as @s run setblock ^-5 ^28 ^59 minecraft:golden_rail
execute as @s at @s rotated as @s run setblock ^-6 ^29 ^59 minecraft:rail
execute as @s at @s rotated as @s run setblock ^-7 ^30 ^59 minecraft:rail
execute as @s at @s rotated as @s run setblock ^-8 ^31 ^59 minecraft:rail
execute as @s at @s rotated as @s run setblock ^-9 ^32 ^59 minecraft:rail
execute as @s at @s rotated as @s run setblock ^-10 ^33 ^59 minecraft:rail
execute as @s at @s rotated as @s run setblock ^-11 ^32 ^59 minecraft:rail
execute as @s at @s rotated as @s run setblock ^-12 ^31 ^59 minecraft:golden_rail
execute as @s at @s rotated as @s run setblock ^-13 ^30 ^59 minecraft:rail
execute as @s at @s rotated as @s run setblock ^-14 ^29 ^59 minecraft:rail
execute as @s at @s rotated as @s run setblock ^-15 ^28 ^59 minecraft:rail
execute as @s at @s rotated as @s run setblock ^-16 ^27 ^59 minecraft:rail
execute as @s at @s rotated as @s run setblock ^-17 ^26 ^59 minecraft:rail
execute as @s at @s rotated as @s run setblock ^-18 ^25 ^59 minecraft:rail
execute as @s at @s rotated as @s run setblock ^-19 ^24 ^59 minecraft:golden_rail
execute as @s at @s rotated as @s run setblock ^-20 ^23 ^59 minecraft:rail
execute as @s at @s rotated as @s run setblock ^-21 ^22 ^59 minecraft:rail
execute as @s at @s rotated as @s run setblock ^-22 ^21 ^59 minecraft:rail
execute as @s at @s rotated as @s run setblock ^-23 ^20 ^59 minecraft:rail
execute as @s at @s rotated as @s run setblock ^-24 ^19 ^59 minecraft:rail
execute as @s at @s rotated as @s run setblock ^-25 ^18 ^59 minecraft:rail
execute as @s at @s rotated as @s run setblock ^-26 ^17 ^59 minecraft:golden_rail
execute as @s at @s rotated as @s run setblock ^-27 ^16 ^59 minecraft:rail
execute as @s at @s rotated as @s run setblock ^-28 ^15 ^59 minecraft:rail
execute as @s at @s rotated as @s run setblock ^-29 ^14 ^59 minecraft:rail
execute as @s at @s rotated as @s run setblock ^-30 ^13 ^59 minecraft:rail
execute as @s at @s rotated as @s run setblock ^-31 ^13 ^59 minecraft:rail
execute as @s at @s rotated as @s run setblock ^-31 ^13 ^58 minecraft:rail
execute as @s at @s rotated as @s run setblock ^-31 ^13 ^57 minecraft:golden_rail
execute as @s at @s rotated as @s run setblock ^-31 ^13 ^56 minecraft:rail
execute as @s at @s rotated as @s run setblock ^-31 ^13 ^55 minecraft:rail
execute as @s at @s rotated as @s run setblock ^-31 ^13 ^54 minecraft:rail
execute as @s at @s rotated as @s run setblock ^-31 ^13 ^53 minecraft:rail
execute as @s at @s rotated as @s run setblock ^-31 ^13 ^52 minecraft:rail
execute as @s at @s rotated as @s run setblock ^-31 ^13 ^51 minecraft:rail
execute as @s at @s rotated as @s run setblock ^-31 ^13 ^50 minecraft:golden_rail
execute as @s at @s rotated as @s run setblock ^-31 ^13 ^49 minecraft:rail
execute as @s at @s rotated as @s run setblock ^-31 ^13 ^48 minecraft:rail
execute as @s at @s rotated as @s run setblock ^-31 ^13 ^47 minecraft:rail
execute as @s at @s rotated as @s run setblock ^-31 ^13 ^46 minecraft:rail
execute as @s at @s rotated as @s run setblock ^-31 ^13 ^45 minecraft:rail
execute as @s at @s rotated as @s run setblock ^-31 ^13 ^44 minecraft:rail
execute as @s at @s rotated as @s run setblock ^-31 ^13 ^43 minecraft:golden_rail
execute as @s at @s rotated as @s run setblock ^-31 ^13 ^42 minecraft:rail
execute as @s at @s rotated as @s run setblock ^-31 ^13 ^41 minecraft:rail
execute as @s at @s rotated as @s run setblock ^-31 ^13 ^40 minecraft:rail
execute as @s at @s rotated as @s run setblock ^-31 ^13 ^39 minecraft:rail
execute as @s at @s rotated as @s run setblock ^-31 ^13 ^38 minecraft:rail
execute as @s at @s rotated as @s run setblock ^-31 ^13 ^37 minecraft:rail
execute as @s at @s rotated as @s run setblock ^-31 ^13 ^36 minecraft:golden_rail
execute as @s at @s rotated as @s run setblock ^-31 ^13 ^35 minecraft:rail
execute as @s at @s rotated as @s run setblock ^-31 ^14 ^34 minecraft:rail
execute as @s at @s rotated as @s run setblock ^-31 ^15 ^33 minecraft:rail
execute as @s at @s rotated as @s run setblock ^-31 ^16 ^32 minecraft:rail
execute as @s at @s rotated as @s run setblock ^-31 ^17 ^31 minecraft:rail
execute as @s at @s rotated as @s run setblock ^-31 ^18 ^30 minecraft:rail
execute as @s at @s rotated as @s run setblock ^-31 ^19 ^29 minecraft:golden_rail
execute as @s at @s rotated as @s run setblock ^-31 ^20 ^28 minecraft:rail
execute as @s at @s rotated as @s run setblock ^-31 ^21 ^27 minecraft:rail
execute as @s at @s rotated as @s run setblock ^-31 ^22 ^26 minecraft:rail
execute as @s at @s rotated as @s run setblock ^-31 ^23 ^25 minecraft:rail
execute as @s at @s rotated as @s run setblock ^-31 ^24 ^24 minecraft:rail
execute as @s at @s rotated as @s run setblock ^-31 ^25 ^23 minecraft:rail
execute as @s at @s rotated as @s run setblock ^-31 ^26 ^22 minecraft:golden_rail
execute as @s at @s rotated as @s run setblock ^-31 ^25 ^21 minecraft:rail
execute as @s at @s rotated as @s run setblock ^-31 ^24 ^20 minecraft:rail
execute as @s at @s rotated as @s run setblock ^-31 ^23 ^19 minecraft:rail
execute as @s at @s rotated as @s run setblock ^-31 ^22 ^18 minecraft:rail
execute as @s at @s rotated as @s run setblock ^-31 ^21 ^17 minecraft:rail
execute as @s at @s rotated as @s run setblock ^-31 ^20 ^16 minecraft:rail
execute as @s at @s rotated as @s run setblock ^-31 ^19 ^15 minecraft:golden_rail
execute as @s at @s rotated as @s run setblock ^-31 ^18 ^14 minecraft:rail
execute as @s at @s rotated as @s run setblock ^-31 ^17 ^13 minecraft:rail
execute as @s at @s rotated as @s run setblock ^-31 ^16 ^12 minecraft:rail
execute as @s at @s rotated as @s run setblock ^-31 ^15 ^11 minecraft:rail
execute as @s at @s rotated as @s run setblock ^-31 ^14 ^10 minecraft:rail
execute as @s at @s rotated as @s run setblock ^-31 ^13 ^9 minecraft:rail
execute as @s at @s rotated as @s run setblock ^-31 ^13 ^8 minecraft:rail
execute as @s at @s rotated as @s run setblock ^-32 ^13 ^8 minecraft:rail
execute as @s at @s rotated as @s run setblock ^-33 ^13 ^8 minecraft:rail
execute as @s at @s rotated as @s run setblock ^-34 ^13 ^8 minecraft:rail
execute as @s at @s rotated as @s run setblock ^-35 ^13 ^8 minecraft:rail
execute as @s at @s rotated as @s run setblock ^-36 ^13 ^8 minecraft:rail
execute as @s at @s rotated as @s run setblock ^-37 ^13 ^8 minecraft:rail
execute as @s at @s rotated as @s run setblock ^-38 ^13 ^8 minecraft:golden_rail
execute as @s at @s rotated as @s run setblock ^-39 ^13 ^8 minecraft:rail
execute as @s at @s rotated as @s run setblock ^-40 ^13 ^8 minecraft:rail
execute as @s at @s rotated as @s run setblock ^-41 ^13 ^8 minecraft:rail
execute as @s at @s rotated as @s run setblock ^-42 ^13 ^8 minecraft:rail
execute as @s at @s rotated as @s run setblock ^-43 ^13 ^8 minecraft:rail
execute as @s at @s rotated as @s run setblock ^-44 ^13 ^8 minecraft:rail
execute as @s at @s rotated as @s run setblock ^-45 ^13 ^8 minecraft:golden_rail
execute as @s at @s rotated as @s run setblock ^-46 ^13 ^8 minecraft:rail
execute as @s at @s rotated as @s run setblock ^-46 ^12 ^7 minecraft:rail
execute as @s at @s rotated as @s run setblock ^-46 ^11 ^6 minecraft:rail
execute as @s at @s rotated as @s run setblock ^-46 ^10 ^5 minecraft:rail
execute as @s at @s rotated as @s run setblock ^-46 ^9 ^4 minecraft:rail
execute as @s at @s rotated as @s run setblock ^-46 ^8 ^3 minecraft:rail
execute as @s at @s rotated as @s run setblock ^-46 ^7 ^2 minecraft:golden_rail
execute as @s at @s rotated as @s run setblock ^-46 ^6 ^1 minecraft:rail
execute as @s at @s rotated as @s run setblock ^-46 ^6 ^0 minecraft:rail
execute as @s at @s rotated as @s run setblock ^-46 ^6 ^-1 minecraft:rail
execute as @s at @s rotated as @s run setblock ^-46 ^6 ^-2 minecraft:rail
execute as @s at @s rotated as @s run setblock ^-46 ^6 ^-3 minecraft:rail
execute as @s at @s rotated as @s run setblock ^-46 ^6 ^-4 minecraft:rail
execute as @s at @s rotated as @s run setblock ^-46 ^6 ^-5 minecraft:golden_rail
execute as @s at @s rotated as @s run setblock ^-46 ^6 ^-6 minecraft:rail
execute as @s at @s rotated as @s run setblock ^-46 ^6 ^-7 minecraft:rail
execute as @s at @s rotated as @s run setblock ^-46 ^6 ^-8 minecraft:rail
execute as @s at @s rotated as @s run setblock ^-46 ^6 ^-9 minecraft:rail
execute as @s at @s rotated as @s run setblock ^-46 ^6 ^-10 minecraft:rail
execute as @s at @s rotated as @s run setblock ^-46 ^6 ^-11 minecraft:rail
execute as @s at @s rotated as @s run setblock ^-46 ^6 ^-12 minecraft:golden_rail
execute as @s at @s rotated as @s run setblock ^-46 ^6 ^-13 minecraft:rail
execute as @s at @s rotated as @s run setblock ^-46 ^6 ^-14 minecraft:rail
execute as @s at @s rotated as @s run setblock ^-46 ^6 ^-15 minecraft:rail
execute as @s at @s rotated as @s run setblock ^-46 ^6 ^-16 minecraft:rail
execute as @s at @s rotated as @s run setblock ^-46 ^6 ^-17 minecraft:rail
execute as @s at @s rotated as @s run setblock ^-46 ^6 ^-18 minecraft:rail
execute as @s at @s rotated as @s run setblock ^-46 ^6 ^-19 minecraft:golden_rail
